Workbook

Sheet Colour Guide
A2: Brand | B2: Primary | C2: Secondary
A3: Holiday Inn Express | B3: #002D72 | C3: #9BCBEB | D3: #E35205
A4: Holiday Inn | B4: #1C4B34 | C4: #578272 | D4: #9BC5B7
A5: avid hotels | B5: #68D2DF | C5: #FF0000
A6: Garner | B6: #ABDBC6 | C6: #FBF8EB
A7: Atwell Suites | B7: #6C714D | C7: #E8CEBD | D7: #B46A55
A8: Staybridge Suites | B8: #006980
A9: Candlewood Suites | B9: #9B2241 | C9: #00205B
A10: Even Hotels | B10: #164945
A11: voco | B11: #121217 | C11: #F8B9OD
A12: Crowne Plaza | B12: #A00062 | C12: #515A61
A13: Hotel Indigo | B13: #2E5992 | C13: #D8A400
A14: Vignette | B14: #2E273B | C14: #E9D0D5
A15: Intercontinental | B15: #3D3935 | C15: #CBC5BE
A16: Regent | B16: #D6E3DC | C16: F5E1CC | D16: #211551
A17: Kimpton | B17: #58565C | C17: #FFFFFF

Sheet Garner
A1: Garner | B1: Course ID | C1: Time Frame (1-10) Not Visible to Learner | D1: Time Frame Visible to Learner | E1: Priority: Y | F1: Notes | G1: General Manager | H1: Sales Team Leader | I1: Revenue Team Leader | J1: Front Office Team Leader | K1: Housekeeping Team Leader | L1: Food & Beverage Team Leader | M1: Engineering Team Leader | N1: Front Desk | O1: Housekeeping | P1: Food and Beverage | Q1: Engineering | R1: All other management colleagues | S1: All other non-management colleagues
A2: True Hospitality Service Skills | B2: IHG051263 | C2: 3 | D2: within 30 days | F2: Self-paced Online Learning (1 Hour 15 Minutes). Hotel-led in-person training (On-Job-Training, OJT) is permitted & completions must be tracked in myLearning. | G2: x | H2: x | I2: x | J2: x | K2: x | L2: x | M2: x | N2: x | O2: x | P2: x | Q2: x | R2: x | S2: x
A3: IHG Managed Hotels - Responsible Business Catalogue | B3: Guide for Managed Hotel Leaders | C3: 3 | D3: within 30 days | F3: For IHG Managed Hotels only; follow guidance on brand-standard related trainings | G3: x | H3: x | I3: x | J3: x | K3: x | L3: x | M3: x | R3: x
A4: IHG Managed Hotels - Responsible Business Catalogue | B4: Guide for Managed Hotel Colleagues | C4: 3 | D4: within 30 days | F4: For IHG Managed Hotels only; follow guidance on brand-standard related trainings | N4: x | O4: x | P4: x | Q4: x | S4: x
A5: Franchised Hotels - Responsible Business Catalogue | B5: Guide for Franchised Hotel Leaders | C5: 3 | D5: within 30 days | F5: For Franchised Hotels only; follow guidance on brand-standard related trainings | G5: x | H5: x | I5: x | J5: x | K5: x | L5: x | M5: x | R5: x
A6: Franchised Hotels - Responsible Business Catalogue | B6: Guide for Franchised Hotel Colleagues | C6: 3 | D6: within 30 days | F6: For Franchised Hotels only; follow guidance on brand-standard related trainings | N6: x | O6: x | P6: x | Q6: x | S6: x
A7: Hotel Experience Champion | B7: Hotel Experience Champion Program | C7: 3 | D7: within 30 days | F7: Not a specific course; review the Hotel Experience Champion Program and ensure Hotel Experience Champion role(s) have been assigned | G7: x
A8: Leading and Sustaining your Service Culture | B8: IHG0056403 | C8: 4 | D8: within 60 days | F8: Self-paced Online Learning (1 Hour 45 Minutes). | G8: x | H8: x | I8: x | J8: x | K8: x | L8: x | M8: x | R8: x
A9: Brand Service Tools & Resources | B9: Brand Service Tools & Resources | C9: 10 | D9: Suggested Learning | F9: Explore resource and apply accordingly | G9: x | H9: x | I9: x | J9: x | K9: x | L9: x | M9: x | R9: x
A10: IHG Problem Handling | B10: IHG056045 | C10: 3 | D10: within 30 days | F10: Self-paced Online Learning (1 Hour). Hotel-led in-person training (On-Job-Training, OJT) is permitted & completions must be tracked in myLearning. | G10: x | H10: x | I10: x | J10: x | K10: x | L10: x | M10: x | N10: x | O10: x | P10: x | Q10: x | R10: x | S10: x
A11: The Value of Loyalty | B11: IHG5072070 | C11: 3 | D11: within 30 days | F11: Self-paced Online Learning (20 Minutes). | G11: x | H11: x | I11: x | J11: x | K11: x | L11: x | M11: x | N11: x | O11: x | P11: x | Q11: x | R11: x | S11: x
A12: Leading Loyalty | B12: IHG6112495 | C12: 3 | D12: within 30 days | F12: Self-paced Online Learning (20 Minutes). | G12: x | H12: x | I12: x | J12: x | K12: x | L12: x | M12: x | R12: x
A13: IHG One Rewards Program Overview | B13: IHG8755255 | C13: 3 | D13: within 30 days | F13: Self-paced Online Learning (20 Minutes). | G13: x | H13: x | I13: x | J13: x | K13: x | L13: x | M13: x | N13: x | O13: x | P13: x | Q13: x | R13: x | S13: x
A14: Member Recognition | B14: IHG1984349 | C14: 3 | D14: within 30 days | F14: Self-paced Online Learning (15 Minutes). | G14: x | H14: x | I14: x | J14: x | K14: x | L14: x | M14: x | N14: x | O14: x | P14: x | Q14: x | R14: x | S14: x
A15: Value of Enrollments | B15: IHG2428898 | C15: 3 | D15: within 30 days | F15: Self-paced Online Learning (20 Minutes). | G15: x | H15: x | I15: x | J15: x | K15: x | L15: x | M15: x | N15: x | O15: x | P15: x | Q15: x | R15: x | S15: x
A16: IHG Business Rewards Training | B16: IHG0052543 | C16: 10 | D16: Suggested Learning | F16: Self-paced Online Learning. | G16: x | H16: x | I16: x | J16: x | K16: x | L16: x | M16: x | N16: x | R16: x | S16: x
A17: LoyaltyConnect | B17: IHG0049654 | C17: 10 | D17: Suggested Learning | F17: Self-paced Online Learning. | G17: x | J17: x | N17: x
A18: IHG Way of Clean 5-S Cleaning Program | B18: IHG7376524 | C18: 3 | D18: within 30 days | F18: Hotel-led in-person training (On-Job-Training, OJT) is permitted & completions must be tracked in myLearning. | K18: x | O18: x | P18: x
A19: IHG Way of Clean 5-S Cleaning Program for Non-Housekeeping colleagues | B19: IHG1227263 | C19: 3 | D19: within 30 days | F19: Self-paced Online Learning (20 Minutes). Hotel-led in-person training (On-Job-Training, OJT) is permitted & completions must be tracked in myLearning. | G19: x | H19: x | I19: x | J19: x | L19: x | M19: x | N19: x | Q19: x | R19: x | S19: x
A20: Getting to Know IHG Concerto | B20: IHG0049491 | C20: 10 | D20: Suggested Learning | F20: Self-paced Online Learning. | G20: x | H20: x | I20: x | J20: x
A21: IHG Concerto - MyID - Approvals | B21: IHG0054204 | C21: 10 | D21: Suggested Learning | F21: Self-paced Online Learning. | G21: x
A22: IHG Concerto - MyID - Assigning Concerto Access | B22: IHG0054203 | C22: 10 | D22: Suggested Learning | F22: Self-paced Online Learning. | G22: x
A23: IHG Concerto - MyID - Accessing IHG Concerto User Report | B23: IHG0054206 | C23: 10 | D23: Suggested Learning | F23: Self-paced Online Learning. | G23: x
A24: IHG Concerto - MyID - Removing Access | B24: IHG0054205 | C24: 10 | D24: Suggested Learning | F24: Self-paced Online Learning. | G24: x
A25: IHG Concerto Homepage overview | B25: IHG0052563 | C25: 10 | D25: Suggested Learning | F25: Self-paced Online Learning. | G25: x | H25: x | I25: x | J25: x
A26: IHG Concerto: Hotel Content Overview | B26: IHG0060624 | C26: 10 | D26: Suggested Learning | F26: Self-paced Online Learning (5 Minutes). | G26: x | H26: x | I26: x | J26: x
A27: Global Sales Induction | B27: IHG7573378 | C27: 10 | D27: Suggested Learning | F27: Self-paced Online Learning (25 Minutes). | G27: x | H27: x
A28: Sales Learning Pathway for On Property Sellers | B28: IHG3530707 | C28: 5 | D28: within 90 days | F28: Self-paced Online Learning (1 Hour 30 Minutes). | G28: x | H28: x
A29: Getting Started with MeetingBroker | B29: IHG0056663 | C29: 10 | D29: Suggested Learning | F29: Self-paced Online Learning. | G29: x | H29: x
A30: IHG Way of Sales - Solution Selling | B30: IHG0025681 | C30: 6 | D30: within 120 days | F30: In-person Instructor Led Course (see available dates & times by clicking the link below). Prerequisite: Must Complete Sales Learning Pathway | G30: x | H30: x
A31: GRS Fundamentals - Reservation, Rate and Inventory Management | B31: IHG0049459 | C31: 10 | D31: Suggested Learning | F31: Self-paced Online Learning. | G31: x | I31: x
A32: RMS Fundamentals: Yielding & Price Optimization | B32: IHG0049460 | C32: 10 | D32: Suggested Learning | F32: Self-paced Online Learning. | G32: x | I32: x
A33: IHG Concerto Hotel Release 2 - Inventory Reset Process Phase II | B33: IHG0061343 | C33: 10 | D33: Suggested Learning | F33: Self-paced Online Learning. | G33: x | I33: x
A34: IHG Concerto Hotel Release 2 - Inventory Reset Process Phase III | B34: IHG0061983 | C34: 10 | D34: Suggested Learning | F34: Self-paced Online Learning. | G34: x | I34: x
A35: IHG Concerto Inventory Configuration - Sleeping Rooms | B35: IHG1677402 | C35: 10 | D35: Suggested Learning | F35: Self-paced Online Learning. | G35: x | I35: x
A36: IHG Concerto - Getting to Know Inventory Balancing | B36: IHG0053503 | C36: 10 | D36: Suggested Learning | F36: Self-paced Online Learning. | G36: x | I36: x
A37: Revenue Management Certification | B37: RM Certification | C37: 5 | D37: within 90 days | I37: x
A38: General Manager Onboarding Learning Plan | B38: Onboarding Learning Plan | C38: 7 | D38: within 6 months | F38: Access to the system will automatically be given. For New Hotels - only to be completed after official hotel opening. | G38: x
A39: General Manager Onboarding Learning Event | B39: Registration Link | C39: 7 | D39: within 6 months | F39: Prerequisite: Must complete Onboarding Learning Plan | G39: x
A40: Food Waste Reduction for People Leaders | B40: IHG7300975 | C40: 10 | D40: Suggested Learning | F40: Self-paced Online Learning (25 Minutes). | G40: x | L40: x
...

Sheet Holiday Inn Express
A1: Holiday Inn Express | B1: Course ID | C1: Time Frame (1-10) Not Visible to Learner | D1: Time Frame Visible to Learner | E1: Priority: Y | F1: Notes | G1: General Manager | H1: Sales Team Leader | I1: Revenue Team Leader | J1: Front Office Team Leader | K1: Housekeeping Team Leader | L1: Food & Beverage Team Leader | M1: Engineering Team Leader | N1: Front Desk | O1: Housekeeping | P1: Food and Beverage | Q1: Engineering | R1: All other management colleagues | S1: All other non-management colleagues
A2: True Hospitality Service Skills | B2: IHG051263 | C2: 3 | D2: within 30 days | F2: Self-paced Online Learning (1 Hour 15 Minutes). Hotel-led in-person training (On-Job-Training, OJT) is permitted & completions must be tracked in myLearning. | G2: x | H2: x | I2: x | J2: x | K2: x | L2: x | M2: x | N2: x | O2: x | P2: x | Q2: x | R2: x | S2: x
A3: Holiday Inn Express Brand Service Training | B3: IHG4548388 | C3: 3 | D3: within 30 days | F3: Self-paced Online Learning (25 Minutes). Hotel-led in-person training (On-Job-Training, OJT) is permitted & completions must be tracked in myLearning. | G3: x | H3: x | I3: x | J3: x | K3: x | L3: x | M3: x | N3: x | O3: x | P3: x | Q3: x | R3: x | S3: x
A4: IHG Managed Hotels - Responsible Business Catalogue | B4: Guide for Managed Hotel Leaders | C4: 3 | D4: within 30 days | F4: For IHG Managed Hotels only; follow guidance on brand-standard related trainings | G4: x | H4: x | I4: x | J4: x | K4: x | L4: x | M4: x | R4: x
A5: IHG Managed Hotels - Responsible Business Catalogue | B5: Guide for Managed Hotel Colleagues | C5: 3 | D5: within 30 days | F5: For IHG Managed Hotels only; follow guidance on brand-standard related trainings | N5: x | O5: x | P5: x | Q5: x | S5: x
A6: Franchised Hotels - Responsible Business Catalogue | B6: Guide for Franchised Hotel Leaders | C6: 3 | D6: within 30 days | F6: For Franchised Hotels only; follow guidance on brand-standard related trainings | G6: x | H6: x | I6: x | J6: x | K6: x | L6: x | M6: x | R6: x
A7: Franchised Hotels - Responsible Business Catalogue | B7: Guide for Franchised Hotel Colleagues | C7: 3 | D7: within 30 days | F7: For Franchised Hotels only; follow guidance on brand-standard related trainings | N7: x | O7: x | P7: x | Q7: x | S7: x
A8: Hotel Experience Champion | B8: Hotel Experience Champion Program | C8: 3 | D8: within 30 days | F8: Not a specific course; review the Hotel Experience Champion Program and ensure Hotel Experience Champion role(s) have been assigned | G8: x
A9: Leading and Sustaining your Service Culture | B9: IHG0056403 | C9: 4 | D9: within 60 days | F9: Self-paced Online Learning (1 Hour 45 Minutes). | G9: x | H9: x | I9: x | J9: x | K9: x | L9: x | M9: x | R9: x
A10: Brand Service Tools & Resources | B10: Brand Service Tools & Resources | C10: 10 | D10: Suggested Learning | F10: Explore resource and apply accordingly | G10: x | H10: x | I10: x | J10: x | K10: x | L10: x | M10: x | R10: x
A11: IHG Problem Handling | B11: IHG056045 | C11: 3 | D11: within 30 days | F11: Self-paced Online Learning (1 Hour). Hotel-led in-person training (On-Job-Training, OJT) is permitted & completions must be tracked in myLearning. | G11: x | H11: x | I11: x | J11: x | K11: x | L11: x | M11: x | N11: x | O11: x | P11: x | Q11: x | R11: x | S11: x
A12: The Value of Loyalty | B12: IHG5072070 | C12: 3 | D12: within 30 days | F12: Self-paced Online Learning (20 Minutes). | G12: x | H12: x | I12: x | J12: x | K12: x | L12: x | M12: x | N12: x | O12: x | P12: x | Q12: x | R12: x | S12: x
A13: Leading Loyalty | B13: IHG6112495 | C13: 3 | D13: within 30 days | F13: Self-paced Online Learning (20 Minutes). | G13: x | H13: x | I13: x | J13: x | K13: x | L13: x | M13: x | R13: x
A14: IHG One Rewards Program Overview | B14: IHG8755255 | C14: 3 | D14: within 30 days | F14: Self-paced Online Learning (20 Minutes). | G14: x | H14: x | I14: x | J14: x | K14: x | L14: x | M14: x | N14: x | O14: x | P14: x | Q14: x | R14: x | S14: x
A15: Member Recognition | B15: IHG1984349 | C15: 3 | D15: within 30 days | F15: Self-paced Online Learning (15 Minutes). | G15: x | H15: x | I15: x | J15: x | K15: x | L15: x | M15: x | N15: x | O15: x | P15: x | Q15: x | R15: x | S15: x
A16: Value of Enrollments | B16: IHG2428898 | C16: 3 | D16: within 30 days | F16: Self-paced Online Learning (20 Minutes). | G16: x | H16: x | I16: x | J16: x | K16: x | L16: x | M16: x | N16: x | O16: x | P16: x | Q16: x | R16: x | S16: x
A17: IHG Business Rewards Training | B17: IHG0052543 | C17: 10 | D17: Suggested Learning | F17: Self-paced Online Learning. | G17: x | H17: x | I17: x | J17: x | K17: x | L17: x | M17: x | N17: x | R17: x | S17: x
A18: LoyaltyConnect | B18: IHG0049654 | C18: 10 | D18: Suggested Learning | F18: Self-paced Online Learning. | G18: x | J18: x | N18: x
A19: IHG Way of Clean 5-S Cleaning Program | B19: IHG7376524 | C19: 3 | D19: within 30 days | F19: Hotel-led in-person training (On-Job-Training, OJT) is permitted & completions must be tracked in myLearning. | K19: x | O19: x | P19: x
A20: IHG Way of Clean 5-S Cleaning Program for Non-Housekeeping colleagues | B20: IHG1227263 | C20: 3 | D20: within 30 days | F20: Self-paced Online Learning (20 Minutes). Hotel-led in-person training (On-Job-Training, OJT) is permitted & completions must be tracked in myLearning. | G20: x | H20: x | I20: x | J20: x | L20: x | M20: x | N20: x | Q20: x | R20: x | S20: x
A21: Getting to Know IHG Concerto | B21: IHG0049491 | C21: 10 | D21: Suggested Learning | F21: Self-paced Online Learning. | G21: x | H21: x | I21: x | J21: x
A22: IHG Concerto - MyID - Approvals | B22: IHG0054204 | C22: 10 | D22: Suggested Learning | F22: Self-paced Online Learning. | G22: x
A23: IHG Concerto - MyID - Assigning Concerto Access | B23: IHG0054203 | C23: 10 | D23: Suggested Learning | F23: Self-paced Online Learning. | G23: x
A24: IHG Concerto - MyID - Accessing IHG Concerto User Report | B24: IHG0054206 | C24: 10 | D24: Suggested Learning | F24: Self-paced Online Learning. | G24: x
A25: IHG Concerto - MyID - Removing Access | B25: IHG0054205 | C25: 10 | D25: Suggested Learning | F25: Self-paced Online Learning. | G25: x
A26: IHG Concerto Homepage overview | B26: IHG0052563 | C26: 10 | D26: Suggested Learning | F26: Self-paced Online Learning. | G26: x | H26: x | I26: x | J26: x
A27: IHG Concerto: Hotel Content Overview | B27: IHG0060624 | C27: 10 | D27: Suggested Learning | F27: Self-paced Online Learning (5 Minutes). | G27: x | H27: x | I27: x | J27: x
A28: Global Sales Induction | B28: IHG7573378 | C28: 10 | D28: Suggested Learning | F28: Self-paced Online Learning (25 Minutes). | G28: x | H28: x
A29: Sales Learning Pathway for On Property Sellers | B29: IHG3530707 | C29: 5 | D29: within 90 days | F29: Self-paced Online Learning (1 Hour 30 Minutes). | G29: x | H29: x
A30: Getting Started with MeetingBroker | B30: IHG0056663 | C30: 10 | D30: Suggested Learning | F30: Self-paced Online Learning. | G30: x | H30: x
A31: IHG Way of Sales - Solution Selling | B31: IHG0025681 | C31: 6 | D31: within 120 days | F31: In-person Instructor Led Course (see available dates & times by clicking the link below). Prerequisite: Must Complete Sales Learning Pathway | G31: x | H31: x
A32: GRS Fundamentals - Reservation, Rate and Inventory Management | B32: IHG0049459 | C32: 10 | D32: Suggested Learning | F32: Self-paced Online Learning. | G32: x | I32: x
A33: RMS Fundamentals: Yielding & Price Optimization | B33: IHG0049460 | C33: 10 | D33: Suggested Learning | F33: Self-paced Online Learning. | G33: x | I33: x
A34: IHG Concerto Hotel Release 2 - Inventory Reset Process Phase II | B34: IHG0061343 | C34: 10 | D34: Suggested Learning | F34: Self-paced Online Learning. | G34: x | I34: x
A35: IHG Concerto Hotel Release 2 - Inventory Reset Process Phase III | B35: IHG0061983 | C35: 10 | D35: Suggested Learning | F35: Self-paced Online Learning. | G35: x | I35: x
A36: IHG Concerto Inventory Configuration - Sleeping Rooms | B36: IHG1677402 | C36: 10 | D36: Suggested Learning | F36: Self-paced Online Learning. | G36: x | I36: x
A37: IHG Concerto - Getting to Know Inventory Balancing | B37: IHG0053503 | C37: 10 | D37: Suggested Learning | F37: Self-paced Online Learning. | G37: x | I37: x
A38: Revenue Management Certification | B38: RM Certification | C38: 5 | D38: within 90 days | I38: x
A39: General Manager Onboarding Learning Plan | B39: Onboarding Learning Plan | C39: 7 | D39: within 6 months | F39: Access to the system will automatically be given. For New Hotels - only to be completed after official hotel opening. | G39: x
A40: General Manager Onboarding Learning Event | B40: Registration Link | C40: 7 | D40: within 6 months | F40: Prerequisite: Must complete Onboarding Learning Plan | G40: x
...

Sheet Holiday Inn
A1: Holiday Inn | B1: Course ID | C1: Time Frame (1-10) Not Visible to Learner | D1: Time Frame Visible to Learner | E1: Priority: Y | F1: Notes | G1: General Manager | H1: Sales Team Leader | I1: Revenue Team Leader | J1: Front Office Team Leader | K1: Housekeeping Team Leader | L1: Food & Beverage Team Leader | M1: Engineering Team Leader | N1: Front Desk | O1: Housekeeping | P1: Food and Beverage | Q1: Engineering | R1: All other management colleagues | S1: All other non-management colleagues
A2: True Hospitality Service Skills | B2: IHG051263 | C2: 3 | D2: within 30 days | F2: Self-paced Online Learning (1 Hour 15 Minutes). Hotel-led in-person training (On-Job-Training, OJT) is permitted & completions must be tracked in myLearning. | G2: x | H2: x | I2: x | J2: x | K2: x | L2: x | M2: x | N2: x | O2: x | P2: x | Q2: x | R2: x | S2: x
A3: Holiday Inn Brand Service Training | B3: IHG3075650 | D3: Not found | F3: Self-paced Online Learning (1 Hour). Hotel-led in-person training (On-Job-Training, OJT) is permitted & completions must be tracked in myLearning. | G3: x | H3: x | I3: x | J3: x | K3: x | L3: x | M3: x | N3: x | O3: x | P3: x | Q3: x | R3: x | S3: x
A4: IHG Managed Hotels - Responsible Business Catalogue | B4: Guide for Managed Hotel Leaders | C4: 3 | D4: within 30 days | F4: For IHG Managed Hotels only; follow guidance on brand-standard related trainings | G4: x | H4: x | I4: x | J4: x | K4: x | L4: x | M4: x | R4: x
A5: IHG Managed Hotels - Responsible Business Catalogue | B5: Guide for Managed Hotel Colleagues | C5: 3 | D5: within 30 days | F5: For IHG Managed Hotels only; follow guidance on brand-standard related trainings | N5: x | O5: x | P5: x | Q5: x | S5: x
A6: Franchised Hotels - Responsible Business Catalogue | B6: Guide for Franchised Hotel Leaders | C6: 3 | D6: within 30 days | F6: For Franchised Hotels only; follow guidance on brand-standard related trainings | G6: x | H6: x | I6: x | J6: x | K6: x | L6: x | M6: x | R6: x
A7: Franchised Hotels - Responsible Business Catalogue | B7: Guide for Franchised Hotel Colleagues | C7: 3 | D7: within 30 days | F7: For Franchised Hotels only; follow guidance on brand-standard related trainings | N7: x | O7: x | P7: x | Q7: x | S7: x
A8: Hotel Experience Champion | B8: Hotel Experience Champion Program | C8: 3 | D8: within 30 days | F8: Not a specific course; review the Hotel Experience Champion Program and ensure Hotel Experience Champion role(s) have been assigned | G8: x
A9: Leading and Sustaining your Service Culture | B9: IHG0056403 | C9: 4 | D9: within 60 days | F9: Self-paced Online Learning (1 Hour 45 Minutes). | G9: x | H9: x | I9: x | J9: x | K9: x | L9: x | M9: x | R9: x
A10: Brand Service Tools & Resources | B10: Brand Service Tools & Resources | C10: 10 | D10: Suggested Learning | F10: Explore resource and apply accordingly | G10: x | H10: x | I10: x | J10: x | K10: x | L10: x | M10: x | R10: x
A11: IHG Problem Handling | B11: IHG056045 | C11: 3 | D11: within 30 days | F11: Self-paced Online Learning (1 Hour). Hotel-led in-person training (On-Job-Training, OJT) is permitted & completions must be tracked in myLearning. | G11: x | H11: x | I11: x | J11: x | K11: x | L11: x | M11: x | N11: x | O11: x | P11: x | Q11: x | R11: x | S11: x
A12: The Value of Loyalty | B12: IHG5072070 | C12: 3 | D12: within 30 days | F12: Self-paced Online Learning (20 Minutes). | G12: x | H12: x | I12: x | J12: x | K12: x | L12: x | M12: x | N12: x | O12: x | P12: x | Q12: x | R12: x | S12: x
A13: Leading Loyalty | B13: IHG6112495 | C13: 3 | D13: within 30 days | F13: Self-paced Online Learning (20 Minutes). | G13: x | H13: x | I13: x | J13: x | K13: x | L13: x | M13: x | R13: x
A14: IHG One Rewards Program Overview | B14: IHG8755255 | C14: 3 | D14: within 30 days | F14: Self-paced Online Learning (20 Minutes). | G14: x | H14: x | I14: x | J14: x | K14: x | L14: x | M14: x | N14: x | O14: x | P14: x | Q14: x | R14: x | S14: x
A15: Member Recognition | B15: IHG1984349 | C15: 3 | D15: within 30 days | F15: Self-paced Online Learning (15 Minutes). | G15: x | H15: x | I15: x | J15: x | K15: x | L15: x | M15: x | N15: x | O15: x | P15: x | Q15: x | R15: x | S15: x
A16: The Value of Enrollments | B16: IHG2428898 | C16: 3 | D16: within 30 days | F16: Self-paced Online Learning (20 Minutes). | G16: x | H16: x | I16: x | J16: x | K16: x | L16: x | M16: x | N16: x | O16: x | P16: x | Q16: x | R16: x | S16: x
A17: IHG Business Rewards Training | B17: IHG0052543 | C17: 10 | D17: Suggested Learning | F17: Self-paced Online Learning. | G17: x | H17: x | I17: x | J17: x | K17: x | L17: x | M17: x | N17: x | R17: x | S17: x
A18: LoyaltyConnect | B18: IHG0049654 | C18: 10 | D18: Suggested Learning | F18: Self-paced Online Learning. | G18: x | J18: x | N18: x
A19: IHG Way of Clean 5-S Cleaning Program | B19: IHG7376524 | C19: 3 | D19: within 30 days | F19: Hotel-led in-person training (On-Job-Training, OJT) is permitted & completions must be tracked in myLearning. | K19: x | O19: x | P19: x
A20: IHG Way of Clean 5-S Cleaning Program for Non-Housekeeping colleagues | B20: IHG1227263 | C20: 3 | D20: within 30 days | F20: Self-paced Online Learning (20 Minutes). Hotel-led in-person training (On-Job-Training, OJT) is permitted & completions must be tracked in myLearning. | G20: x | H20: x | I20: x | J20: x | L20: x | M20: x | N20: x | Q20: x | R20: x | S20: x
A21: Getting to Know IHG Concerto | B21: IHG0049491 | C21: 10 | D21: Suggested Learning | F21: Self-paced Online Learning. | G21: x | H21: x | I21: x | J21: x
A22: IHG Concerto - MyID - Approvals | B22: IHG0054204 | C22: 10 | D22: Suggested Learning | F22: Self-paced Online Learning. | G22: x
A23: IHG Concerto - MyID - Assigning Concerto Access | B23: IHG0054203 | C23: 10 | D23: Suggested Learning | F23: Self-paced Online Learning. | G23: x
A24: IHG Concerto - MyID - Accessing IHG Concerto User Report | B24: IHG0054206 | C24: 10 | D24: Suggested Learning | F24: Self-paced Online Learning. | G24: x
A25: IHG Concerto - MyID - Removing Access | B25: IHG0054205 | C25: 10 | D25: Suggested Learning | F25: Self-paced Online Learning. | G25: x
A26: IHG Concerto Homepage overview | B26: IHG0052563 | C26: 10 | D26: Suggested Learning | F26: Self-paced Online Learning. | G26: x | H26: x | I26: x | J26: x
A27: IHG Concerto: Hotel Content Overview | B27: IHG0060624 | C27: 10 | D27: Suggested Learning | F27: Self-paced Online Learning (5 Minutes). | G27: x | H27: x | I27: x | J27: x
A28: Global Sales Induction | B28: IHG7573378 | C28: 10 | D28: Suggested Learning | F28: Self-paced Online Learning (25 Minutes). | G28: x | H28: x
A29: Sales Learning Pathway for On Property Sellers | B29: IHG3530707 | C29: 5 | D29: within 90 days | F29: Self-paced Online Learning (1 Hour 30 Minutes). | G29: x | H29: x
A30: Getting Started with MeetingBroker | B30: IHG0056663 | C30: 10 | D30: Suggested Learning | F30: Self-paced Online Learning. | G30: x | H30: x
A31: IHG Way of Sales - Solution Selling | B31: IHG0025681 | C31: 6 | D31: within 120 days | F31: In-person Instructor Led Course (see available dates & times by clicking the link below). Prerequisite: Must Complete Sales Learning Pathway | G31: x | H31: x
A32: GRS Fundamentals - Reservation, Rate and Inventory Management | B32: IHG0049459 | C32: 10 | D32: Suggested Learning | F32: Self-paced Online Learning. | G32: x | I32: x
A33: RMS Fundamentals: Yielding & Price Optimization | B33: IHG0049460 | C33: 10 | D33: Suggested Learning | F33: Self-paced Online Learning. | G33: x | I33: x
A34: IHG Concerto Hotel Release 2 - Inventory Reset Process Phase II | B34: IHG0061343 | C34: 10 | D34: Suggested Learning | F34: Self-paced Online Learning. | G34: x | I34: x
A35: IHG Concerto Hotel Release 2 - Inventory Reset Process Phase III | B35: IHG0061983 | C35: 10 | D35: Suggested Learning | F35: Self-paced Online Learning. | G35: x | I35: x
A36: IHG Concerto Inventory Configuration - Sleeping Rooms | B36: IHG1677402 | C36: 10 | D36: Suggested Learning | F36: Self-paced Online Learning. | G36: x | I36: x
A37: IHG Concerto - Getting to Know Inventory Balancing | B37: IHG0053503 | C37: 10 | D37: Suggested Learning | F37: Self-paced Online Learning. | G37: x | I37: x
A38: Revenue Management Certification | B38: RM Certification | C38: 5 | D38: within 90 days | I38: x
A39: General Manager Onboarding Learning Plan | B39: Onboarding Learning Plan | C39: 7 | D39: within 6 months | F39: Access to the system will automatically be given. For New Hotels - only to be completed after official hotel opening. | G39: x
A40: General Manager Onboarding Learning Event | B40: Registration Link | C40: 7 | D40: within 6 months | F40: Prerequisite: Must complete Onboarding Learning Plan | G40: x
...

Sheet Staybridge Suites
A1: Staybridge Suites | B1: Course ID | C1: Time Frame (1-10) Not Visible to Learner | D1: Time Frame Visible to Learner | E1: Priority: Y | F1: Notes | G1: General Manager | H1: Sales Team Leader | I1: Revenue Team Leader | J1: Front Office Team Leader | K1: Housekeeping Team Leader | L1: Food & Beverage Team Leader | M1: Engineering Team Leader | N1: Front Desk | O1: Housekeeping | P1: Food and Beverage | Q1: Engineering | R1: All other management colleagues | S1: All other non-management colleagues
A2: True Hospitality Service Skills | B2: IHG051263 | C2: 3 | D2: within 30 days | F2: Self-paced Online Learning (1 Hour 15 Minutes). Hotel-led in-person training (On-Job-Training, OJT) is permitted & completions must be tracked in myLearning. | G2: x | H2: x | I2: x | J2: x | K2: x | L2: x | M2: x | N2: x | O2: x | P2: x | Q2: x | R2: x | S2: x
A3: Staybridge Suites Brand Orientation | B3: IHG058783 | C3: 3 | D3: within 30 days | F3: Self-paced Online Learning (30 Minutes). Hotel-led in-person training (On-Job-Training, OJT) is permitted & completions must be tracked in myLearning. | G3: x | H3: x | I3: x | J3: x | K3: x | L3: x | M3: x | N3: x | O3: x | P3: x | Q3: x | R3: x | S3: x
A4: Staybridge Suites Brand Experience Training | B4: IHG058784 | C4: 3 | D4: within 30 days | F4: Self-paced Online Learning (30 Minutes). Hotel-led in-person training (On-Job-Training, OJT) is permitted & completions must be tracked in myLearning. | G4: x | H4: x | I4: x | J4: x | K4: x | L4: x | M4: x | N4: x | O4: x | P4: x | Q4: x | R4: x | S4: x
A5: IHG Managed Hotels - Responsible Business Catalogue | B5: Guide for Managed Hotel Leaders | C5: 3 | D5: within 30 days | F5: For IHG Managed Hotels only; follow guidance on brand-standard related trainings | G5: x | H5: x | I5: x | J5: x | K5: x | L5: x | M5: x | R5: x
A6: IHG Managed Hotels - Responsible Business Catalogue | B6: Guide for Managed Hotel Colleagues | C6: 3 | D6: within 30 days | F6: For IHG Managed Hotels only; follow guidance on brand-standard related trainings | N6: x | O6: x | P6: x | Q6: x | S6: x
A7: Franchised Hotels - Responsible Business Catalogue | B7: Guide for Franchised Hotel Leaders | C7: 3 | D7: within 30 days | F7: For Franchised Hotels only; follow guidance on brand-standard related trainings | G7: x | H7: x | I7: x | J7: x | K7: x | L7: x | M7: x | R7: x
A8: Franchised Hotels - Responsible Business Catalogue | B8: Guide for Franchised Hotel Colleagues | C8: 3 | D8: within 30 days | F8: For Franchised Hotels only; follow guidance on brand-standard related trainings | N8: x | O8: x | P8: x | Q8: x | S8: x
A9: Hotel Experience Champion | B9: Hotel Experience Champion Program | C9: 3 | D9: within 30 days | F9: Not a specific course; review the Hotel Experience Champion Program and ensure Hotel Experience Champion role(s) have been assigned | G9: x
A10: Leading and Sustaining your Service Culture | B10: IHG0056403 | C10: 4 | D10: within 60 days | F10: Self-paced Online Learning (1 Hour 45 Minutes). | G10: x | H10: x | I10: x | J10: x | K10: x | L10: x | M10: x | R10: x
A11: Brand Service Tools & Resources | B11: Brand Service Tools & Resources | C11: 10 | D11: Suggested Learning | F11: Explore resource and apply accordingly | G11: x | H11: x | I11: x | J11: x | K11: x | L11: x | M11: x | R11: x
A12: IHG Problem Handling | B12: IHG056045 | C12: 3 | D12: within 30 days | F12: Self-paced Online Learning (1 Hour). Hotel-led in-person training (On-Job-Training, OJT) is permitted & completions must be tracked in myLearning. | G12: x | H12: x | I12: x | J12: x | K12: x | L12: x | M12: x | N12: x | O12: x | P12: x | Q12: x | R12: x | S12: x
A13: The Value of Loyalty | B13: IHG5072070 | C13: 3 | D13: within 30 days | F13: Self-paced Online Learning (20 Minutes). | G13: x | H13: x | I13: x | J13: x | K13: x | L13: x | M13: x | N13: x | O13: x | P13: x | Q13: x | R13: x | S13: x
A14: Leading Loyalty | B14: IHG6112495 | C14: 3 | D14: within 30 days | F14: Self-paced Online Learning (20 Minutes). | G14: x | H14: x | I14: x | J14: x | K14: x | L14: x | M14: x | R14: x
A15: IHG One Rewards Program Overview | B15: IHG8755255 | C15: 3 | D15: within 30 days | F15: Self-paced Online Learning (20 Minutes). | G15: x | H15: x | I15: x | J15: x | K15: x | L15: x | M15: x | N15: x | O15: x | P15: x | Q15: x | R15: x | S15: x
A16: Member Recognition | B16: IHG1984349 | C16: 3 | D16: within 30 days | F16: Self-paced Online Learning (15 Minutes). | G16: x | H16: x | I16: x | J16: x | K16: x | L16: x | M16: x | N16: x | O16: x | P16: x | Q16: x | R16: x | S16: x
A17: The Value of Enrollments | B17: IHG2428898 | C17: 3 | D17: within 30 days | F17: Self-paced Online Learning (20 Minutes). | G17: x | H17: x | I17: x | J17: x | K17: x | L17: x | M17: x | N17: x | O17: x | P17: x | Q17: x | R17: x | S17: x
A18: IHG Business Rewards Training | B18: IHG0052543 | C18: 10 | D18: Suggested Learning | F18: Self-paced Online Learning. | G18: x | H18: x | I18: x | J18: x | K18: x | L18: x | M18: x | N18: x | R18: x | S18: x
A19: LoyaltyConnect | B19: IHG0049654 | C19: 10 | D19: Suggested Learning | F19: Self-paced Online Learning. | G19: x | J19: x | N19: x
A20: IHG Way of Clean 5-S Cleaning Program | B20: IHG7376524 | C20: 3 | D20: within 30 days | F20: Hotel-led in-person training (On-Job-Training, OJT) is permitted & completions must be tracked in myLearning. | K20: x | O20: x
A21: IHG Way of Clean 5-S Cleaning Program for Non-Housekeeping colleagues | B21: IHG1227263 | C21: 3 | D21: within 30 days | F21: Self-paced Online Learning (20 Minutes). Hotel-led in-person training (On-Job-Training, OJT) is permitted & completions must be tracked in myLearning. | G21: x | H21: x | I21: x | J21: x | L21: x | M21: x | N21: x | P21: x | Q21: x | R21: x | S21: x
A22: Getting to Know IHG Concerto | B22: IHG0049491 | C22: 10 | D22: Suggested Learning | F22: Self-paced Online Learning. | G22: x | H22: x | I22: x | J22: x
A23: IHG Concerto - MyID - Approvals | B23: IHG0054204 | C23: 10 | D23: Suggested Learning | F23: Self-paced Online Learning. | G23: x
A24: IHG Concerto - MyID - Assigning Concerto Access | B24: IHG0054203 | C24: 10 | D24: Suggested Learning | F24: Self-paced Online Learning. | G24: x
A25: IHG Concerto - MyID - Accessing IHG Concerto User Report | B25: IHG0054206 | C25: 10 | D25: Suggested Learning | F25: Self-paced Online Learning. | G25: x
A26: IHG Concerto - MyID - Removing Access | B26: IHG0054205 | C26: 10 | D26: Suggested Learning | F26: Self-paced Online Learning. | G26: x
A27: IHG Concerto Homepage overview | B27: IHG0052563 | C27: 10 | D27: Suggested Learning | F27: Self-paced Online Learning. | G27: x | H27: x | I27: x | J27: x
A28: IHG Concerto: Hotel Content Overview | B28: IHG0060624 | C28: 10 | D28: Suggested Learning | F28: Self-paced Online Learning (5 Minutes). | G28: x | H28: x | I28: x | J28: x
A29: Global Sales Induction | B29: IHG7573378 | C29: 10 | D29: Suggested Learning | F29: Self-paced Online Learning (25 Minutes). | G29: x | H29: x
A30: Sales Learning Pathway for On Property Sellers | B30: IHG3530707 | C30: 5 | D30: within 90 days | F30: Self-paced Online Learning (1 Hour 30 Minutes). | G30: x | H30: x
A31: Getting Started with MeetingBroker | B31: IHG0056663 | C31: 10 | D31: Suggested Learning | F31: Self-paced Online Learning. | G31: x | H31: x
A32: IHG Way of Sales - Solution Selling | B32: IHG0025681 | C32: 6 | D32: within 120 days | F32: In-person Instructor Led Course (see available dates & times by clicking the link below). Prerequisite: Must Complete Sales Learning Pathway | G32: x | H32: x
A33: GRS Fundamentals - Reservation, Rate and Inventory Management | B33: IHG0049459 | C33: 10 | D33: Suggested Learning | F33: Self-paced Online Learning. | G33: x | I33: x
A34: RMS Fundamentals: Yielding & Price Optimization | B34: IHG0049460 | C34: 10 | D34: Suggested Learning | F34: Self-paced Online Learning. | G34: x | I34: x
A35: IHG Concerto Hotel Release 2 - Inventory Reset Process Phase II | B35: IHG0061343 | C35: 10 | D35: Suggested Learning | F35: Self-paced Online Learning. | G35: x | I35: x
A36: IHG Concerto Hotel Release 2 - Inventory Reset Process Phase III | B36: IHG0061983 | C36: 10 | D36: Suggested Learning | F36: Self-paced Online Learning. | G36: x | I36: x
A37: IHG Concerto Inventory Configuration - Sleeping Rooms | B37: IHG1677402 | C37: 10 | D37: Suggested Learning | F37: Self-paced Online Learning. | G37: x | I37: x
A38: IHG Concerto - Getting to Know Inventory Balancing | B38: IHG0053503 | C38: 10 | D38: Suggested Learning | F38: Self-paced Online Learning. | G38: x | I38: x
A39: Revenue Management Certification | B39: RM Certification | C39: 5 | D39: within 90 days | I39: x
A40: General Manager Onboarding Learning Plan | B40: Onboarding Learning Plan | C40: 7 | D40: within 6 months | F40: Access to the system will automatically be given. For New Hotels - only to be completed after official hotel opening. | G40: x
...

Sheet voco
A1: voco | B1: Course ID | C1: Time Frame (1-10) Not Visible to Learner | D1: Time Frame Visible to Learner | E1: Priority: Y | F1: Notes | G1: General Manager | H1: Sales Team Leader | I1: Revenue Team Leader | J1: Front Office Team Leader | K1: Housekeeping Team Leader | L1: Food & Beverage Team Leader | M1: Engineering Team Leader | N1: Front Desk | O1: Housekeeping | P1: Food and Beverage | Q1: Engineering | R1: All other management colleagues | S1: All other non-management colleagues
A2: True Hospitality Service Skills | B2: IHG051263 | C2: 3 | D2: within 30 days | F2: Self-paced Online Learning (1 Hour 15 Minutes). Hotel-led in-person training (On-Job-Training, OJT) is permitted & completions must be tracked in myLearning. | G2: x | H2: x | I2: x | J2: x | K2: x | L2: x | M2: x | N2: x | O2: x | P2: x | Q2: x | R2: x | S2: x
A3: voco hotels Brand Orientation | B3: IHG0065384 | C3: 3 | D3: within 30 days | F3: Self-paced Online Learning (40 Minutes). Hotel-led in-person training (On-Job-Training, OJT) is permitted & completions must be tracked in myLearning. | G3: x | H3: x | I3: x | J3: x | K3: x | L3: x | M3: x | N3: x | O3: x | P3: x | Q3: x | R3: x | S3: x
A4: voco hotels Brand Experience | B4: IHG0066043 | C4: 3 | D4: within 30 days | F4: Self-paced Online Learning (20 Minutes). Hotel-led in-person training (On-Job-Training, OJT) is permitted & completions must be tracked in myLearning. | G4: x | H4: x | I4: x | J4: x | K4: x | L4: x | M4: x | N4: x | O4: x | P4: x | Q4: x | R4: x | S4: x
A5: IHG Managed Hotels - Responsible Business Catalogue | B5: Guide for Managed Hotel Leaders | C5: 3 | D5: within 30 days | F5: For IHG Managed Hotels only; follow guidance on brand-standard related trainings | G5: x | H5: x | I5: x | J5: x | K5: x | L5: x | M5: x | R5: x
A6: IHG Managed Hotels - Responsible Business Catalogue | B6: Guide for Managed Hotel Colleagues | C6: 3 | D6: within 30 days | F6: For IHG Managed Hotels only; follow guidance on brand-standard related trainings | N6: x | O6: x | P6: x | Q6: x | S6: x
A7: Franchised Hotels - Responsible Business Catalogue | B7: Guide for Franchised Hotel Leaders | C7: 3 | D7: within 30 days | F7: For Franchised Hotels only; follow guidance on brand-standard related trainings | G7: x | H7: x | I7: x | J7: x | K7: x | L7: x | M7: x | R7: x
A8: Franchised Hotels - Responsible Business Catalogue | B8: Guide for Franchised Hotel Colleagues | C8: 3 | D8: within 30 days | F8: For Franchised Hotels only; follow guidance on brand-standard related trainings | N8: x | O8: x | P8: x | Q8: x | S8: x
A9: Hotel Experience Champion | B9: Hotel Experience Champion Program | C9: 3 | D9: within 30 days | F9: Not a specific course; review the Hotel Experience Champion Program and ensure Hotel Experience Champion role(s) have been assigned | G9: x
A10: Leading and Sustaining your Service Culture | B10: IHG0056403 | C10: 4 | D10: within 60 days | F10: Self-paced Online Learning (1 Hour 45 Minutes). | G10: x | H10: x | I10: x | J10: x | K10: x | L10: x | M10: x | R10: x
A11: Brand Service Tools & Resources | B11: Brand Service Tools & Resources | C11: 10 | D11: Suggested Learning | F11: Explore resource and apply accordingly | G11: x | H11: x | I11: x | J11: x | K11: x | L11: x | M11: x | R11: x
A12: IHG Problem Handling | B12: IHG056045 | C12: 3 | D12: within 30 days | F12: Self-paced Online Learning (1 Hour). Hotel-led in-person training (On-Job-Training, OJT) is permitted & completions must be tracked in myLearning. | G12: x | H12: x | I12: x | J12: x | K12: x | L12: x | M12: x | N12: x | O12: x | P12: x | Q12: x | R12: x | S12: x
A13: The Value of Loyalty | B13: IHG5072070 | C13: 3 | D13: within 30 days | F13: Self-paced Online Learning (20 Minutes). | G13: x | H13: x | I13: x | J13: x | K13: x | L13: x | M13: x | N13: x | O13: x | P13: x | Q13: x | R13: x | S13: x
A14: Leading Loyalty | B14: IHG6112495 | C14: 3 | D14: within 30 days | F14: Self-paced Online Learning (20 Minutes). | G14: x | H14: x | I14: x | J14: x | K14: x | L14: x | M14: x | R14: x
A15: IHG One Rewards Program Overview | B15: IHG8755255 | C15: 3 | D15: within 30 days | F15: Self-paced Online Learning (20 Minutes). | G15: x | H15: x | I15: x | J15: x | K15: x | L15: x | M15: x | N15: x | O15: x | P15: x | Q15: x | R15: x | S15: x
A16: Member Recognition | B16: IHG1984349 | C16: 3 | D16: within 30 days | F16: Self-paced Online Learning (15 Minutes). | G16: x | H16: x | I16: x | J16: x | K16: x | L16: x | M16: x | N16: x | O16: x | P16: x | Q16: x | R16: x | S16: x
A17: The Value of Enrollments | B17: IHG2428898 | C17: 3 | D17: within 30 days | F17: Self-paced Online Learning (20 Minutes). | G17: x | H17: x | I17: x | J17: x | K17: x | L17: x | M17: x | N17: x | O17: x | P17: x | Q17: x | R17: x | S17: x
A18: IHG Business Rewards Training | B18: IHG0052543 | C18: 10 | D18: Suggested Learning | F18: Self-paced Online Learning. | G18: x | H18: x | I18: x | J18: x | K18: x | L18: x | M18: x | N18: x | R18: x | S18: x
A19: LoyaltyConnect | B19: IHG0049654 | C19: 10 | D19: Suggested Learning | F19: Self-paced Online Learning. | G19: x | J19: x | N19: x
A20: IHG Way of Clean 5-S Cleaning Program | B20: IHG7376524 | C20: 3 | D20: within 30 days | F20: Hotel-led in-person training (On-Job-Training, OJT) is permitted & completions must be tracked in myLearning. | K20: x | O20: x | P20: x
A21: IHG Way of Clean 5-S Cleaning Program for Non-Housekeeping colleagues | B21: IHG1227263 | C21: 3 | D21: within 30 days | F21: Self-paced Online Learning (20 Minutes). Hotel-led in-person training (On-Job-Training, OJT) is permitted & completions must be tracked in myLearning. | G21: x | H21: x | I21: x | J21: x | L21: x | M21: x | N21: x | Q21: x | R21: x | S21: x
A22: Getting to Know IHG Concerto | B22: IHG0049491 | C22: 10 | D22: Suggested Learning | F22: Self-paced Online Learning. | G22: x | H22: x | I22: x | J22: x
A23: IHG Concerto - MyID - Approvals | B23: IHG0054204 | C23: 10 | D23: Suggested Learning | F23: Self-paced Online Learning. | G23: x
A24: IHG Concerto - MyID - Assigning Concerto Access | B24: IHG0054203 | C24: 10 | D24: Suggested Learning | F24: Self-paced Online Learning. | G24: x
A25: IHG Concerto - MyID - Accessing IHG Concerto User Report | B25: IHG0054206 | C25: 10 | D25: Suggested Learning | F25: Self-paced Online Learning. | G25: x
A26: IHG Concerto - MyID - Removing Access | B26: IHG0054205 | C26: 10 | D26: Suggested Learning | F26: Self-paced Online Learning. | G26: x
A27: IHG Concerto Homepage overview | B27: IHG0052563 | C27: 10 | D27: Suggested Learning | F27: Self-paced Online Learning. | G27: x | H27: x | I27: x | J27: x
A28: IHG Concerto: Hotel Content Overview | B28: IHG0060624 | C28: 10 | D28: Suggested Learning | F28: Self-paced Online Learning (5 Minutes). | G28: x | H28: x | I28: x | J28: x
A29: Global Sales Induction | B29: IHG7573378 | C29: 10 | D29: Suggested Learning | F29: Self-paced Online Learning (25 Minutes). | G29: x | H29: x
A30: Sales Learning Pathway for On Property Sellers | B30: IHG3530707 | C30: 5 | D30: within 90 days | F30: Self-paced Online Learning (1 Hour 30 Minutes). | G30: x | H30: x
A31: Getting Started with MeetingBroker | B31: IHG0056663 | C31: 10 | D31: Suggested Learning | F31: Self-paced Online Learning. | G31: x | H31: x
A32: IHG Way of Sales - Solution Selling | B32: IHG0025681 | C32: 6 | D32: within 120 days | F32: In-person Instructor Led Course (see available dates & times by clicking the link below). Prerequisite: Must Complete Sales Learning Pathway | G32: x | H32: x
A33: GRS Fundamentals - Reservation, Rate and Inventory Management | B33: IHG0049459 | C33: 10 | D33: Suggested Learning | F33: Self-paced Online Learning. | G33: x | I33: x
A34: RMS Fundamentals: Yielding & Price Optimization | B34: IHG0049460 | C34: 10 | D34: Suggested Learning | F34: Self-paced Online Learning. | G34: x | I34: x
A35: IHG Concerto Hotel Release 2 - Inventory Reset Process Phase II | B35: IHG0061343 | C35: 10 | D35: Suggested Learning | F35: Self-paced Online Learning. | G35: x | I35: x
A36: IHG Concerto Hotel Release 2 - Inventory Reset Process Phase III | B36: IHG0061983 | C36: 10 | D36: Suggested Learning | F36: Self-paced Online Learning. | G36: x | I36: x
A37: IHG Concerto Inventory Configuration - Sleeping Rooms | B37: IHG1677402 | C37: 10 | D37: Suggested Learning | F37: Self-paced Online Learning. | G37: x | I37: x
A38: IHG Concerto - Getting to Know Inventory Balancing | B38: IHG0053503 | C38: 10 | D38: Suggested Learning | F38: Self-paced Online Learning. | G38: x | I38: x
A39: Revenue Management Certification | B39: RM Certification | C39: 5 | D39: within 90 days | I39: x
A40: General Manager Onboarding Learning Plan | B40: Onboarding Learning Plan | C40: 7 | D40: within 6 months | F40: Access to the system will automatically be given. For New Hotels - only to be completed after official hotel opening. | G40: x
...

Sheet Crowne Plaza
A1: Crowne Plaza | B1: Course ID | C1: Time Frame (1-10) Not Visible to Learner | D1: Time Frame Visible to Learner | E1: Priority: Y | F1: Notes | G1: General Manager | H1: Sales Team Leader | I1: Revenue Team Leader | J1: Front Office Team Leader | K1: Housekeeping Team Leader | L1: Food & Beverage Team Leader | M1: Engineering Team Leader | N1: Front Desk | O1: Housekeeping | P1: Food and Beverage | Q1: Engineering | R1: All other management colleagues | S1: All other non-management colleagues
A2: True Hospitality Service Skills | B2: IHG051263 | C2: 3 | D2: within 30 days | F2: Self-paced Online Learning (1 Hour 15 Minutes). Hotel-led in-person training (On-Job-Training, OJT) is permitted & completions must be tracked in myLearning. | G2: x | H2: x | I2: x | J2: x | K2: x | L2: x | M2: x | N2: x | O2: x | P2: x | Q2: x | R2: x | S2: x
A3: Crowne Plaza Brand Orientation | B3: IHG051234 | C3: 3 | D3: within 30 days | F3: Self-paced Online Learning (1 Hour 30 Minutes). Hotel-led in-person training (On-Job-Training, OJT) is permitted & completions must be tracked in myLearning. | G3: x | H3: x | I3: x | J3: x | K3: x | L3: x | M3: x | N3: x | O3: x | P3: x | Q3: x | R3: x | S3: x
A4: Europe Hotels - Crowne Plaza Dare to Connect Brand Experience Training | B4: IHG058303 | C4: 3 | D4: within 30 days | F4: For hotels in Europe only; Self-paced Online Learning (2 Hours 30 Minutes). Hotel-led in-person training (On-Job-Training, OJT) is permitted & completions must be tracked in myLearning. | G4: x | H4: x | I4: x | J4: x | K4: x | L4: x | M4: x | N4: x | O4: x | P4: x | Q4: x | R4: x | S4: x
A5: Middle East, Africa and Asia Hotels - Crowne Plaza Dare to Connect Brand Experience Training | B5: IHG0059211 | C5: 3 | D5: within 30 days | F5: For hotels outside of Europe only; Self-paced Online Learning (2 Hours 30 Minutes). Hotel-led in-person training (On-Job-Training, OJT) is permitted & completions must be tracked in myLearning. | G5: x | H5: x | I5: x | J5: x | K5: x | L5: x | M5: x | N5: x | O5: x | P5: x | Q5: x | R5: x | S5: x
A6: IHG Managed Hotels - Responsible Business Catalogue | B6: Guide for Managed Hotel Leaders | C6: 3 | D6: within 30 days | F6: For IHG Managed Hotels only; follow guidance on brand-standard related trainings | G6: x | H6: x | I6: x | J6: x | K6: x | L6: x | M6: x | R6: x
A7: IHG Managed Hotels - Responsible Business Catalogue | B7: Guide for Managed Hotel Colleagues | C7: 3 | D7: within 30 days | F7: For IHG Managed Hotels only; follow guidance on brand-standard related trainings | N7: x | O7: x | P7: x | Q7: x | S7: x
A8: Franchised Hotels - Responsible Business Catalogue | B8: Guide for Franchised Hotel Leaders | C8: 3 | D8: within 30 days | F8: For Franchised Hotels only; follow guidance on brand-standard related trainings | G8: x | H8: x | I8: x | J8: x | K8: x | L8: x | M8: x | R8: x
A9: Franchised Hotels - Responsible Business Catalogue | B9: Guide for Franchised Hotel Colleagues | C9: 3 | D9: within 30 days | F9: For Franchised Hotels only; follow guidance on brand-standard related trainings | N9: x | O9: x | P9: x | Q9: x | S9: x
A10: Hotel Experience Champion | B10: Hotel Experience Champion Program | C10: 3 | D10: within 30 days | F10: Not a specific course; review the Hotel Experience Champion Program and ensure Hotel Experience Champion role(s) have been assigned | G10: x
A11: Leading and Sustaining your Service Culture | B11: IHG0056403 | C11: 4 | D11: within 60 days | F11: Self-paced Online Learning (1 Hour 45 Minutes). | G11: x | H11: x | I11: x | J11: x | K11: x | L11: x | M11: x | R11: x
A12: Brand Service Tools & Resources | B12: Brand Service Tools & Resources | C12: 10 | D12: Suggested Learning | F12: Explore resource and apply accordingly | G12: x | H12: x | I12: x | J12: x | K12: x | L12: x | M12: x | R12: x
A13: IHG Problem Handling | B13: IHG056045 | C13: 3 | D13: within 30 days | F13: Self-paced Online Learning (1 Hour). Hotel-led in-person training (On-Job-Training, OJT) is permitted & completions must be tracked in myLearning. | G13: x | H13: x | I13: x | J13: x | K13: x | L13: x | M13: x | N13: x | O13: x | P13: x | Q13: x | R13: x | S13: x
A14: The Value of Loyalty | B14: IHG5072070 | C14: 3 | D14: within 30 days | F14: Self-paced Online Learning (20 Minutes). | G14: x | H14: x | I14: x | J14: x | K14: x | L14: x | M14: x | N14: x | O14: x | P14: x | Q14: x | R14: x | S14: x
A15: Leading Loyalty | B15: IHG6112495 | C15: 3 | D15: within 30 days | F15: Self-paced Online Learning (20 Minutes). | G15: x | H15: x | I15: x | J15: x | K15: x | L15: x | M15: x | R15: x
A16: IHG One Rewards Program Overview | B16: IHG8755255 | C16: 3 | D16: within 30 days | F16: Self-paced Online Learning (20 Minutes). | G16: x | H16: x | I16: x | J16: x | K16: x | L16: x | M16: x | N16: x | O16: x | P16: x | Q16: x | R16: x | S16: x
A17: Member Recognition | B17: IHG1984349 | C17: 3 | D17: within 30 days | F17: Self-paced Online Learning (15 Minutes). | G17: x | H17: x | I17: x | J17: x | K17: x | L17: x | M17: x | N17: x | O17: x | P17: x | Q17: x | R17: x | S17: x
A18: The Value of Enrollments | B18: IHG2428898 | C18: 3 | D18: within 30 days | F18: Self-paced Online Learning (20 Minutes). | G18: x | H18: x | I18: x | J18: x | K18: x | L18: x | M18: x | N18: x | O18: x | P18: x | Q18: x | R18: x | S18: x
A19: IHG Business Rewards Training | B19: IHG0052543 | C19: 10 | D19: Suggested Learning | F19: Self-paced Online Learning. | G19: x | H19: x | I19: x | J19: x | K19: x | L19: x | M19: x | N19: x | R19: x | S19: x
A20: LoyaltyConnect | B20: IHG0049654 | C20: 10 | D20: Suggested Learning | F20: Self-paced Online Learning. | G20: x | J20: x | N20: x
A21: IHG Way of Clean 5-S Cleaning Program | B21: IHG7376524 | C21: 3 | D21: within 30 days | F21: Hotel-led in-person training (On-Job-Training, OJT) is permitted & completions must be tracked in myLearning. | K21: x | O21: x | P21: x
A22: IHG Way of Clean 5-S Cleaning Program for Non-Housekeeping colleagues | B22: IHG1227263 | C22: 3 | D22: within 30 days | F22: Self-paced Online Learning (20 Minutes). Hotel-led in-person training (On-Job-Training, OJT) is permitted & completions must be tracked in myLearning. | G22: x | H22: x | I22: x | J22: x | L22: x | M22: x | N22: x | Q22: x | R22: x | S22: x
A23: Getting to Know IHG Concerto | B23: IHG0049491 | C23: 10 | D23: Suggested Learning | F23: Self-paced Online Learning. | G23: x | H23: x | I23: x | J23: x
A24: IHG Concerto - MyID - Approvals | B24: IHG0054204 | C24: 10 | D24: Suggested Learning | F24: Self-paced Online Learning. | G24: x
A25: IHG Concerto - MyID - Assigning Concerto Access | B25: IHG0054203 | C25: 10 | D25: Suggested Learning | F25: Self-paced Online Learning. | G25: x
A26: IHG Concerto - MyID - Accessing IHG Concerto User Report | B26: IHG0054206 | C26: 10 | D26: Suggested Learning | F26: Self-paced Online Learning. | G26: x
A27: IHG Concerto - MyID - Removing Access | B27: IHG0054205 | C27: 10 | D27: Suggested Learning | F27: Self-paced Online Learning. | G27: x
A28: IHG Concerto Homepage overview | B28: IHG0052563 | C28: 10 | D28: Suggested Learning | F28: Self-paced Online Learning. | G28: x | H28: x | I28: x | J28: x
A29: IHG Concerto: Hotel Content Overview | B29: IHG0060624 | C29: 10 | D29: Suggested Learning | F29: Self-paced Online Learning (5 Minutes). | G29: x | H29: x | I29: x | J29: x
A30: Global Sales Induction | B30: IHG7573378 | C30: 10 | D30: Suggested Learning | F30: Self-paced Online Learning (25 Minutes). | G30: x | H30: x
A31: Sales Learning Pathway for On Property Sellers | B31: IHG3530707 | C31: 5 | D31: within 90 days | F31: Self-paced Online Learning (1 Hour 30 Minutes). | G31: x | H31: x
A32: Getting Started with MeetingBroker | B32: IHG0056663 | C32: 10 | D32: Suggested Learning | F32: Self-paced Online Learning. | G32: x | H32: x
A33: IHG Way of Sales - Solution Selling | B33: IHG0025681 | C33: 6 | D33: within 120 days | F33: In-person Instructor Led Course (see available dates & times by clicking the link below). Prerequisite: Must Complete Sales Learning Pathway | G33: x | H33: x
A34: GRS Fundamentals - Reservation, Rate and Inventory Management | B34: IHG0049459 | C34: 10 | D34: Suggested Learning | F34: Self-paced Online Learning. | G34: x | I34: x
A35: RMS Fundamentals: Yielding & Price Optimization | B35: IHG0049460 | C35: 10 | D35: Suggested Learning | F35: Self-paced Online Learning. | G35: x | I35: x
A36: IHG Concerto Hotel Release 2 - Inventory Reset Process Phase II | B36: IHG0061343 | C36: 10 | D36: Suggested Learning | F36: Self-paced Online Learning. | G36: x | I36: x
A37: IHG Concerto Hotel Release 2 - Inventory Reset Process Phase III | B37: IHG0061983 | C37: 10 | D37: Suggested Learning | F37: Self-paced Online Learning. | G37: x | I37: x
A38: IHG Concerto Inventory Configuration - Sleeping Rooms | B38: IHG1677402 | C38: 10 | D38: Suggested Learning | F38: Self-paced Online Learning. | G38: x | I38: x
A39: IHG Concerto - Getting to Know Inventory Balancing | B39: IHG0053503 | C39: 10 | D39: Suggested Learning | F39: Self-paced Online Learning. | G39: x | I39: x
A40: Revenue Management Certification | B40: RM Certification | C40: 5 | D40: within 90 days | I40: x
...

Sheet Hotel Indigo
A1: Hotel Indigo | B1: Course ID | C1: Time Frame (1-10) Not Visible to Learner | D1: Time Frame Visible to Learner | E1: Priority: Y | F1: Notes | G1: General Manager | H1: Sales Team Leader | I1: Revenue Team Leader | J1: Front Office Team Leader | K1: Housekeeping Team Leader | L1: Food & Beverage Team Leader | M1: Engineering Team Leader | N1: Front Desk | O1: Housekeeping | P1: Food and Beverage | Q1: Engineering | R1: All other management colleagues | S1: All other non-management colleagues
A2: True Hospitality Service Skills | B2: IHG051263 | C2: =_xlfn.XLOOKUP(B2,Lookups!G:G,Lookups!H:H,"",0,1) -> 3 | D2: =_xlfn.XLOOKUP(C2,[1]Sheet2!$A$2:$A$11,[1]Sheet2!$B$2:$B$11,"Not found") -> within 30 days | F2: =_xlfn.XLOOKUP(B2,'Holiday Inn Express'!B:B,'Holiday Inn Express'!F:F,"",0,1) -> Self-paced Online Learning (1 Hour 15 Minutes). Hotel-led in-person training (On-Job-Training, OJT) is permitted & completions must be tracked in myLearning. | G2: x | H2: x | I2: x | J2: x | K2: x | L2: x | M2: x | N2: x | O2: x | P2: x | Q2: x | R2: x | S2: x
A3: Hotel Indigo Inspire New Stories Brand Orientation | B3: IHG0064483 | C3: =_xlfn.XLOOKUP(B3,Lookups!G:G,Lookups!H:H,"",0,1) -> 3 | D3: =_xlfn.XLOOKUP(C3,[1]Sheet2!$A$2:$A$11,[1]Sheet2!$B$2:$B$11,"Not found") -> within 30 days | F3: Self-paced Online Learning (1 Hour). Hotel-led in-person training (On-Job-Training, OJT) is permitted & completions must be tracked in myLearning. | G3: x | H3: x | I3: x | J3: x | K3: x | L3: x | M3: x | N3: x | O3: x | P3: x | Q3: x | R3: x | S3: x
A4: Hotel Indigo Inspire New Stories Brand Experience Training | B4: IHG0064463 | C4: =_xlfn.XLOOKUP(B4,Lookups!G:G,Lookups!H:H,"",0,1) -> 3 | D4: =_xlfn.XLOOKUP(C4,[1]Sheet2!$A$2:$A$11,[1]Sheet2!$B$2:$B$11,"Not found") -> within 30 days | F4: Self-paced Online Learning (1 Hour). Hotel-led in-person training (On-Job-Training, OJT) is permitted & completions must be tracked in myLearning. | G4: x | H4: x | I4: x | J4: x | K4: x | L4: x | M4: x | N4: x | O4: x | P4: x | Q4: x | R4: x | S4: x
A5: IHG Managed Hotels - Responsible Business Catalogue | B5: Guide for Managed Hotel Leaders | C5: =_xlfn.XLOOKUP(B5,Lookups!G:G,Lookups!H:H,"",0,1) -> 3 | D5: =_xlfn.XLOOKUP(C5,[1]Sheet2!$A$2:$A$11,[1]Sheet2!$B$2:$B$11,"Not found") -> within 30 days | F5: For IHG Managed Hotels only; follow guidance on brand-standard related trainings | G5: x | H5: x | I5: x | J5: x | K5: x | L5: x | M5: x | R5: x
A6: IHG Managed Hotels - Responsible Business Catalogue | B6: Guide for Managed Hotel Colleagues | C6: =_xlfn.XLOOKUP(B6,Lookups!G:G,Lookups!H:H,"",0,1) -> 3 | D6: =_xlfn.XLOOKUP(C6,[1]Sheet2!$A$2:$A$11,[1]Sheet2!$B$2:$B$11,"Not found") -> within 30 days | F6: For IHG Managed Hotels only; follow guidance on brand-standard related trainings | N6: x | O6: x | P6: x | Q6: x | S6: x
A7: Franchised Hotels - Responsible Business Catalogue | B7: Guide for Franchised Hotel Leaders | C7: =_xlfn.XLOOKUP(B7,Lookups!G:G,Lookups!H:H,"",0,1) -> 3 | D7: =_xlfn.XLOOKUP(C7,[1]Sheet2!$A$2:$A$11,[1]Sheet2!$B$2:$B$11,"Not found") -> within 30 days | F7: For Franchised Hotels only; follow guidance on brand-standard related trainings | G7: x | H7: x | I7: x | J7: x | K7: x | L7: x | M7: x | R7: x
A8: Franchised Hotels - Responsible Business Catalogue | B8: Guide for Franchised Hotel Colleagues | C8: =_xlfn.XLOOKUP(B8,Lookups!G:G,Lookups!H:H,"",0,1) -> 3 | D8: =_xlfn.XLOOKUP(C8,[1]Sheet2!$A$2:$A$11,[1]Sheet2!$B$2:$B$11,"Not found") -> within 30 days | F8: For Franchised Hotels only; follow guidance on brand-standard related trainings | N8: x | O8: x | P8: x | Q8: x | S8: x
A9: Hotel Experience Champion | B9: Hotel Experience Champion Program | C9: 3 | D9: =_xlfn.XLOOKUP(C9,[1]Sheet2!$A$2:$A$11,[1]Sheet2!$B$2:$B$11,"Not found") -> within 30 days | F9: Not a specific course; review the Hotel Experience Champion Program and ensure Hotel Experience Champion role(s) have been assigned | G9: x
A10: Leading and Sustaining your Service Culture | B10: IHG0056403 | C10: =_xlfn.XLOOKUP(B10,Lookups!G:G,Lookups!H:H,"",0,1) -> 4 | D10: =_xlfn.XLOOKUP(C10,[1]Sheet2!$A$2:$A$11,[1]Sheet2!$B$2:$B$11,"Not found") -> within 60 days | F10: =_xlfn.XLOOKUP(B10,'Holiday Inn Express'!B:B,'Holiday Inn Express'!F:F,"",0,1) -> Self-paced Online Learning (1 Hour 45 Minutes). | G10: x | H10: x | I10: x | J10: x | K10: x | L10: x | M10: x | R10: x
A11: Brand Service Tools & Resources | B11: Brand Service Tools & Resources | C11: 10 | D11: =_xlfn.XLOOKUP(C11,[1]Sheet2!$A$2:$A$11,[1]Sheet2!$B$2:$B$11,"Not found") -> Suggested Learning | F11: =_xlfn.XLOOKUP(B11,'Holiday Inn Express'!B:B,'Holiday Inn Express'!F:F,"",0,1) -> Explore resource and apply accordingly | G11: x | H11: x | I11: x | J11: x | K11: x | L11: x | M11: x | R11: x
A12: IHG Problem Handling | B12: IHG056045 | C12: =_xlfn.XLOOKUP(B12,Lookups!G:G,Lookups!H:H,"",0,1) -> 3 | D12: =_xlfn.XLOOKUP(C12,[1]Sheet2!$A$2:$A$11,[1]Sheet2!$B$2:$B$11,"Not found") -> within 30 days | F12: =_xlfn.XLOOKUP(B12,'Holiday Inn Express'!B:B,'Holiday Inn Express'!F:F,"",0,1) -> Self-paced Online Learning (1 Hour). Hotel-led in-person training (On-Job-Training, OJT) is permitted & completions must be tracked in myLearning. | G12: x | H12: x | I12: x | J12: x | K12: x | L12: x | M12: x | N12: x | O12: x | P12: x | Q12: x | R12: x | S12: x
A13: The Value of Loyalty | B13: IHG5072070 | C13: =_xlfn.XLOOKUP(B13,Lookups!G:G,Lookups!H:H,"",0,1) -> 3 | D13: =_xlfn.XLOOKUP(C13,[1]Sheet2!$A$2:$A$11,[1]Sheet2!$B$2:$B$11,"Not found") -> within 30 days | F13: =_xlfn.XLOOKUP(B13,'Holiday Inn Express'!B:B,'Holiday Inn Express'!F:F,"",0,1) -> Self-paced Online Learning (20 Minutes). | G13: x | H13: x | I13: x | J13: x | K13: x | L13: x | M13: x | N13: x | O13: x | P13: x | Q13: x | R13: x | S13: x
