Workbook

Sheet Colour Guide
A1: Brand | B1: Primary | C1: Secondary
A2: Holiday Inn Express | B2: #002D72 | C2: #9BCBEB | D2: #E35205
A3: Holiday Inn | B3: #1C4B34 | C3: #578272 | D3: #9BC5B7
A4: avid hotels | B4: #68D2DF | C4: #FF0000
A5: Garner | B5: #ABDBC6 | C5: #FBF8EB
A6: Atwell Suites | B6: #6C714D | C6: #E8CEBD | D6: #B46A55
A7: Staybridge Suites | B7: #006980
A8: Candlewood Suites | B8: #9B2241 | C8: #00205B
A9: Even Hotels | B9: #164945
A10: voco | B10: #121217 | C10: #F8B9OD
A11: Crowne Plaza | B11: #A00062 | C11: #515A61
A12: Hotel Indigo | B12: #2E5992 | C12: #D8A400
A13: Vignette | B13: #2E273B | C13: #E9D0D5
A14: Intercontinental | B14: #3D3935 | C14: #CBC5BE
A15: Regent | B15: #D6E3DC | C15: F5E1CC | D15: #211551
A16: Kimpton | B16: #58565C | C16: #FFFFFF

Sheet Regent
A1: Course Title | B1: Instructions | C1: Hyperlink for Access | D1: Access ______ | E1: Not visible to learner: OJT Course ID: | F1: Create OJT Button
A2: Business Services training | B2: Review maunufactor operating manuals for equipment and software. | E2: =_xlfn.XLOOKUP(A2,'OJT IDs'!A:A,'OJT IDs'!N:N,"Not found") -> IHG6321776-OJT | F2: =_xlfn.XLOOKUP(E2,'OJT Links'!E:E,'OJT Links'!H:H,"Not found") -> https://mylearning.sumtotal.host/core/pillarRedirect?relyingParty=LM&url=app%2Fmanagement%2FLMS_ActDetails.aspx%3FActivityId%3D601648%26UserMode%3D0
A3: Digital Check-in | B3: View the videos with your group to complete the learning offer | C3: https://mylearning.sumtotal.host/core/pillarRedirect?relyingParty=LM&url=app%2fmanagement%2fLMS_ActDetails.aspx%3fActivityId%3d41%26UserMode%3d0 | D3: =_xlfn.XLOOKUP(A3,'All Courses'!A:A,'All Courses'!D:D,"Not found") -> course | E3: =_xlfn.XLOOKUP(A3,'OJT IDs'!A:A,'OJT IDs'!N:N,"Not found") -> IHG0061303-OJT | F3: =_xlfn.XLOOKUP(E3,'OJT Links'!E:E,'OJT Links'!H:H,"Not found") -> https://mylearning.sumtotal.host/core/pillarRedirect?relyingParty=LM&url=app%2Fmanagement%2FLMS_ActDetails.aspx%3FActivityId%3D595005%26UserMode%3D0
A4: First Aid | B4: Review your first aid procedures and practices. | E4: =_xlfn.XLOOKUP(A4,'OJT IDs'!A:A,'OJT IDs'!N:N,"Not found") -> IHG1885862-OJT | F4: =_xlfn.XLOOKUP(E4,'OJT Links'!E:E,'OJT Links'!H:H,"Not found") -> https://mylearning.sumtotal.host/core/pillarRedirect?relyingParty=LM&url=app%2Fmanagement%2FLMS_ActDetails.aspx%3FActivityId%3D601671%26UserMode%3D0
A5: Handling Credit Cards Securely | B5: View the videos with your group to complete the learning offer | C5: https://me2.ihgmerlin.com/web/init-ihg-information-security/homeandhttps://me2.ihgmerlin.com/web/init-pci-compliance | D5: =_xlfn.XLOOKUP(A5,'All Courses'!A:A,'All Courses'!D:D,"Not found") -> Resource | E5: =_xlfn.XLOOKUP(A5,'OJT IDs'!A:A,'OJT IDs'!N:N,"Not found") -> IHG0047626-OJT | F5: =_xlfn.XLOOKUP(E5,'OJT Links'!E:E,'OJT Links'!H:H,"Not found") -> Not found
A6: Health & Safety, Security an Emergency Procedures | B6: Review your health safety and security procedures, including fire evacuation plan. | C6: Link | D6: =_xlfn.XLOOKUP(A6,'All Courses'!A:A,'All Courses'!D:D,"Not found") -> course | E6: =_xlfn.XLOOKUP(A6,'OJT IDs'!A:A,'OJT IDs'!N:N,"Not found") -> IHG9191264-OJT | F6: =_xlfn.XLOOKUP(E6,'OJT Links'!E:E,'OJT Links'!H:H,"Not found") -> https://mylearning.sumtotal.host/core/pillarRedirect?relyingParty=LM&url=app%2Fmanagement%2FLMS_ActDetails.aspx%3FActivityId%3D601724%26UserMode%3D0
A7: Housekeeping Safety Device (US & Canada only) | B7: Review maunufactor operating manual for equipment and procedure for action when an alarm is triggered | E7: =_xlfn.XLOOKUP(A7,'OJT IDs'!A:A,'OJT IDs'!N:N,"Not found") -> IHG8611503-OJT | F7: =_xlfn.XLOOKUP(E7,'OJT Links'!E:E,'OJT Links'!H:H,"Not found") -> https://mylearning.sumtotal.host/core/pillarRedirect?relyingParty=LM&url=app%2Fmanagement%2FLMS_ActDetails.aspx%3FActivityId%3D601740%26UserMode%3D0
A8: Getting to Know IHG Concerto | B8: View the videos with your group to complete the learning offer . Once complete, review the assessments as a group. NOTE: Assessment records are not required) | C8: https://mylearning.sumtotal.host/core/pillarRedirect?relyingParty=LM&url=app%2fmanagement%2fLMS_ActDetails.aspx%3fActivityId%3d52090%26UserMode%3d0 | D8: =_xlfn.XLOOKUP(A8,'All Courses'!A:A,'All Courses'!D:D,"Not found") -> course | E8: =_xlfn.XLOOKUP(A8,'OJT IDs'!A:A,'OJT IDs'!N:N,"Not found") -> IHG0049491-OJT | F8: =_xlfn.XLOOKUP(E8,'OJT Links'!E:E,'OJT Links'!H:H,"Not found") -> https://mylearning.sumtotal.host/core/pillarRedirect?relyingParty=LM&url=app%2Fmanagement%2FLMS_ActDetails.aspx%3FActivityId%3D595027%26UserMode%3D0
A9: IHG Voice Program Training | B9: View the videos with your group to complete the learning offer | C9: https://mylearning.sumtotal.host/core/pillarRedirect?relyingParty=LM&url=app%2fmanagement%2fLMS_ActDetails.aspx%3fActivityId%3d2823%26UserMode%3d0 | D9: =_xlfn.XLOOKUP(A9,'All Courses'!A:A,'All Courses'!D:D,"Not found") -> course | E9: =_xlfn.XLOOKUP(A9,'OJT IDs'!A:A,'OJT IDs'!N:N,"Not found") -> IHG0054667-OJT | F9: =_xlfn.XLOOKUP(E9,'OJT Links'!E:E,'OJT Links'!H:H,"Not found") -> https://mylearning.sumtotal.host/core/pillarRedirect?relyingParty=LM&url=app%2Fmanagement%2FLMS_ActDetails.aspx%3FActivityId%3D595030%26UserMode%3D0
A10: IHG Way of Clean 5-S Cleaning Program | B10: View the videos with your group to complete the learning offer . Once complete, review the assessments as a group. NOTE: Assessment records are not required) | C10: Link | D10: =_xlfn.XLOOKUP(A10,'All Courses'!A:A,'All Courses'!D:D,"Not found") -> course | E10: =_xlfn.XLOOKUP(A10,'OJT IDs'!A:A,'OJT IDs'!N:N,"Not found") -> IHG7376524-OJT | F10: =_xlfn.XLOOKUP(E10,'OJT Links'!E:E,'OJT Links'!H:H,"Not found") -> https://mylearning.sumtotal.host/core/pillarRedirect?relyingParty=LM&url=app%2Fmanagement%2FLMS_ActDetails.aspx%3FActivityId%3D468097%26UserMode%3D0
A11: IHG Way of Clean 5-S Cleaning Program for Non-Housekeeping Colleagues | B11: View the videos with your group to complete the learning offer . Once complete, review the assessments as a group. NOTE: Assessment records are not required) | C11: Link | D11: =_xlfn.XLOOKUP(A11,'All Courses'!A:A,'All Courses'!D:D,"Not found") -> course | E11: =_xlfn.XLOOKUP(A11,'OJT IDs'!A:A,'OJT IDs'!N:N,"Not found") -> IHG1227263-OJT | F11: =_xlfn.XLOOKUP(E11,'OJT Links'!E:E,'OJT Links'!H:H,"Not found") -> https://mylearning.sumtotal.host/core/pillarRedirect?relyingParty=LM&url=app%2Fmanagement%2FLMS_ActDetails.aspx%3FActivityId%3D595028%26UserMode%3D0
A12: IHG World Class Beverage Academy - 101 Essentials | B12: View the videos with your group to complete the learning offer . Once complete, review the assessments as a group. NOTE: Assessment records are not required) | C12: Link | D12: =_xlfn.XLOOKUP(A12,'All Courses'!A:A,'All Courses'!D:D,"Not found") -> course | E12: =_xlfn.XLOOKUP(A12,'OJT IDs'!A:A,'OJT IDs'!N:N,"Not found") -> IHG052185-OJT | F12: =_xlfn.XLOOKUP(E12,'OJT Links'!E:E,'OJT Links'!H:H,"Not found") -> https://mylearning.sumtotal.host/core/pillarRedirect?relyingParty=LM&url=app%2Fmanagement%2FLMS_ActDetails.aspx%3FActivityId%3D595029%26UserMode%3D0
A13: Introduction to Information Security | B13: View the videos with your group to complete the learning offer | C13: Link | D13: =_xlfn.XLOOKUP(A13,'All Courses'!A:A,'All Courses'!D:D,"Not found") -> course | E13: =_xlfn.XLOOKUP(A13,'OJT IDs'!A:A,'OJT IDs'!N:N,"Not found") -> IHG0047625-OJT | F13: =_xlfn.XLOOKUP(E13,'OJT Links'!E:E,'OJT Links'!H:H,"Not found") -> https://mylearning.sumtotal.host/core/pillarRedirect?relyingParty=LM&url=app%2Fmanagement%2FLMS_ActDetails.aspx%3FActivityId%3D596770%26UserMode%3D0
A14: Leading and Sustaining your Service Culture | B14: View the videos with your group to complete the learning offer . Once complete, review the assessments as a group. NOTE: Assessment records are not required) | C14: Link | D14: =_xlfn.XLOOKUP(A14,'All Courses'!A:A,'All Courses'!D:D,"Not found") -> course | E14: =_xlfn.XLOOKUP(A14,'OJT IDs'!A:A,'OJT IDs'!N:N,"Not found") -> IHG0056403-OJT | F14: =_xlfn.XLOOKUP(E14,'OJT Links'!E:E,'OJT Links'!H:H,"Not found") -> https://mylearning.sumtotal.host/core/pillarRedirect?relyingParty=LM&url=app%2Fmanagement%2FLMS_ActDetails.aspx%3FActivityId%3D596772%26UserMode%3D0
A15: Luxury Fundamentals | B15: Use the link provided to access the learning offer. Review the offering in its entirety to complete. | C15: Link | D15: course | E15: =_xlfn.XLOOKUP(A15,'OJT IDs'!A:A,'OJT IDs'!N:N,"Not found") -> IHG0063363-OJT | F15: =_xlfn.XLOOKUP(E15,'OJT Links'!E:E,'OJT Links'!H:H,"Not found") -> https://mylearning.sumtotal.host/core/pillarRedirect?relyingParty=LM&url=app%2Fmanagement%2FLMS_ActDetails.aspx%3FActivityId%3D468098%26UserMode%3D0
A16: Preventing Human Trafficking | B16: View the videos with your group to complete the learning offer . Once complete, review the assessments as a group. NOTE: Assessment records are not required) | C16: Link | D16: =_xlfn.XLOOKUP(A16,'All Courses'!A:A,'All Courses'!D:D,"Not found") -> course | E16: =_xlfn.XLOOKUP(A16,'OJT IDs'!A:A,'OJT IDs'!N:N,"Not found") -> IHG0057043-v2024-OJT | F16: =_xlfn.XLOOKUP(E16,'OJT Links'!E:E,'OJT Links'!H:H,"Not found") -> https://mylearning.sumtotal.host/core/pillarRedirect?relyingParty=LM&url=app%2Fmanagement%2FLMS_ActDetails.aspx%3FActivityId%3D468091%26UserMode%3D0
A17: IHG Problem Handling V2 | B17: View the videos with your group to complete the learning offer . Once complete, review the assessments as a group. NOTE: Assessment records are not required) | C17: https://ihg.sharepoint.com/sites/ResponsibleBusiness/SitePages/Human-Rights-Brand-Standards-Guidance.aspx | D17: =_xlfn.XLOOKUP(A17,'All Courses'!A:A,'All Courses'!D:D,"Not found") -> course | E17: =_xlfn.XLOOKUP(A17,'OJT IDs'!A:A,'OJT IDs'!N:N,"Not found") -> IHG056045-OJT | F17: =_xlfn.XLOOKUP(E17,'OJT Links'!E:E,'OJT Links'!H:H,"Not found") -> https://mylearning.sumtotal.host/core/pillarRedirect?relyingParty=LM&url=app%2Fmanagement%2FLMS_ActDetails.aspx%3FActivityId%3D468095%26UserMode%3D0
A18: Property Management System (PMS) | B18: Review maunufactor operating manual relevant department training in the PMS system | C18: Link | E18: =_xlfn.XLOOKUP(A18,'OJT IDs'!A:A,'OJT IDs'!N:N,"Not found") -> IHG5969164-OJT | F18: =_xlfn.XLOOKUP(E18,'OJT Links'!E:E,'OJT Links'!H:H,"Not found") -> https://mylearning.sumtotal.host/core/pillarRedirect?relyingParty=LM&url=app%2Fmanagement%2FLMS_ActDetails.aspx%3FActivityId%3D602920%26UserMode%3D0
A19: True Hospitality Service Skills | B19: View the videos with your group to complete the learning offer . Once complete, review the assessments as a group. NOTE: Assessment records are not required) | D19: =_xlfn.XLOOKUP(A19,'All Courses'!A:A,'All Courses'!D:D,"Not found") -> course | E19: =_xlfn.XLOOKUP(A19,'OJT IDs'!A:A,'OJT IDs'!N:N,"Not found") -> IHG051263-OJT | F19: =_xlfn.XLOOKUP(E19,'OJT Links'!E:E,'OJT Links'!H:H,"Not found") -> https://mylearning.sumtotal.host/core/pillarRedirect?relyingParty=LM&url=app%2Fmanagement%2FLMS_ActDetails.aspx%3FActivityId%3D468089%26UserMode%3D0
A20: Welcome to IHG | B20: View the videos with your group to complete the learning offer | C20: Link | D20: =_xlfn.XLOOKUP(A20,'All Courses'!A:A,'All Courses'!D:D,"Not found") -> course | E20: =_xlfn.XLOOKUP(A20,'OJT IDs'!A:A,'OJT IDs'!N:N,"Not found") -> IHG058044-OJT | F20: =_xlfn.XLOOKUP(E20,'OJT Links'!E:E,'OJT Links'!H:H,"Not found") -> Not found
A21: Property Orientation | B21: Complete a tour of your property with new hires. | C21: Link | E21: =_xlfn.XLOOKUP(A21,'OJT IDs'!A:A,'OJT IDs'!N:N,"Not found") -> IHG8342629-OJT | F21: =_xlfn.XLOOKUP(E21,'OJT Links'!E:E,'OJT Links'!H:H,"Not found") -> https://mylearning.sumtotal.host/core/pillarRedirect?relyingParty=LM&url=app%2Fmanagement%2FLMS_ActDetails.aspx%3FActivityId%3D603028%26UserMode%3D0

Sheet InterContinental
A1: Course Title | B1: Instructions | C1: Hyperlink for Access | D1: Access ______ | E1: Not visible to learner: OJT Course ID: | F1: Create OJT Button
A2: Business Services training | B2: Review maunufactor operating manuals for equipment and software. | E2: =_xlfn.XLOOKUP(A2,'OJT IDs'!A:A,'OJT IDs'!N:N,"Not found") -> IHG6321776-OJT | F2: =_xlfn.XLOOKUP(E2,'OJT Links'!E:E,'OJT Links'!H:H,"Not found") -> https://mylearning.sumtotal.host/core/pillarRedirect?relyingParty=LM&url=app%2Fmanagement%2FLMS_ActDetails.aspx%3FActivityId%3D601648%26UserMode%3D0
A3: Digital Check-in | B3: View the videos with your group to complete the learning offer | C3: https://mylearning.sumtotal.host/core/pillarRedirect?relyingParty=LM&url=app%2fmanagement%2fLMS_ActDetails.aspx%3fActivityId%3d41%26UserMode%3d0 | D3: =_xlfn.XLOOKUP(A3,'All Courses'!A:A,'All Courses'!D:D,"Not found") -> course | E3: =_xlfn.XLOOKUP(A3,'OJT IDs'!A:A,'OJT IDs'!N:N,"Not found") -> IHG0061303-OJT | F3: =_xlfn.XLOOKUP(E3,'OJT Links'!E:E,'OJT Links'!H:H,"Not found") -> https://mylearning.sumtotal.host/core/pillarRedirect?relyingParty=LM&url=app%2Fmanagement%2FLMS_ActDetails.aspx%3FActivityId%3D595005%26UserMode%3D0
A4: First Aid | B4: Review your first aid procedures and practices. | E4: =_xlfn.XLOOKUP(A4,'OJT IDs'!A:A,'OJT IDs'!N:N,"Not found") -> IHG1885862-OJT | F4: =_xlfn.XLOOKUP(E4,'OJT Links'!E:E,'OJT Links'!H:H,"Not found") -> https://mylearning.sumtotal.host/core/pillarRedirect?relyingParty=LM&url=app%2Fmanagement%2FLMS_ActDetails.aspx%3FActivityId%3D601671%26UserMode%3D0
A5: Handling Credit Cards Securely | B5: View the videos with your group to complete the learning offer | C5: https://me2.ihgmerlin.com/web/init-ihg-information-security/homeandhttps://me2.ihgmerlin.com/web/init-pci-compliance | D5: =_xlfn.XLOOKUP(A5,'All Courses'!A:A,'All Courses'!D:D,"Not found") -> Resource | E5: =_xlfn.XLOOKUP(A5,'OJT IDs'!A:A,'OJT IDs'!N:N,"Not found") -> IHG0047626-OJT | F5: =_xlfn.XLOOKUP(E5,'OJT Links'!E:E,'OJT Links'!H:H,"Not found") -> Not found
A6: Health & Safety, Security an Emergency Procedures | B6: Review your health safety and security procedures, including fire evacuation plan. | C6: Link | D6: =_xlfn.XLOOKUP(A6,'All Courses'!A:A,'All Courses'!D:D,"Not found") -> course | E6: =_xlfn.XLOOKUP(A6,'OJT IDs'!A:A,'OJT IDs'!N:N,"Not found") -> IHG9191264-OJT | F6: =_xlfn.XLOOKUP(E6,'OJT Links'!E:E,'OJT Links'!H:H,"Not found") -> https://mylearning.sumtotal.host/core/pillarRedirect?relyingParty=LM&url=app%2Fmanagement%2FLMS_ActDetails.aspx%3FActivityId%3D601724%26UserMode%3D0
A7: Housekeeping Safety Device (US & Canada only) | B7: Review maunufactor operating manual for equipment and procedure for action when an alarm is triggered | E7: =_xlfn.XLOOKUP(A7,'OJT IDs'!A:A,'OJT IDs'!N:N,"Not found") -> IHG8611503-OJT | F7: =_xlfn.XLOOKUP(E7,'OJT Links'!E:E,'OJT Links'!H:H,"Not found") -> https://mylearning.sumtotal.host/core/pillarRedirect?relyingParty=LM&url=app%2Fmanagement%2FLMS_ActDetails.aspx%3FActivityId%3D601740%26UserMode%3D0
A8: Getting to Know IHG Concerto | B8: View the videos with your group to complete the learning offer . Once complete, review the assessments as a group. NOTE: Assessment records are not required) | C8: https://mylearning.sumtotal.host/core/pillarRedirect?relyingParty=LM&url=app%2fmanagement%2fLMS_ActDetails.aspx%3fActivityId%3d52090%26UserMode%3d0 | D8: =_xlfn.XLOOKUP(A8,'All Courses'!A:A,'All Courses'!D:D,"Not found") -> course | E8: =_xlfn.XLOOKUP(A8,'OJT IDs'!A:A,'OJT IDs'!N:N,"Not found") -> IHG0049491-OJT | F8: =_xlfn.XLOOKUP(E8,'OJT Links'!E:E,'OJT Links'!H:H,"Not found") -> https://mylearning.sumtotal.host/core/pillarRedirect?relyingParty=LM&url=app%2Fmanagement%2FLMS_ActDetails.aspx%3FActivityId%3D595027%26UserMode%3D0
A9: IHG Voice Program Training | B9: View the videos with your group to complete the learning offer | C9: https://mylearning.sumtotal.host/core/pillarRedirect?relyingParty=LM&url=app%2fmanagement%2fLMS_ActDetails.aspx%3fActivityId%3d2823%26UserMode%3d0 | D9: =_xlfn.XLOOKUP(A9,'All Courses'!A:A,'All Courses'!D:D,"Not found") -> course | E9: =_xlfn.XLOOKUP(A9,'OJT IDs'!A:A,'OJT IDs'!N:N,"Not found") -> IHG0054667-OJT | F9: =_xlfn.XLOOKUP(E9,'OJT Links'!E:E,'OJT Links'!H:H,"Not found") -> https://mylearning.sumtotal.host/core/pillarRedirect?relyingParty=LM&url=app%2Fmanagement%2FLMS_ActDetails.aspx%3FActivityId%3D595030%26UserMode%3D0
A10: IHG Way of Clean 5-S Cleaning Program | B10: View the videos with your group to complete the learning offer . Once complete, review the assessments as a group. NOTE: Assessment records are not required) | C10: Link | D10: =_xlfn.XLOOKUP(A10,'All Courses'!A:A,'All Courses'!D:D,"Not found") -> course | E10: =_xlfn.XLOOKUP(A10,'OJT IDs'!A:A,'OJT IDs'!N:N,"Not found") -> IHG7376524-OJT | F10: =_xlfn.XLOOKUP(E10,'OJT Links'!E:E,'OJT Links'!H:H,"Not found") -> https://mylearning.sumtotal.host/core/pillarRedirect?relyingParty=LM&url=app%2Fmanagement%2FLMS_ActDetails.aspx%3FActivityId%3D468097%26UserMode%3D0
A11: IHG Way of Clean 5-S Cleaning Program for Non-Housekeeping Colleagues | B11: View the videos with your group to complete the learning offer . Once complete, review the assessments as a group. NOTE: Assessment records are not required) | C11: Link | D11: =_xlfn.XLOOKUP(A11,'All Courses'!A:A,'All Courses'!D:D,"Not found") -> course | E11: =_xlfn.XLOOKUP(A11,'OJT IDs'!A:A,'OJT IDs'!N:N,"Not found") -> IHG1227263-OJT | F11: =_xlfn.XLOOKUP(E11,'OJT Links'!E:E,'OJT Links'!H:H,"Not found") -> https://mylearning.sumtotal.host/core/pillarRedirect?relyingParty=LM&url=app%2Fmanagement%2FLMS_ActDetails.aspx%3FActivityId%3D595028%26UserMode%3D0
A12: IHG World Class Beverage Academy - 101 Essentials | B12: View the videos with your group to complete the learning offer . Once complete, review the assessments as a group. NOTE: Assessment records are not required) | C12: Link | D12: =_xlfn.XLOOKUP(A12,'All Courses'!A:A,'All Courses'!D:D,"Not found") -> course | E12: =_xlfn.XLOOKUP(A12,'OJT IDs'!A:A,'OJT IDs'!N:N,"Not found") -> IHG052185-OJT | F12: =_xlfn.XLOOKUP(E12,'OJT Links'!E:E,'OJT Links'!H:H,"Not found") -> https://mylearning.sumtotal.host/core/pillarRedirect?relyingParty=LM&url=app%2Fmanagement%2FLMS_ActDetails.aspx%3FActivityId%3D595029%26UserMode%3D0
A13: Introduction to Information Security | B13: View the videos with your group to complete the learning offer | C13: Link | D13: =_xlfn.XLOOKUP(A13,'All Courses'!A:A,'All Courses'!D:D,"Not found") -> course | E13: =_xlfn.XLOOKUP(A13,'OJT IDs'!A:A,'OJT IDs'!N:N,"Not found") -> IHG0047625-OJT | F13: =_xlfn.XLOOKUP(E13,'OJT Links'!E:E,'OJT Links'!H:H,"Not found") -> https://mylearning.sumtotal.host/core/pillarRedirect?relyingParty=LM&url=app%2Fmanagement%2FLMS_ActDetails.aspx%3FActivityId%3D596770%26UserMode%3D0
A14: Leading and Sustaining your Service Culture | B14: View the videos with your group to complete the learning offer . Once complete, review the assessments as a group. NOTE: Assessment records are not required) | C14: Link | D14: =_xlfn.XLOOKUP(A14,'All Courses'!A:A,'All Courses'!D:D,"Not found") -> course | E14: =_xlfn.XLOOKUP(A14,'OJT IDs'!A:A,'OJT IDs'!N:N,"Not found") -> IHG0056403-OJT | F14: =_xlfn.XLOOKUP(E14,'OJT Links'!E:E,'OJT Links'!H:H,"Not found") -> https://mylearning.sumtotal.host/core/pillarRedirect?relyingParty=LM&url=app%2Fmanagement%2FLMS_ActDetails.aspx%3FActivityId%3D596772%26UserMode%3D0
A15: Luxury Fundamentals | B15: Use the link provided to access the learning offer. Review the offering in its entirety to complete. | C15: Link | D15: course | E15: =_xlfn.XLOOKUP(A15,'OJT IDs'!A:A,'OJT IDs'!N:N,"Not found") -> IHG0063363-OJT | F15: =_xlfn.XLOOKUP(E15,'OJT Links'!E:E,'OJT Links'!H:H,"Not found") -> https://mylearning.sumtotal.host/core/pillarRedirect?relyingParty=LM&url=app%2Fmanagement%2FLMS_ActDetails.aspx%3FActivityId%3D468098%26UserMode%3D0
A16: Preventing Human Trafficking | B16: View the videos with your group to complete the learning offer . Once complete, review the assessments as a group. NOTE: Assessment records are not required) | C16: Link https://ihg.sharepoint.com/sites/ResponsibleBusiness/SitePages/Human-Rights-Brand-Standards-Guidance.aspx | D16: =_xlfn.XLOOKUP(A16,'All Courses'!A:A,'All Courses'!D:D,"Not found") -> course | E16: =_xlfn.XLOOKUP(A16,'OJT IDs'!A:A,'OJT IDs'!N:N,"Not found") -> IHG0057043-v2024-OJT | F16: =_xlfn.XLOOKUP(E16,'OJT Links'!E:E,'OJT Links'!H:H,"Not found") -> https://mylearning.sumtotal.host/core/pillarRedirect?relyingParty=LM&url=app%2Fmanagement%2FLMS_ActDetails.aspx%3FActivityId%3D468091%26UserMode%3D0
A17: IHG Problem Handling V2 | B17: View the videos with your group to complete the learning offer . Once complete, review the assessments as a group. NOTE: Assessment records are not required) | C17: Link | D17: =_xlfn.XLOOKUP(A17,'All Courses'!A:A,'All Courses'!D:D,"Not found") -> course | E17: =_xlfn.XLOOKUP(A17,'OJT IDs'!A:A,'OJT IDs'!N:N,"Not found") -> IHG056045-OJT | F17: =_xlfn.XLOOKUP(E17,'OJT Links'!E:E,'OJT Links'!H:H,"Not found") -> https://mylearning.sumtotal.host/core/pillarRedirect?relyingParty=LM&url=app%2Fmanagement%2FLMS_ActDetails.aspx%3FActivityId%3D468095%26UserMode%3D0
A18: Property Management System (PMS) | B18: Review maunufactor operating manual relevant department training in the PMS system | E18: =_xlfn.XLOOKUP(A18,'OJT IDs'!A:A,'OJT IDs'!N:N,"Not found") -> IHG5969164-OJT | F18: =_xlfn.XLOOKUP(E18,'OJT Links'!E:E,'OJT Links'!H:H,"Not found") -> https://mylearning.sumtotal.host/core/pillarRedirect?relyingParty=LM&url=app%2Fmanagement%2FLMS_ActDetails.aspx%3FActivityId%3D602920%26UserMode%3D0
A19: True Hospitality Service Skills | B19: View the videos with your group to complete the learning offer . Once complete, review the assessments as a group. NOTE: Assessment records are not required) | C19: Link | D19: =_xlfn.XLOOKUP(A19,'All Courses'!A:A,'All Courses'!D:D,"Not found") -> course | E19: =_xlfn.XLOOKUP(A19,'OJT IDs'!A:A,'OJT IDs'!N:N,"Not found") -> IHG051263-OJT | F19: =_xlfn.XLOOKUP(E19,'OJT Links'!E:E,'OJT Links'!H:H,"Not found") -> https://mylearning.sumtotal.host/core/pillarRedirect?relyingParty=LM&url=app%2Fmanagement%2FLMS_ActDetails.aspx%3FActivityId%3D468089%26UserMode%3D0
A20: Welcome to IHG | B20: View the videos with your group to complete the learning offer | C20: Link | D20: =_xlfn.XLOOKUP(A20,'All Courses'!A:A,'All Courses'!D:D,"Not found") -> course | E20: =_xlfn.XLOOKUP(A20,'OJT IDs'!A:A,'OJT IDs'!N:N,"Not found") -> IHG058044-OJT | F20: =_xlfn.XLOOKUP(E20,'OJT Links'!E:E,'OJT Links'!H:H,"Not found") -> Not found
A21: Property Orientation | B21: Complete a tour of your property with new hires. | E21: =_xlfn.XLOOKUP(A21,'OJT IDs'!A:A,'OJT IDs'!N:N,"Not found") -> IHG8342629-OJT | F21: =_xlfn.XLOOKUP(E21,'OJT Links'!E:E,'OJT Links'!H:H,"Not found") -> https://mylearning.sumtotal.host/core/pillarRedirect?relyingParty=LM&url=app%2Fmanagement%2FLMS_ActDetails.aspx%3FActivityId%3D603028%26UserMode%3D0
A22: InterContinental Hotels and Resorts Brand Orientation | B22: View the videos with your group to complete the learning offer . Once complete, review the assessments as a group. NOTE: Assessment records are not required) | C22: https://mylearning.sumtotal.host/core/pillarRedirect?relyingParty=LM&url=app%2fmanagement%2fLMS_ActDetails.aspx%3fActivityId%3d10703%26UserMode%3d0 | D22: course | E22: =_xlfn.XLOOKUP(A22,'OJT IDs'!A:A,'OJT IDs'!N:N,"Not found") -> IHG051925-OJT | F22: =_xlfn.XLOOKUP(E22,'OJT Links'!E:E,'OJT Links'!H:H,"Not found") -> https://mylearning.sumtotal.host/core/pillarRedirect?relyingParty=LM&url=app%2Fmanagement%2FLMS_ActDetails.aspx%3FActivityId%3D595031%26UserMode%3D0

Sheet Kimpton
A1: Course Title | B1: Instructions | C1: Hyperlink for Access | D1: Access ______ | E1: Not visible to learner: OJT Course ID: | F1: Create OJT Button
A2: Business Services training | B2: Review maunufactor operating manuals for equipment and software. | E2: =_xlfn.XLOOKUP(A2,'OJT IDs'!A:A,'OJT IDs'!N:N,"Not found") -> IHG6321776-OJT | F2: =_xlfn.XLOOKUP(E2,'OJT Links'!E:E,'OJT Links'!H:H,"Not found") -> https://mylearning.sumtotal.host/core/pillarRedirect?relyingParty=LM&url=app%2Fmanagement%2FLMS_ActDetails.aspx%3FActivityId%3D601648%26UserMode%3D0
A3: Digital Check-in | B3: View the videos with your group to complete the learning offer | C3: https://mylearning.sumtotal.host/core/pillarRedirect?relyingParty=LM&url=app%2fmanagement%2fLMS_ActDetails.aspx%3fActivityId%3d41%26UserMode%3d0 | D3: =_xlfn.XLOOKUP(A3,'All Courses'!A:A,'All Courses'!D:D,"Not found") -> course | E3: =_xlfn.XLOOKUP(A3,'OJT IDs'!A:A,'OJT IDs'!N:N,"Not found") -> IHG0061303-OJT | F3: =_xlfn.XLOOKUP(E3,'OJT Links'!E:E,'OJT Links'!H:H,"Not found") -> https://mylearning.sumtotal.host/core/pillarRedirect?relyingParty=LM&url=app%2Fmanagement%2FLMS_ActDetails.aspx%3FActivityId%3D595005%26UserMode%3D0
A4: First Aid | B4: Review your first aid procedures and practices. | E4: =_xlfn.XLOOKUP(A4,'OJT IDs'!A:A,'OJT IDs'!N:N,"Not found") -> IHG1885862-OJT | F4: =_xlfn.XLOOKUP(E4,'OJT Links'!E:E,'OJT Links'!H:H,"Not found") -> https://mylearning.sumtotal.host/core/pillarRedirect?relyingParty=LM&url=app%2Fmanagement%2FLMS_ActDetails.aspx%3FActivityId%3D601671%26UserMode%3D0
A5: Handling Credit Cards Securely | B5: View the videos with your group to complete the learning offer | C5: https://me2.ihgmerlin.com/web/init-ihg-information-security/homeandhttps://me2.ihgmerlin.com/web/init-pci-compliance | D5: =_xlfn.XLOOKUP(A5,'All Courses'!A:A,'All Courses'!D:D,"Not found") -> Resource | E5: =_xlfn.XLOOKUP(A5,'OJT IDs'!A:A,'OJT IDs'!N:N,"Not found") -> IHG0047626-OJT | F5: =_xlfn.XLOOKUP(E5,'OJT Links'!E:E,'OJT Links'!H:H,"Not found") -> Not found
A6: Health & Safety, Security an Emergency Procedures | B6: Review your health safety and security procedures, including fire evacuation plan. | C6: Link | D6: =_xlfn.XLOOKUP(A6,'All Courses'!A:A,'All Courses'!D:D,"Not found") -> course | E6: =_xlfn.XLOOKUP(A6,'OJT IDs'!A:A,'OJT IDs'!N:N,"Not found") -> IHG9191264-OJT | F6: =_xlfn.XLOOKUP(E6,'OJT Links'!E:E,'OJT Links'!H:H,"Not found") -> https://mylearning.sumtotal.host/core/pillarRedirect?relyingParty=LM&url=app%2Fmanagement%2FLMS_ActDetails.aspx%3FActivityId%3D601724%26UserMode%3D0
A7: Housekeeping Safety Device (US & Canada only) | B7: Review maunufactor operating manual for equipment and procedure for action when an alarm is triggered | E7: =_xlfn.XLOOKUP(A7,'OJT IDs'!A:A,'OJT IDs'!N:N,"Not found") -> IHG8611503-OJT | F7: =_xlfn.XLOOKUP(E7,'OJT Links'!E:E,'OJT Links'!H:H,"Not found") -> https://mylearning.sumtotal.host/core/pillarRedirect?relyingParty=LM&url=app%2Fmanagement%2FLMS_ActDetails.aspx%3FActivityId%3D601740%26UserMode%3D0
A8: Getting to Know IHG Concerto | B8: View the videos with your group to complete the learning offer . Once complete, review the assessments as a group. NOTE: Assessment records are not required) | C8: https://mylearning.sumtotal.host/core/pillarRedirect?relyingParty=LM&url=app%2fmanagement%2fLMS_ActDetails.aspx%3fActivityId%3d52090%26UserMode%3d0 | D8: =_xlfn.XLOOKUP(A8,'All Courses'!A:A,'All Courses'!D:D,"Not found") -> course | E8: =_xlfn.XLOOKUP(A8,'OJT IDs'!A:A,'OJT IDs'!N:N,"Not found") -> IHG0049491-OJT | F8: =_xlfn.XLOOKUP(E8,'OJT Links'!E:E,'OJT Links'!H:H,"Not found") -> https://mylearning.sumtotal.host/core/pillarRedirect?relyingParty=LM&url=app%2Fmanagement%2FLMS_ActDetails.aspx%3FActivityId%3D595027%26UserMode%3D0
A9: IHG Voice Program Training | B9: View the videos with your group to complete the learning offer | C9: https://mylearning.sumtotal.host/core/pillarRedirect?relyingParty=LM&url=app%2fmanagement%2fLMS_ActDetails.aspx%3fActivityId%3d2823%26UserMode%3d0 | D9: =_xlfn.XLOOKUP(A9,'All Courses'!A:A,'All Courses'!D:D,"Not found") -> course | E9: =_xlfn.XLOOKUP(A9,'OJT IDs'!A:A,'OJT IDs'!N:N,"Not found") -> IHG0054667-OJT | F9: =_xlfn.XLOOKUP(E9,'OJT Links'!E:E,'OJT Links'!H:H,"Not found") -> https://mylearning.sumtotal.host/core/pillarRedirect?relyingParty=LM&url=app%2Fmanagement%2FLMS_ActDetails.aspx%3FActivityId%3D595030%26UserMode%3D0
A10: IHG Way of Clean 5-S Cleaning Program | B10: View the videos with your group to complete the learning offer . Once complete, review the assessments as a group. NOTE: Assessment records are not required) | C10: Link | D10: =_xlfn.XLOOKUP(A10,'All Courses'!A:A,'All Courses'!D:D,"Not found") -> course | E10: =_xlfn.XLOOKUP(A10,'OJT IDs'!A:A,'OJT IDs'!N:N,"Not found") -> IHG7376524-OJT | F10: =_xlfn.XLOOKUP(E10,'OJT Links'!E:E,'OJT Links'!H:H,"Not found") -> https://mylearning.sumtotal.host/core/pillarRedirect?relyingParty=LM&url=app%2Fmanagement%2FLMS_ActDetails.aspx%3FActivityId%3D468097%26UserMode%3D0
A11: IHG Way of Clean 5-S Cleaning Program for Non-Housekeeping Colleagues | B11: View the videos with your group to complete the learning offer . Once complete, review the assessments as a group. NOTE: Assessment records are not required) | C11: Link | D11: =_xlfn.XLOOKUP(A11,'All Courses'!A:A,'All Courses'!D:D,"Not found") -> course | E11: =_xlfn.XLOOKUP(A11,'OJT IDs'!A:A,'OJT IDs'!N:N,"Not found") -> IHG1227263-OJT | F11: =_xlfn.XLOOKUP(E11,'OJT Links'!E:E,'OJT Links'!H:H,"Not found") -> https://mylearning.sumtotal.host/core/pillarRedirect?relyingParty=LM&url=app%2Fmanagement%2FLMS_ActDetails.aspx%3FActivityId%3D595028%26UserMode%3D0
A12: IHG World Class Beverage Academy - 101 Essentials | B12: View the videos with your group to complete the learning offer . Once complete, review the assessments as a group. NOTE: Assessment records are not required) | C12: Link | D12: =_xlfn.XLOOKUP(A12,'All Courses'!A:A,'All Courses'!D:D,"Not found") -> course | E12: =_xlfn.XLOOKUP(A12,'OJT IDs'!A:A,'OJT IDs'!N:N,"Not found") -> IHG052185-OJT | F12: =_xlfn.XLOOKUP(E12,'OJT Links'!E:E,'OJT Links'!H:H,"Not found") -> https://mylearning.sumtotal.host/core/pillarRedirect?relyingParty=LM&url=app%2Fmanagement%2FLMS_ActDetails.aspx%3FActivityId%3D595029%26UserMode%3D0
A13: Introduction to Information Security | B13: View the videos with your group to complete the learning offer | C13: Link | D13: =_xlfn.XLOOKUP(A13,'All Courses'!A:A,'All Courses'!D:D,"Not found") -> course | E13: =_xlfn.XLOOKUP(A13,'OJT IDs'!A:A,'OJT IDs'!N:N,"Not found") -> IHG0047625-OJT | F13: =_xlfn.XLOOKUP(E13,'OJT Links'!E:E,'OJT Links'!H:H,"Not found") -> https://mylearning.sumtotal.host/core/pillarRedirect?relyingParty=LM&url=app%2Fmanagement%2FLMS_ActDetails.aspx%3FActivityId%3D596770%26UserMode%3D0
A14: Leading and Sustaining your Service Culture | B14: View the videos with your group to complete the learning offer . Once complete, review the assessments as a group. NOTE: Assessment records are not required) | C14: Link | D14: =_xlfn.XLOOKUP(A14,'All Courses'!A:A,'All Courses'!D:D,"Not found") -> course | E14: =_xlfn.XLOOKUP(A14,'OJT IDs'!A:A,'OJT IDs'!N:N,"Not found") -> IHG0056403-OJT | F14: =_xlfn.XLOOKUP(E14,'OJT Links'!E:E,'OJT Links'!H:H,"Not found") -> https://mylearning.sumtotal.host/core/pillarRedirect?relyingParty=LM&url=app%2Fmanagement%2FLMS_ActDetails.aspx%3FActivityId%3D596772%26UserMode%3D0
A15: Luxury Fundamentals | B15: Use the link provided to access the learning offer. Review the offering in its entirety to complete. | C15: Link | D15: =_xlfn.XLOOKUP(A15,'All Courses'!A:A,'All Courses'!D:D,"Not found") -> Course | E15: =_xlfn.XLOOKUP(A15,'OJT IDs'!A:A,'OJT IDs'!N:N,"Not found") -> IHG0063363-OJT | F15: =_xlfn.XLOOKUP(E15,'OJT Links'!E:E,'OJT Links'!H:H,"Not found") -> https://mylearning.sumtotal.host/core/pillarRedirect?relyingParty=LM&url=app%2Fmanagement%2FLMS_ActDetails.aspx%3FActivityId%3D468098%26UserMode%3D0
A16: Preventing Human Trafficking | B16: View the videos with your group to complete the learning offer . Once complete, review the assessments as a group. NOTE: Assessment records are not required) | C16: Link https://ihg.sharepoint.com/sites/ResponsibleBusiness/SitePages/Human-Rights-Brand-Standards-Guidance.aspx | D16: =_xlfn.XLOOKUP(A16,'All Courses'!A:A,'All Courses'!D:D,"Not found") -> course | E16: =_xlfn.XLOOKUP(A16,'OJT IDs'!A:A,'OJT IDs'!N:N,"Not found") -> IHG0057043-v2024-OJT | F16: =_xlfn.XLOOKUP(E16,'OJT Links'!E:E,'OJT Links'!H:H,"Not found") -> https://mylearning.sumtotal.host/core/pillarRedirect?relyingParty=LM&url=app%2Fmanagement%2FLMS_ActDetails.aspx%3FActivityId%3D468091%26UserMode%3D0
A17: IHG Problem Handling V2 | B17: View the videos with your group to complete the learning offer . Once complete, review the assessments as a group. NOTE: Assessment records are not required) | C17: Link | D17: =_xlfn.XLOOKUP(A17,'All Courses'!A:A,'All Courses'!D:D,"Not found") -> course | E17: =_xlfn.XLOOKUP(A17,'OJT IDs'!A:A,'OJT IDs'!N:N,"Not found") -> IHG056045-OJT | F17: =_xlfn.XLOOKUP(E17,'OJT Links'!E:E,'OJT Links'!H:H,"Not found") -> https://mylearning.sumtotal.host/core/pillarRedirect?relyingParty=LM&url=app%2Fmanagement%2FLMS_ActDetails.aspx%3FActivityId%3D468095%26UserMode%3D0
A18: Property Management System (PMS) | B18: Review maunufactor operating manual relevant department training in the PMS system | E18: =_xlfn.XLOOKUP(A18,'OJT IDs'!A:A,'OJT IDs'!N:N,"Not found") -> IHG5969164-OJT | F18: =_xlfn.XLOOKUP(E18,'OJT Links'!E:E,'OJT Links'!H:H,"Not found") -> https://mylearning.sumtotal.host/core/pillarRedirect?relyingParty=LM&url=app%2Fmanagement%2FLMS_ActDetails.aspx%3FActivityId%3D602920%26UserMode%3D0
A19: True Hospitality Service Skills | B19: View the videos with your group to complete the learning offer . Once complete, review the assessments as a group. NOTE: Assessment records are not required) | C19: Link | D19: =_xlfn.XLOOKUP(A19,'All Courses'!A:A,'All Courses'!D:D,"Not found") -> course | E19: =_xlfn.XLOOKUP(A19,'OJT IDs'!A:A,'OJT IDs'!N:N,"Not found") -> IHG051263-OJT | F19: =_xlfn.XLOOKUP(E19,'OJT Links'!E:E,'OJT Links'!H:H,"Not found") -> https://mylearning.sumtotal.host/core/pillarRedirect?relyingParty=LM&url=app%2Fmanagement%2FLMS_ActDetails.aspx%3FActivityId%3D468089%26UserMode%3D0
A20: Welcome to IHG | B20: View the videos with your group to complete the learning offer | C20: Link | D20: =_xlfn.XLOOKUP(A20,'All Courses'!A:A,'All Courses'!D:D,"Not found") -> course | E20: =_xlfn.XLOOKUP(A20,'OJT IDs'!A:A,'OJT IDs'!N:N,"Not found") -> IHG058044-OJT | F20: =_xlfn.XLOOKUP(E20,'OJT Links'!E:E,'OJT Links'!H:H,"Not found") -> Not found
A21: Property Orientation | B21: Complete a tour of your property with new hires. | E21: =_xlfn.XLOOKUP(A21,'OJT IDs'!A:A,'OJT IDs'!N:N,"Not found") -> IHG8342629-OJT | F21: =_xlfn.XLOOKUP(E21,'OJT Links'!E:E,'OJT Links'!H:H,"Not found") -> https://mylearning.sumtotal.host/core/pillarRedirect?relyingParty=LM&url=app%2Fmanagement%2FLMS_ActDetails.aspx%3FActivityId%3D603028%26UserMode%3D0
A22: Welcome to Kimpton! A Cultural Orientation | B22: This content can be delivered in a classroom setting as part of a orientation program or refresher | E22: =_xlfn.XLOOKUP(A22,'OJT IDs'!A:A,'OJT IDs'!N:N,"Not found") -> IHG0061384-OJT | F22: =_xlfn.XLOOKUP(E22,'OJT Links'!E:E,'OJT Links'!H:H,"Not found") -> https://mylearning.sumtotal.host/core/pillarRedirect?relyingParty=LM&url=app%2Fmanagement%2FLMS_ActDetails.aspx%3FActivityId%3D596787%26UserMode%3D0
D23: =_xlfn.XLOOKUP(A23,'All Courses'!A:A,'All Courses'!D:D,"Not found") -> 0
D24: =_xlfn.XLOOKUP(A24,'All Courses'!A:A,'All Courses'!D:D,"Not found") -> 0
D25: =_xlfn.XLOOKUP(A25,'All Courses'!A:A,'All Courses'!D:D,"Not found") -> 0
D26: =_xlfn.XLOOKUP(A26,'All Courses'!A:A,'All Courses'!D:D,"Not found") -> 0
D27: =_xlfn.XLOOKUP(A27,'All Courses'!A:A,'All Courses'!D:D,"Not found") -> 0
D28: =_xlfn.XLOOKUP(A28,'All Courses'!A:A,'All Courses'!D:D,"Not found") -> 0
D29: =_xlfn.XLOOKUP(A29,'All Courses'!A:A,'All Courses'!D:D,"Not found") -> 0
D30: =_xlfn.XLOOKUP(A30,'All Courses'!A:A,'All Courses'!D:D,"Not found") -> 0
D31: =_xlfn.XLOOKUP(A31,'All Courses'!A:A,'All Courses'!D:D,"Not found") -> 0
D32: =_xlfn.XLOOKUP(A32,'All Courses'!A:A,'All Courses'!D:D,"Not found") -> 0
D33: =_xlfn.XLOOKUP(A33,'All Courses'!A:A,'All Courses'!D:D,"Not found") -> 0
D34: =_xlfn.XLOOKUP(A34,'All Courses'!A:A,'All Courses'!D:D,"Not found") -> 0
... D39: =_xlfn.XLOOKUP(A39,'All Courses'!A:A,'All Courses'!D:D,"Not found") -> 0

Sheet Vignette
A1: Course Title | B1: Instructions | C1: Hyperlink for Access | D1: Access ______ | E1: Not visible to learner: OJT Course ID: | F1: Create OJT Button
A2: Digital Check-in | B2: View the videos with your group to complete the learning offer | C2: https://mylearning.sumtotal.host/core/pillarRedirect?relyingParty=LM&url=app%2fmanagement%2fLMS_ActDetails.aspx%3fActivityId%3d41%26UserMode%3d0 | D2: =_xlfn.XLOOKUP(A2,'All Courses'!A:A,'All Courses'!D:D,"Not found") -> course | E2: =_xlfn.XLOOKUP(A2,'OJT IDs'!A:A,'OJT IDs'!N:N,"Not found") -> IHG0061303-OJT | F2: =_xlfn.XLOOKUP(E2,'OJT Links'!E:E,'OJT Links'!H:H,"Not found") -> https://mylearning.sumtotal.host/core/pillarRedirect?relyingParty=LM&url=app%2Fmanagement%2FLMS_ActDetails.aspx%3FActivityId%3D595005%26UserMode%3D0
A3: First Aid | B3: Review your first aid procedures and practices. | E3: =_xlfn.XLOOKUP(A3,'OJT IDs'!A:A,'OJT IDs'!N:N,"Not found") -> IHG1885862-OJT | F3: =_xlfn.XLOOKUP(E3,'OJT Links'!E:E,'OJT Links'!H:H,"Not found") -> https://mylearning.sumtotal.host/core/pillarRedirect?relyingParty=LM&url=app%2Fmanagement%2FLMS_ActDetails.aspx%3FActivityId%3D601671%26UserMode%3D0
A4: Handling Credit Cards Securely | B4: View the videos with your group to complete the learning offer | C4: https://me2.ihgmerlin.com/web/init-ihg-information-security/homeandhttps://me2.ihgmerlin.com/web/init-pci-compliance | D4: =_xlfn.XLOOKUP(A4,'All Courses'!A:A,'All Courses'!D:D,"Not found") -> Resource | E4: =_xlfn.XLOOKUP(A4,'OJT IDs'!A:A,'OJT IDs'!N:N,"Not found") -> IHG0047626-OJT | F4: =_xlfn.XLOOKUP(E4,'OJT Links'!E:E,'OJT Links'!H:H,"Not found") -> Not found
A5: Health & Safety, Security an Emergency Procedures | B5: Review your health safety and security procedures, including fire evacuation plan. | C5: Link | D5: =_xlfn.XLOOKUP(A5,'All Courses'!A:A,'All Courses'!D:D,"Not found") -> course | E5: =_xlfn.XLOOKUP(A5,'OJT IDs'!A:A,'OJT IDs'!N:N,"Not found") -> IHG9191264-OJT | F5: =_xlfn.XLOOKUP(E5,'OJT Links'!E:E,'OJT Links'!H:H,"Not found") -> https://mylearning.sumtotal.host/core/pillarRedirect?relyingParty=LM&url=app%2Fmanagement%2FLMS_ActDetails.aspx%3FActivityId%3D601724%26UserMode%3D0
A6: Housekeeping Safety Device (US & Canada only) | B6: Review maunufactor operating manual for equipment and procedure for action when an alarm is triggered | E6: =_xlfn.XLOOKUP(A6,'OJT IDs'!A:A,'OJT IDs'!N:N,"Not found") -> IHG8611503-OJT | F6: =_xlfn.XLOOKUP(E6,'OJT Links'!E:E,'OJT Links'!H:H,"Not found") -> https://mylearning.sumtotal.host/core/pillarRedirect?relyingParty=LM&url=app%2Fmanagement%2FLMS_ActDetails.aspx%3FActivityId%3D601740%26UserMode%3D0
A7: Getting to Know IHG Concerto | B7: View the videos with your group to complete the learning offer . Once complete, review the assessments as a group. NOTE: Assessment records are not required) | C7: https://mylearning.sumtotal.host/core/pillarRedirect?relyingParty=LM&url=app%2fmanagement%2fLMS_ActDetails.aspx%3fActivityId%3d52090%26UserMode%3d0 | D7: =_xlfn.XLOOKUP(A7,'All Courses'!A:A,'All Courses'!D:D,"Not found") -> course | E7: =_xlfn.XLOOKUP(A7,'OJT IDs'!A:A,'OJT IDs'!N:N,"Not found") -> IHG0049491-OJT | F7: =_xlfn.XLOOKUP(E7,'OJT Links'!E:E,'OJT Links'!H:H,"Not found") -> https://mylearning.sumtotal.host/core/pillarRedirect?relyingParty=LM&url=app%2Fmanagement%2FLMS_ActDetails.aspx%3FActivityId%3D595027%26UserMode%3D0
A8: IHG Voice Program Training | B8: View the videos with your group to complete the learning offer | C8: https://mylearning.sumtotal.host/core/pillarRedirect?relyingParty=LM&url=app%2fmanagement%2fLMS_ActDetails.aspx%3fActivityId%3d2823%26UserMode%3d0 | D8: =_xlfn.XLOOKUP(A8,'All Courses'!A:A,'All Courses'!D:D,"Not found") -> course | E8: =_xlfn.XLOOKUP(A8,'OJT IDs'!A:A,'OJT IDs'!N:N,"Not found") -> IHG0054667-OJT | F8: =_xlfn.XLOOKUP(E8,'OJT Links'!E:E,'OJT Links'!H:H,"Not found") -> https://mylearning.sumtotal.host/core/pillarRedirect?relyingParty=LM&url=app%2Fmanagement%2FLMS_ActDetails.aspx%3FActivityId%3D595030%26UserMode%3D0
A9: IHG Way of Clean 5-S Cleaning Program | B9: View the videos with your group to complete the learning offer . Once complete, review the assessments as a group. NOTE: Assessment records are not required) | C9: Link | D9: =_xlfn.XLOOKUP(A9,'All Courses'!A:A,'All Courses'!D:D,"Not found") -> course | E9: =_xlfn.XLOOKUP(A9,'OJT IDs'!A:A,'OJT IDs'!N:N,"Not found") -> IHG7376524-OJT | F9: =_xlfn.XLOOKUP(E9,'OJT Links'!E:E,'OJT Links'!H:H,"Not found") -> https://mylearning.sumtotal.host/core/pillarRedirect?relyingParty=LM&url=app%2Fmanagement%2FLMS_ActDetails.aspx%3FActivityId%3D468097%26UserMode%3D0
A10: IHG Way of Clean 5-S Cleaning Program for Non-Housekeeping Colleagues | B10: View the videos with your group to complete the learning offer . Once complete, review the assessments as a group. NOTE: Assessment records are not required) | C10: Link | D10: =_xlfn.XLOOKUP(A10,'All Courses'!A:A,'All Courses'!D:D,"Not found") -> course | E10: =_xlfn.XLOOKUP(A10,'OJT IDs'!A:A,'OJT IDs'!N:N,"Not found") -> IHG1227263-OJT | F10: =_xlfn.XLOOKUP(E10,'OJT Links'!E:E,'OJT Links'!H:H,"Not found") -> https://mylearning.sumtotal.host/core/pillarRedirect?relyingParty=LM&url=app%2Fmanagement%2FLMS_ActDetails.aspx%3FActivityId%3D595028%26UserMode%3D0
A11: IHG World Class Beverage Academy - 101 Essentials | B11: View the videos with your group to complete the learning offer . Once complete, review the assessments as a group. NOTE: Assessment records are not required) | C11: Link | D11: =_xlfn.XLOOKUP(A11,'All Courses'!A:A,'All Courses'!D:D,"Not found") -> course | E11: =_xlfn.XLOOKUP(A11,'OJT IDs'!A:A,'OJT IDs'!N:N,"Not found") -> IHG052185-OJT | F11: =_xlfn.XLOOKUP(E11,'OJT Links'!E:E,'OJT Links'!H:H,"Not found") -> https://mylearning.sumtotal.host/core/pillarRedirect?relyingParty=LM&url=app%2Fmanagement%2FLMS_ActDetails.aspx%3FActivityId%3D595029%26UserMode%3D0
A12: Introduction to Information Security | B12: View the videos with your group to complete the learning offer | C12: Link | D12: =_xlfn.XLOOKUP(A12,'All Courses'!A:A,'All Courses'!D:D,"Not found") -> course | E12: =_xlfn.XLOOKUP(A12,'OJT IDs'!A:A,'OJT IDs'!N:N,"Not found") -> IHG0047625-OJT | F12: =_xlfn.XLOOKUP(E12,'OJT Links'!E:E,'OJT Links'!H:H,"Not found") -> https://mylearning.sumtotal.host/core/pillarRedirect?relyingParty=LM&url=app%2Fmanagement%2FLMS_ActDetails.aspx%3FActivityId%3D596770%26UserMode%3D0
A13: Leading and Sustaining your Service Culture | B13: View the videos with your group to complete the learning offer . Once complete, review the assessments as a group. NOTE: Assessment records are not required) | C13: Link | D13: =_xlfn.XLOOKUP(A13,'All Courses'!A:A,'All Courses'!D:D,"Not found") -> course | E13: =_xlfn.XLOOKUP(A13,'OJT IDs'!A:A,'OJT IDs'!N:N,"Not found") -> IHG0056403-OJT | F13: =_xlfn.XLOOKUP(E13,'OJT Links'!E:E,'OJT Links'!H:H,"Not found") -> https://mylearning.sumtotal.host/core/pillarRedirect?relyingParty=LM&url=app%2Fmanagement%2FLMS_ActDetails.aspx%3FActivityId%3D596772%26UserMode%3D0
A14: Luxury Fundamentals | B14: Use the link provided to access the learning offer. Review the offering in its entirety to complete. | C14: Link | D14: course | E14: =_xlfn.XLOOKUP(A14,'OJT IDs'!A:A,'OJT IDs'!N:N,"Not found") -> IHG0063363-OJT | F14: =_xlfn.XLOOKUP(E14,'OJT Links'!E:E,'OJT Links'!H:H,"Not found") -> https://mylearning.sumtotal.host/core/pillarRedirect?relyingParty=LM&url=app%2Fmanagement%2FLMS_ActDetails.aspx%3FActivityId%3D468098%26UserMode%3D0
A15: Preventing Human Trafficking | B15: View the videos with your group to complete the learning offer . Once complete, review the assessments as a group. NOTE: Assessment records are not required) | C15: Link https://ihg.sharepoint.com/sites/ResponsibleBusiness/SitePages/Human-Rights-Brand-Standards-Guidance.aspx | D15: =_xlfn.XLOOKUP(A15,'All Courses'!A:A,'All Courses'!D:D,"Not found") -> course | E15: =_xlfn.XLOOKUP(A15,'OJT IDs'!A:A,'OJT IDs'!N:N,"Not found") -> IHG0057043-v2024-OJT | F15: =_xlfn.XLOOKUP(E15,'OJT Links'!E:E,'OJT Links'!H:H,"Not found") -> https://mylearning.sumtotal.host/core/pillarRedirect?relyingParty=LM&url=app%2Fmanagement%2FLMS_ActDetails.aspx%3FActivityId%3D468091%26UserMode%3D0
A16: IHG Problem Handling V2 | B16: View the videos with your group to complete the learning offer . Once complete, review the assessments as a group. NOTE: Assessment records are not required) | C16: Link | D16: =_xlfn.XLOOKUP(A16,'All Courses'!A:A,'All Courses'!D:D,"Not found") -> course | E16: =_xlfn.XLOOKUP(A16,'OJT IDs'!A:A,'OJT IDs'!N:N,"Not found") -> IHG056045-OJT | F16: =_xlfn.XLOOKUP(E16,'OJT Links'!E:E,'OJT Links'!H:H,"Not found") -> https://mylearning.sumtotal.host/core/pillarRedirect?relyingParty=LM&url=app%2Fmanagement%2FLMS_ActDetails.aspx%3FActivityId%3D468095%26UserMode%3D0
A17: Property Management System (PMS) | B17: Review maunufactor operating manual relevant department training in the PMS system | E17: =_xlfn.XLOOKUP(A17,'OJT IDs'!A:A,'OJT IDs'!N:N,"Not found") -> IHG5969164-OJT | F17: =_xlfn.XLOOKUP(E17,'OJT Links'!E:E,'OJT Links'!H:H,"Not found") -> https://mylearning.sumtotal.host/core/pillarRedirect?relyingParty=LM&url=app%2Fmanagement%2FLMS_ActDetails.aspx%3FActivityId%3D602920%26UserMode%3D0
A18: True Hospitality Service Skills | B18: View the videos with your group to complete the learning offer . Once complete, review the assessments as a group. NOTE: Assessment records are not required) | C18: Link | D18: =_xlfn.XLOOKUP(A18,'All Courses'!A:A,'All Courses'!D:D,"Not found") -> course | E18: =_xlfn.XLOOKUP(A18,'OJT IDs'!A:A,'OJT IDs'!N:N,"Not found") -> IHG051263-OJT | F18: =_xlfn.XLOOKUP(E18,'OJT Links'!E:E,'OJT Links'!H:H,"Not found") -> https://mylearning.sumtotal.host/core/pillarRedirect?relyingParty=LM&url=app%2Fmanagement%2FLMS_ActDetails.aspx%3FActivityId%3D468089%26UserMode%3D0
A19: Welcome to IHG | B19: View the videos with your group to complete the learning offer | C19: Link | D19: =_xlfn.XLOOKUP(A19,'All Courses'!A:A,'All Courses'!D:D,"Not found") -> course | E19: =_xlfn.XLOOKUP(A19,'OJT IDs'!A:A,'OJT IDs'!N:N,"Not found") -> IHG058044-OJT | F19: =_xlfn.XLOOKUP(E19,'OJT Links'!E:E,'OJT Links'!H:H,"Not found") -> Not found
A20: Property Orientation | B20: Complete a tour of your property with new hires. | E20: =_xlfn.XLOOKUP(A20,'OJT IDs'!A:A,'OJT IDs'!N:N,"Not found") -> IHG8342629-OJT | F20: =_xlfn.XLOOKUP(E20,'OJT Links'!E:E,'OJT Links'!H:H,"Not found") -> https://mylearning.sumtotal.host/core/pillarRedirect?relyingParty=LM&url=app%2Fmanagement%2FLMS_ActDetails.aspx%3FActivityId%3D603028%26UserMode%3D0

Sheet Hotel Indigo
A1: Course Title | B1: Instructions | C1: Hyperlink for Access | D1: Access ______ | E1: Not visible to learner: OJT Course ID: | F1: Create OJT Button
A2: Art of Breakfast | B2: Use the link provided to access the learning offer. Review the offering in its entirety to complete. | C2: https://ihgfbamericas.com/wp-content/uploads/2016/09/The-Art-of-Breakfast-Service-Manager-Handbook-1.pdf | D2: =_xlfn.XLOOKUP(A2,'All Courses'!A:A,'All Courses'!D:D,"Not found") -> Resource | E2: =_xlfn.XLOOKUP(A2,'OJT IDs'!A:A,'OJT IDs'!N:N,"Not found") -> IHG1353819-OJT | F2: =_xlfn.XLOOKUP(E2,'OJT Links'!E:E,'OJT Links'!H:H,"Not found") -> https://mylearning.sumtotal.host/core/pillarRedirect?relyingParty=LM&url=app%2Fmanagement%2FLMS_ActDetails.aspx%3FActivityId%3D601508%26UserMode%3D0
A3: Art of Room | B3: Use the link provided to access the learning offer. Review the offering in its entirety to complete. | C3: https://ihgfbamericas.com/wp-content/uploads/2016/09/Art-of-Room-Service-Training-Manual.pdf | D3: =_xlfn.XLOOKUP(A3,'All Courses'!A:A,'All Courses'!D:D,"Not found") -> Resource | E3: =_xlfn.XLOOKUP(A3,'OJT IDs'!A:A,'OJT IDs'!N:N,"Not found") -> IHG9959789-OJT | F3: =_xlfn.XLOOKUP(E3,'OJT Links'!E:E,'OJT Links'!H:H,"Not found") -> https://mylearning.sumtotal.host/core/pillarRedirect?relyingParty=LM&url=app%2Fmanagement%2FLMS_ActDetails.aspx%3FActivityId%3D601510%26UserMode%3D0
A4: Business Services training | B4: Review maunufactor operating manuals for equipment and software. | E4: =_xlfn.XLOOKUP(A4,'OJT IDs'!A:A,'OJT IDs'!N:N,"Not found") -> IHG6321776-OJT | F4: =_xlfn.XLOOKUP(E4,'OJT Links'!E:E,'OJT Links'!H:H,"Not found") -> https://mylearning.sumtotal.host/core/pillarRedirect?relyingParty=LM&url=app%2Fmanagement%2FLMS_ActDetails.aspx%3FActivityId%3D601648%26UserMode%3D0
A5: Digital Check-in | B5: View the videos with your group to complete the learning offer | C5: https://mylearning.sumtotal.host/core/pillarRedirect?relyingParty=LM&url=app%2fmanagement%2fLMS_ActDetails.aspx%3fActivityId%3d41%26UserMode%3d0 | D5: =_xlfn.XLOOKUP(A5,'All Courses'!A:A,'All Courses'!D:D,"Not found") -> course | E5: =_xlfn.XLOOKUP(A5,'OJT IDs'!A:A,'OJT IDs'!N:N,"Not found") -> IHG0061303-OJT | F5: =_xlfn.XLOOKUP(E5,'OJT Links'!E:E,'OJT Links'!H:H,"Not found") -> https://mylearning.sumtotal.host/core/pillarRedirect?relyingParty=LM&url=app%2Fmanagement%2FLMS_ActDetails.aspx%3FActivityId%3D595005%26UserMode%3D0
A6: First Aid | B6: Review your first aid procedures and practices. | E6: =_xlfn.XLOOKUP(A6,'OJT IDs'!A:A,'OJT IDs'!N:N,"Not found") -> IHG1885862-OJT | F6: =_xlfn.XLOOKUP(E6,'OJT Links'!E:E,'OJT Links'!H:H,"Not found") -> https://mylearning.sumtotal.host/core/pillarRedirect?relyingParty=LM&url=app%2Fmanagement%2FLMS_ActDetails.aspx%3FActivityId%3D601671%26UserMode%3D0
A7: Handling Credit Cards Securely | B7: View the videos with your group to complete the learning offer | C7: https://me2.ihgmerlin.com/web/init-ihg-information-security/homeandhttps://me2.ihgmerlin.com/web/init-pci-compliance | D7: =_xlfn.XLOOKUP(A7,'All Courses'!A:A,'All Courses'!D:D,"Not found") -> Resource | E7: =_xlfn.XLOOKUP(A7,'OJT IDs'!A:A,'OJT IDs'!N:N,"Not found") -> IHG0047626-OJT | F7: =_xlfn.XLOOKUP(E7,'OJT Links'!E:E,'OJT Links'!H:H,"Not found") -> Not found
A8: Health & Safety, Security an Emergency Procedures | B8: Review your health safety and security procedures, including fire evacuation plan. | C8: Link | D8: =_xlfn.XLOOKUP(A8,'All Courses'!A:A,'All Courses'!D:D,"Not found") -> course | E8: =_xlfn.XLOOKUP(A8,'OJT IDs'!A:A,'OJT IDs'!N:N,"Not found") -> IHG9191264-OJT | F8: =_xlfn.XLOOKUP(E8,'OJT Links'!E:E,'OJT Links'!H:H,"Not found") -> https://mylearning.sumtotal.host/core/pillarRedirect?relyingParty=LM&url=app%2Fmanagement%2FLMS_ActDetails.aspx%3FActivityId%3D601724%26UserMode%3D0
A9: Housekeeping Safety Device (US & Canada only) | B9: Review maunufactor operating manual for equipment and procedure for action when an alarm is triggered | E9: =_xlfn.XLOOKUP(A9,'OJT IDs'!A:A,'OJT IDs'!N:N,"Not found") -> IHG8611503-OJT | F9: =_xlfn.XLOOKUP(E9,'OJT Links'!E:E,'OJT Links'!H:H,"Not found") -> https://mylearning.sumtotal.host/core/pillarRedirect?relyingParty=LM&url=app%2Fmanagement%2FLMS_ActDetails.aspx%3FActivityId%3D601740%26UserMode%3D0
A10: Getting to Know IHG Concerto | B10: View the videos with your group to complete the learning offer . Once complete, review the assessments as a group. NOTE: Assessment records are not required) | C10: https://mylearning.sumtotal.host/core/pillarRedirect?relyingParty=LM&url=app%2fmanagement%2fLMS_ActDetails.aspx%3fActivityId%3d52090%26UserMode%3d0 | D10: =_xlfn.XLOOKUP(A10,'All Courses'!A:A,'All Courses'!D:D,"Not found") -> course | E10: =_xlfn.XLOOKUP(A10,'OJT IDs'!A:A,'OJT IDs'!N:N,"Not found") -> IHG0049491-OJT | F10: =_xlfn.XLOOKUP(E10,'OJT Links'!E:E,'OJT Links'!H:H,"Not found") -> https://mylearning.sumtotal.host/core/pillarRedirect?relyingParty=LM&url=app%2Fmanagement%2FLMS_ActDetails.aspx%3FActivityId%3D595027%26UserMode%3D0
A11: IHG Voice Program Training | B11: View the videos with your group to complete the learning offer | C11: https://mylearning.sumtotal.host/core/pillarRedirect?relyingParty=LM&url=app%2fmanagement%2fLMS_ActDetails.aspx%3fActivityId%3d2823%26UserMode%3d0 | D11: =_xlfn.XLOOKUP(A11,'All Courses'!A:A,'All Courses'!D:D,"Not found") -> course | E11: =_xlfn.XLOOKUP(A11,'OJT IDs'!A:A,'OJT IDs'!N:N,"Not found") -> IHG0054667-OJT | F11: =_xlfn.XLOOKUP(E11,'OJT Links'!E:E,'OJT Links'!H:H,"Not found") -> https://mylearning.sumtotal.host/core/pillarRedirect?relyingParty=LM&url=app%2Fmanagement%2FLMS_ActDetails.aspx%3FActivityId%3D595030%26UserMode%3D0
A12: IHG Way of Clean 5-S Cleaning Program | B12: View the videos with your group to complete the learning offer . Once complete, review the assessments as a group. NOTE: Assessment records are not required) | C12: Link | D12: =_xlfn.XLOOKUP(A12,'All Courses'!A:A,'All Courses'!D:D,"Not found") -> course | E12: =_xlfn.XLOOKUP(A12,'OJT IDs'!A:A,'OJT IDs'!N:N,"Not found") -> IHG7376524-OJT | F12: =_xlfn.XLOOKUP(E12,'OJT Links'!E:E,'OJT Links'!H:H,"Not found") -> https://mylearning.sumtotal.host/core/pillarRedirect?relyingParty=LM&url=app%2Fmanagement%2FLMS_ActDetails.aspx%3FActivityId%3D468097%26UserMode%3D0
A13: IHG Way of Clean 5-S Cleaning Program for Non-Housekeeping Colleagues | B13: View the videos with your group to complete the learning offer . Once complete, review the assessments as a group. NOTE: Assessment records are not required) | C13: Link | D13: =_xlfn.XLOOKUP(A13,'All Courses'!A:A,'All Courses'!D:D,"Not found") -> course | E13: =_xlfn.XLOOKUP(A13,'OJT IDs'!A:A,'OJT IDs'!N:N,"Not found") -> IHG1227263-OJT | F13: =_xlfn.XLOOKUP(E13,'OJT Links'!E:E,'OJT Links'!H:H,"Not found") -> https://mylearning.sumtotal.host/core/pillarRedirect?relyingParty=LM&url=app%2Fmanagement%2FLMS_ActDetails.aspx%3FActivityId%3D595028%26UserMode%3D0
A14: IHG World Class Beverage Academy - 101 Essentials | B14: View the videos with your group to complete the learning offer . Once complete, review the assessments as a group. NOTE: Assessment records are not required) | C14: Link | D14: =_xlfn.XLOOKUP(A14,'All Courses'!A:A,'All Courses'!D:D,"Not found") -> course | E14: =_xlfn.XLOOKUP(A14,'OJT IDs'!A:A,'OJT IDs'!N:N,"Not found") -> IHG052185-OJT | F14: =_xlfn.XLOOKUP(E14,'OJT Links'!E:E,'OJT Links'!H:H,"Not found") -> https://mylearning.sumtotal.host/core/pillarRedirect?relyingParty=LM&url=app%2Fmanagement%2FLMS_ActDetails.aspx%3FActivityId%3D595029%26UserMode%3D0
A15: Introduction to Information Security | B15: View the videos with your group to complete the learning offer | C15: Link | D15: =_xlfn.XLOOKUP(A15,'All Courses'!A:A,'All Courses'!D:D,"Not found") -> course | E15: =_xlfn.XLOOKUP(A15,'OJT IDs'!A:A,'OJT IDs'!N:N,"Not found") -> IHG0047625-OJT | F15: =_xlfn.XLOOKUP(E15,'OJT Links'!E:E,'OJT Links'!H:H,"Not found") -> https://mylearning.sumtotal.host/core/pillarRedirect?relyingParty=LM&url=app%2Fmanagement%2FLMS_ActDetails.aspx%3FActivityId%3D596770%26UserMode%3D0
A16: Leading and Sustaining your Service Culture | B16: View the videos with your group to complete the learning offer . Once complete, review the assessments as a group. NOTE: Assessment records are not required) | C16: Link | D16: =_xlfn.XLOOKUP(A16,'All Courses'!A:A,'All Courses'!D:D,"Not found") -> course | E16: =_xlfn.XLOOKUP(A16,'OJT IDs'!A:A,'OJT IDs'!N:N,"Not found") -> IHG0056403-OJT | F16: =_xlfn.XLOOKUP(E16,'OJT Links'!E:E,'OJT Links'!H:H,"Not found") -> https://mylearning.sumtotal.host/core/pillarRedirect?relyingParty=LM&url=app%2Fmanagement%2FLMS_ActDetails.aspx%3FActivityId%3D596772%26UserMode%3D0
A17: Preventing Human Trafficking | B17: View the videos with your group to complete the learning offer . Once complete, review the assessments as a group. NOTE: Assessment records are not required) | C17: Link | D17: =_xlfn.XLOOKUP(A17,'All Courses'!A:A,'All Courses'!D:D,"Not found") -> course | E17: =_xlfn.XLOOKUP(A17,'OJT IDs'!A:A,'OJT IDs'!N:N,"Not found") -> IHG0057043-v2024-OJT | F17: =_xlfn.XLOOKUP(E17,'OJT Links'!E:E,'OJT Links'!H:H,"Not found") -> https://mylearning.sumtotal.host/core/pillarRedirect?relyingParty=LM&url=app%2Fmanagement%2FLMS_ActDetails.aspx%3FActivityId%3D468091%26UserMode%3D0
A18: IHG Problem Handling V2 | B18: View the videos with your group to complete the learning offer . Once complete, review the assessments as a group. NOTE: Assessment records are not required) | C18: https://ihg.sharepoint.com/sites/ResponsibleBusiness/SitePages/Human-Rights-Brand-Standards-Guidance.aspx | D18: =_xlfn.XLOOKUP(A18,'All Courses'!A:A,'All Courses'!D:D,"Not found") -> course | E18: =_xlfn.XLOOKUP(A18,'OJT IDs'!A:A,'OJT IDs'!N:N,"Not found") -> IHG056045-OJT | F18: =_xlfn.XLOOKUP(E18,'OJT Links'!E:E,'OJT Links'!H:H,"Not found") -> https://mylearning.sumtotal.host/core/pillarRedirect?relyingParty=LM&url=app%2Fmanagement%2FLMS_ActDetails.aspx%3FActivityId%3D468095%26UserMode%3D0
A19: Property Management System (PMS) | B19: Review maunufactor operating manual relevant department training in the PMS system | C19: Link | E19: =_xlfn.XLOOKUP(A19,'OJT IDs'!A:A,'OJT IDs'!N:N,"Not found") -> IHG5969164-OJT | F19: =_xlfn.XLOOKUP(E19,'OJT Links'!E:E,'OJT Links'!H:H,"Not found") -> https://mylearning.sumtotal.host/core/pillarRedirect?relyingParty=LM&url=app%2Fmanagement%2FLMS_ActDetails.aspx%3FActivityId%3D602920%26UserMode%3D0
A20: True Hospitality Service Skills | B20: View the videos with your group to complete the learning offer . Once complete, review the assessments as a group. NOTE: Assessment records are not required) | D20: =_xlfn.XLOOKUP(A20,'All Courses'!A:A,'All Courses'!D:D,"Not found") -> course | E20: =_xlfn.XLOOKUP(A20,'OJT IDs'!A:A,'OJT IDs'!N:N,"Not found") -> IHG051263-OJT | F20: =_xlfn.XLOOKUP(E20,'OJT Links'!E:E,'OJT Links'!H:H,"Not found") -> https://mylearning.sumtotal.host/core/pillarRedirect?relyingParty=LM&url=app%2Fmanagement%2FLMS_ActDetails.aspx%3FActivityId%3D468089%26UserMode%3D0
A21: Welcome to IHG | B21: View the videos with your group to complete the learning offer | C21: Link | D21: =_xlfn.XLOOKUP(A21,'All Courses'!A:A,'All Courses'!D:D,"Not found") -> course | E21: =_xlfn.XLOOKUP(A21,'OJT IDs'!A:A,'OJT IDs'!N:N,"Not found") -> IHG058044-OJT | F21: =_xlfn.XLOOKUP(E21,'OJT Links'!E:E,'OJT Links'!H:H,"Not found") -> Not found
A22: Property Orientation | B22: Complete a tour of your property with new hires. | C22: Link | E22: =_xlfn.XLOOKUP(A22,'OJT IDs'!A:A,'OJT IDs'!N:N,"Not found") -> IHG8342629-OJT | F22: =_xlfn.XLOOKUP(E22,'OJT Links'!E:E,'OJT Links'!H:H,"Not found") -> https://mylearning.sumtotal.host/core/pillarRedirect?relyingParty=LM&url=app%2Fmanagement%2FLMS_ActDetails.aspx%3FActivityId%3D603028%26UserMode%3D0
A23: Hotel Indigo Inspire New Stories Brand Experience Training | B23: View the videos with your group to complete the learning offer . Once complete, review the assessments as a group. NOTE: Assessment records are not required) | D23: =_xlfn.XLOOKUP(A23,'All Courses'!A:A,'All Courses'!D:D,"Not found") -> course | E23: =_xlfn.XLOOKUP(A23,'OJT IDs'!A:A,'OJT IDs'!N:N,"Not found") -> IHG0064483-OJT | F23: =_xlfn.XLOOKUP(E23,'OJT Links'!E:E,'OJT Links'!H:H,"Not found") -> https://mylearning.sumtotal.host/core/pillarRedirect?relyingParty=LM&url=app%2Fmanagement%2FLMS_ActDetails.aspx%3FActivityId%3D595025%26UserMode%3D0
A24: Hotel Indigo Inspire New Stories Brand Orientation | B24: View the videos with your group to complete the learning offer . Once complete, review the assessments as a group. NOTE: Assessment records are not required) | C24: https://mylearning.sumtotal.host/core/pillarRedirect?relyingParty=LM&url=app%2fmanagement%2fLMS_ActDetails.aspx%3fActivityId%3d14870%26UserMode%3d0 | D24: =_xlfn.XLOOKUP(A24,'All Courses'!A:A,'All Courses'!D:D,"Not found") -> course | E24: =_xlfn.XLOOKUP(A24,'OJT IDs'!A:A,'OJT IDs'!N:N,"Not found") -> IHG0064483-OJT | F24: =_xlfn.XLOOKUP(E24,'OJT Links'!E:E,'OJT Links'!H:H,"Not found") -> https://mylearning.sumtotal.host/core/pillarRedirect?relyingParty=LM&url=app%2Fmanagement%2FLMS_ActDetails.aspx%3FActivityId%3D595025%26UserMode%3D0

Sheet voco
