Workbook

Sheet Colour Guide
A1: Brand | B1: Primary | C1: Secondary
A2: Holiday Inn Express | B2: #002D72 | C2: #9BCBEB | D2: #E35205
A3: Holiday Inn | B3: #1C4B34 | C3: #578272 | D3: #9BC5B7
A4: avid hotels | B4: #68D2DF | C4: #FF0000
A5: Garner | B5: #ABDBC6 | C5: #FBF8EB
A6: Atwell Suites | B6: #6C714D | C6: #E8CEBD | D6: #B46A55
A7: Staybridge Suites | B7: #006980
A8: Candlewood Suites | B8: #9B2241 | C8: #00205B
A9: Even Hotels | B9: #164945
A10: voco | B10: #121217 | C10: #F8B9OD
A11: Crowne Plaza | B11: #A00062 | C11: #515A61
A12: Hotel Indigo | B12: #2E5992 | C12: #D8A400
A13: Vignette | B13: #2E273B | C13: #E9D0D5
A14: Intercontinental | B14: #3D3935 | C14: #CBC5BE
A15: Regent | B15: #D6E3DC | C15: F5E1CC | D15: #211551
A16: Kimpton | B16: #58565C | C16: #FFFFFF

Sheet Regent
A1: Course Title | B1: Instructions | C1: Hyperlink for Access | D1: Access ______ | E1: Not visible to learner: OJT Course ID: | F1: Create OJT Button
A2: First Aid | B2: Review your first aid procedures and practices. | E2: IHG1885862-OJT | F2: https://mylearning.sumtotal.host/core/pillarRedirect?relyingParty=LM&url=app%2Fmanagement%2FLMS_ActDetails.aspx%3FActivityId%3D601671%26UserMode%3D0
A3: Understanding PCI DSS | B3: View the videos with your group to complete the learning offer | C3: https://mylearning.sumtotal.host/core/pillarRedirect?relyingParty=LM&url=app%2fmanagement%2fLMS_ActDetails.aspx%3fActivityId%3d612703%26UserMode%3d0 | D3: Course | E3: IHG0047626-OJT | F3: https://mylearning.sumtotal.host/core/pillarRedirect?relyingParty=LM&url=app%2fmanagement%2fLMS_ActDetails.aspx%3fActivityId%3d595012%26UserMode%3d0
A4: Health & Safety, Security an Emergency Procedures | B4: Review your health safety and security procedures, including fire evacuation plan. | C4: Link | D4: course | E4: IHG9191264-OJT | F4: https://mylearning.sumtotal.host/core/pillarRedirect?relyingParty=LM&url=app%2Fmanagement%2FLMS_ActDetails.aspx%3FActivityId%3D601724%26UserMode%3D0
A5: Getting to Know IHG Concerto | B5: View the videos with your group to complete the learning offer. Once complete, review the assessments as a group. NOTE: Assessment records are not required | C5: https://mylearning.sumtotal.host/core/pillarRedirect?relyingParty=LM&url=app%2fmanagement%2fLMS_ActDetails.aspx%3fActivityId%3d52090%26UserMode%3d0 | D5: course | E5: IHG0049491-OJT | F5: https://mylearning.sumtotal.host/core/pillarRedirect?relyingParty=LM&url=app%2Fmanagement%2FLMS_ActDetails.aspx%3FActivityId%3D595027%26UserMode%3D0
A6: IHG Voice Program Training | B6: View the videos with your group to complete the learning offer | C6: https://mylearning.sumtotal.host/core/pillarRedirect?relyingParty=LM&url=app%2fmanagement%2fLMS_ActDetails.aspx%3fActivityId%3d2823%26UserMode%3d0 | D6: course | E6: IHG0054667-OJT | F6: https://mylearning.sumtotal.host/core/pillarRedirect?relyingParty=LM&url=app%2Fmanagement%2FLMS_ActDetails.aspx%3FActivityId%3D595030%26UserMode%3D0
A7: IHG Way of Clean 5-S Cleaning Program | B7: View the videos with your group to complete the learning offer. Once complete, review the assessments as a group. NOTE: Assessment records are not required | C7: Link | D7: course | E7: IHG7376524-OJT | F7: https://mylearning.sumtotal.host/core/pillarRedirect?relyingParty=LM&url=app%2Fmanagement%2FLMS_ActDetails.aspx%3FActivityId%3D468097%26UserMode%3D0
A8: IHG Way of Clean 5-S Cleaning Program for Non-Housekeeping Colleagues | B8: View the videos with your group to complete the learning offer. Once complete, review the assessments as a group. NOTE: Assessment records are not required | C8: Link | D8: course | E8: IHG1227263-OJT | F8: https://mylearning.sumtotal.host/core/pillarRedirect?relyingParty=LM&url=app%2Fmanagement%2FLMS_ActDetails.aspx%3FActivityId%3D595028%26UserMode%3D0
A9: IHG World Class Beverage Academy - 101 Essentials | B9: View the videos with your group to complete the learning offer. Once complete, review the assessments as a group. NOTE: Assessment records are not required | C9: Link | D9: course | E9: IHG052185-OJT | F9: https://mylearning.sumtotal.host/core/pillarRedirect?relyingParty=LM&url=app%2Fmanagement%2FLMS_ActDetails.aspx%3FActivityId%3D595029%26UserMode%3D0
A10: Introduction to Information Security | B10: View the videos with your group to complete the learning offer Please visit the Information Security Page on Merlin to learn more about Information Security at IHG: https://me2.ihgmerlin.com/web/init-ihg-information-security/home | C10: https://me2.ihgmerlin.com/web/init-ihg-information-security/home | D10: Resource | E10: IHG0047625-OJT | F10: https://mylearning.sumtotal.host/core/pillarRedirect?relyingParty=LM&url=app%2Fmanagement%2FLMS_ActDetails.aspx%3FActivityId%3D596770%26UserMode%3D0
A11: Leading and Sustaining your Service Culture | B11: View the videos with your group to complete the learning offer. Once complete, review the assessments as a group. NOTE: Assessment records are not required | C11: Link | D11: course | E11: IHG0056403-OJT | F11: https://mylearning.sumtotal.host/core/pillarRedirect?relyingParty=LM&url=app%2Fmanagement%2FLMS_ActDetails.aspx%3FActivityId%3D596772%26UserMode%3D0
A12: Luxury Fundamentals | B12: Use the link provided to access the learning offer. Review the offering in its entirety to complete. | C12: Link | D12: Course | E12: IHG0063363-OJT | F12: https://mylearning.sumtotal.host/core/pillarRedirect?relyingParty=LM&url=app%2Fmanagement%2FLMS_ActDetails.aspx%3FActivityId%3D468098%26UserMode%3D0
A13: Preventing Human Trafficking | B13: View the videos with your group to complete the learning offer. Once complete, review the assessments as a group. NOTE: Assessment records are not required | C13: Link https://ihg.sharepoint.com/sites/ResponsibleBusiness/SitePages/Human-Rights-Brand-Standards-Guidance.aspx | D13: course | E13: IHG0057043-OJT | F13: https://mylearning.sumtotal.host/core/pillarRedirect?relyingParty=LM&url=app%2Fmanagement%2FLMS_ActDetails.aspx%3FActivityId%3D468092%26UserMode%3D0
A14: IHG Problem Handling V2 | B14: View the videos with your group to complete the learning offer. Once complete, review the assessments as a group. NOTE: Assessment records are not required | C14: Link | D14: course | E14: IHG056045-OJT | F14: https://mylearning.sumtotal.host/core/pillarRedirect?relyingParty=LM&url=app%2Fmanagement%2FLMS_ActDetails.aspx%3FActivityId%3D468095%26UserMode%3D0
A15: Property Orientation | B15: Complete a tour of your property with new hires. | E15: IHG8342629-OJT | F15: https://mylearning.sumtotal.host/core/pillarRedirect?relyingParty=LM&url=app%2Fmanagement%2FLMS_ActDetails.aspx%3FActivityId%3D603028%26UserMode%3D0
A16: Regent Brand Experience Training | B16: Deliver your brand service training | E16: IHG2466648-OJT | F16: https://mylearning.sumtotal.host/core/pillarRedirect?relyingParty=LM&url=app%2Fmanagement%2FLMS_ActDetails.aspx%3FActivityId%3D606314%26UserMode%3D0
A17: Regent Brand Orientation | B17: Deliver your brand service training | E17: IHG2170824-OJT | F17: https://mylearning.sumtotal.host/core/pillarRedirect?relyingParty=LM&url=app%2Fmanagement%2FLMS_ActDetails.aspx%3FActivityId%3D606352%26UserMode%3D0
A18: True Hospitality Service Skills | B18: View the videos with your group to complete the learning offer. Once complete, review the assessments as a group. NOTE: Assessment records are not required | C18: Link | D18: course | E18: IHG051263-OJT | F18: https://mylearning.sumtotal.host/core/pillarRedirect?relyingParty=LM&url=app%2Fmanagement%2FLMS_ActDetails.aspx%3FActivityId%3D468089%26UserMode%3D0
A19: Welcome to IHG | B19: View the videos with your group to complete the learning offer | C19: Link | D19: course | E19: IHG058044-OJT | F19: https://mylearning.sumtotal.host/core/pillarRedirect?relyingParty=LM&url=app%2Fmanagement%2FLMS_ActDetails.aspx%3FActivityId%3D606314%26UserMode%3D0

Sheet InterContinental
A1: Course Title | B1: Instructions | C1: Hyperlink for Access | D1: Access ______ | E1: Not visible to learner: OJT Course ID: | F1: Create OJT Button
A2: First Aid | B2: Review your first aid procedures and practices. | E2: IHG1885862-OJT | F2: https://mylearning.sumtotal.host/core/pillarRedirect?relyingParty=LM&url=app%2Fmanagement%2FLMS_ActDetails.aspx%3FActivityId%3D601671%26UserMode%3D0
A3: Understanding PCI DSS | B3: View the videos with your group to complete the learning offer | C3: https://mylearning.sumtotal.host/core/pillarRedirect?relyingParty=LM&url=app%2fmanagement%2fLMS_ActDetails.aspx%3fActivityId%3d612703%26UserMode%3d0 | D3: Course | E3: IHG0047626-OJT | F3: https://mylearning.sumtotal.host/core/pillarRedirect?relyingParty=LM&url=app%2fmanagement%2fLMS_ActDetails.aspx%3fActivityId%3d595012%26UserMode%3d0
A4: Health & Safety, Security an Emergency Procedures | B4: Review your health safety and security procedures, including fire evacuation plan. | C4: Link | D4: course | E4: IHG9191264-OJT | F4: https://mylearning.sumtotal.host/core/pillarRedirect?relyingParty=LM&url=app%2Fmanagement%2FLMS_ActDetails.aspx%3FActivityId%3D601724%26UserMode%3D0
A5: Getting to Know IHG Concerto | B5: View the videos with your group to complete the learning offer. Once complete, review the assessments as a group. NOTE: Assessment records are not required | C5: https://mylearning.sumtotal.host/core/pillarRedirect?relyingParty=LM&url=app%2fmanagement%2fLMS_ActDetails.aspx%3fActivityId%3d52090%26UserMode%3d0 | D5: course | E5: IHG0049491-OJT | F5: https://mylearning.sumtotal.host/core/pillarRedirect?relyingParty=LM&url=app%2Fmanagement%2FLMS_ActDetails.aspx%3FActivityId%3D595027%26UserMode%3D0
A6: IHG Voice Program Training | B6: View the videos with your group to complete the learning offer | C6: https://mylearning.sumtotal.host/core/pillarRedirect?relyingParty=LM&url=app%2fmanagement%2fLMS_ActDetails.aspx%3fActivityId%3d2823%26UserMode%3d0 | D6: course | E6: IHG0054667-OJT | F6: https://mylearning.sumtotal.host/core/pillarRedirect?relyingParty=LM&url=app%2Fmanagement%2FLMS_ActDetails.aspx%3FActivityId%3D595030%26UserMode%3D0
A7: IHG Way of Clean 5-S Cleaning Program | B7: View the videos with your group to complete the learning offer. Once complete, review the assessments as a group. NOTE: Assessment records are not required | C7: Link | D7: course | E7: IHG7376524-OJT | F7: https://mylearning.sumtotal.host/core/pillarRedirect?relyingParty=LM&url=app%2Fmanagement%2FLMS_ActDetails.aspx%3FActivityId%3D468097%26UserMode%3D0
A8: IHG Way of Clean 5-S Cleaning Program for Non-Housekeeping Colleagues | B8: View the videos with your group to complete the learning offer. Once complete, review the assessments as a group. NOTE: Assessment records are not required | C8: Link | D8: course | E8: IHG1227263-OJT | F8: https://mylearning.sumtotal.host/core/pillarRedirect?relyingParty=LM&url=app%2Fmanagement%2FLMS_ActDetails.aspx%3FActivityId%3D595028%26UserMode%3D0
A9: IHG World Class Beverage Academy - 101 Essentials | B9: View the videos with your group to complete the learning offer. Once complete, review the assessments as a group. NOTE: Assessment records are not required | C9: Link | D9: course | E9: IHG052185-OJT | F9: https://mylearning.sumtotal.host/core/pillarRedirect?relyingParty=LM&url=app%2Fmanagement%2FLMS_ActDetails.aspx%3FActivityId%3D595029%26UserMode%3D0
A10: Introduction to Information Security | B10: View the videos with your group to complete the learning offer Please visit the Information Security Page on Merlin to learn more about Information Security at IHG: https://me2.ihgmerlin.com/web/init-ihg-information-security/home | C10: Link | D10: course | E10: IHG0047625-OJT | F10: https://mylearning.sumtotal.host/core/pillarRedirect?relyingParty=LM&url=app%2Fmanagement%2FLMS_ActDetails.aspx%3FActivityId%3D596770%26UserMode%3D0
A11: Leading and Sustaining your Service Culture | B11: View the videos with your group to complete the learning offer. Once complete, review the assessments as a group. NOTE: Assessment records are not required | C11: Link | D11: course | E11: IHG0056403-OJT | F11: https://mylearning.sumtotal.host/core/pillarRedirect?relyingParty=LM&url=app%2Fmanagement%2FLMS_ActDetails.aspx%3FActivityId%3D596772%26UserMode%3D0
A12: Luxury Fundamentals | B12: Use the link provided to access the learning offer. Review the offering in its entirety to complete. | C12: Link | D12: Course | E12: IHG0063363-OJT | F12: https://mylearning.sumtotal.host/core/pillarRedirect?relyingParty=LM&url=app%2Fmanagement%2FLMS_ActDetails.aspx%3FActivityId%3D468098%26UserMode%3D0
A13: Preventing Human Trafficking | B13: View the videos with your group to complete the learning offer. Once complete, review the assessments as a group. NOTE: Assessment records are not required | C13: Link https://ihg.sharepoint.com/sites/ResponsibleBusiness/SitePages/Human-Rights-Brand-Standards-Guidance.aspx | D13: course | E13: IHG0057043-OJT | F13: https://mylearning.sumtotal.host/core/pillarRedirect?relyingParty=LM&url=app%2Fmanagement%2FLMS_ActDetails.aspx%3FActivityId%3D468092%26UserMode%3D0
A14: IHG Problem Handling V2 | B14: View the videos with your group to complete the learning offer. Once complete, review the assessments as a group. NOTE: Assessment records are not required | C14: Link | D14: course | E14: IHG056045-OJT | F14: https://mylearning.sumtotal.host/core/pillarRedirect?relyingParty=LM&url=app%2Fmanagement%2FLMS_ActDetails.aspx%3FActivityId%3D468095%26UserMode%3D0
... A16: Welcome to IHG | B16: View the videos with your group to complete the learning offer | C16: Link | D16: course | E16: IHG058044-OJT | F16: https://mylearning.sumtotal.host/core/pillarRedirect?relyingParty=LM&url=app%2Fmanagement%2FLMS_ActDetails.aspx%3FActivityId%3D606314%26UserMode%3D0
A17: Property Orientation | B17: Complete a tour of your property with new hires. | E17: IHG8342629-OJT | F17: https://mylearning.sumtotal.host/core/pillarRedirect?relyingParty=LM&url=app%2Fmanagement%2FLMS_ActDetails.aspx%3FActivityId%3D603028%26UserMode%3D0
A18: InterContinental Hotels and Resorts Brand Orientation | B18: View the videos with your group to complete the learning offer. Once complete, review the assessments as a group. NOTE: Assessment records are not required | C18: https://mylearning.sumtotal.host/core/pillarRedirect?relyingParty=LM&url=app%2fmanagement%2fLMS_ActDetails.aspx%3fActivityId%3d10703%26UserMode%3d0 | D18: course | E18: IHG051925-OJT | F18: https://mylearning.sumtotal.host/core/pillarRedirect?relyingParty=LM&url=app%2Fmanagement%2FLMS_ActDetails.aspx%3FActivityId%3D595031%26UserMode%3D0

Sheet Kimpton
A1: Course Title | B1: Instructions | C1: Hyperlink for Access | D1: Access ______ | E1: Not visible to learner: OJT Course ID: | F1: Create OJT Button
A2: First Aid | B2: Review your first aid procedures and practices. | E2: IHG1885862-OJT | F2: https://mylearning.sumtotal.host/core/pillarRedirect?relyingParty=LM&url=app%2Fmanagement%2FLMS_ActDetails.aspx%3FActivityId%3D601671%26UserMode%3D0
A3: Understanding PCI DSS | B3: View the videos with your group to complete the learning offer | C3: https://mylearning.sumtotal.host/core/pillarRedirect?relyingParty=LM&url=app%2fmanagement%2fLMS_ActDetails.aspx%3fActivityId%3d612703%26UserMode%3d0 | D3: Course | E3: IHG0047626-OJT | F3: https://mylearning.sumtotal.host/core/pillarRedirect?relyingParty=LM&url=app%2fmanagement%2fLMS_ActDetails.aspx%3fActivityId%3d595012%26UserMode%3d0
A4: Health & Safety, Security an Emergency Procedures | B4: Review your health safety and security procedures, including fire evacuation plan. | C4: Link | D4: course | E4: IHG9191264-OJT | F4: https://mylearning.sumtotal.host/core/pillarRedirect?relyingParty=LM&url=app%2Fmanagement%2FLMS_ActDetails.aspx%3FActivityId%3D601724%26UserMode%3D0
A5: Getting to Know IHG Concerto | B5: View the videos with your group to complete the learning offer. Once complete, review the assessments as a group. NOTE: Assessment records are not required | C5: https://mylearning.sumtotal.host/core/pillarRedirect?relyingParty=LM&url=app%2fmanagement%2fLMS_ActDetails.aspx%3fActivityId%3d52090%26UserMode%3d0 | D5: course | E5: IHG0049491-OJT | F5: https://mylearning.sumtotal.host/core/pillarRedirect?relyingParty=LM&url=app%2Fmanagement%2FLMS_ActDetails.aspx%3FActivityId%3D595027%26UserMode%3D0
A6: IHG Voice Program Training | B6: View the videos with your group to complete the learning offer | C6: https://mylearning.sumtotal.host/core/pillarRedirect?relyingParty=LM&url=app%2fmanagement%2fLMS_ActDetails.aspx%3fActivityId%3d2823%26UserMode%3d0 | D6: course | E6: IHG0054667-OJT | F6: https://mylearning.sumtotal.host/core/pillarRedirect?relyingParty=LM&url=app%2Fmanagement%2FLMS_ActDetails.aspx%3FActivityId%3D595030%26UserMode%3D0
A7: IHG Way of Clean 5-S Cleaning Program | B7: View the videos with your group to complete the learning offer. Once complete, review the assessments as a group. NOTE: Assessment records are not required | C7: Link | D7: course | E7: IHG7376524-OJT | F7: https://mylearning.sumtotal.host/core/pillarRedirect?relyingParty=LM&url=app%2Fmanagement%2FLMS_ActDetails.aspx%3FActivityId%3D468097%26UserMode%3D0
A8: IHG Way of Clean 5-S Cleaning Program for Non-Housekeeping Colleagues | B8: View the videos with your group to complete the learning offer. Once complete, review the assessments as a group. NOTE: Assessment records are not required | C8: Link | D8: course | E8: IHG1227263-OJT | F8: https://mylearning.sumtotal.host/core/pillarRedirect?relyingParty=LM&url=app%2Fmanagement%2FLMS_ActDetails.aspx%3FActivityId%3D595028%26UserMode%3D0
A9: IHG World Class Beverage Academy - 101 Essentials | B9: View the videos with your group to complete the learning offer. Once complete, review the assessments as a group. NOTE: Assessment records are not required | C9: Link | D9: course | E9: IHG052185-OJT | F9: https://mylearning.sumtotal.host/core/pillarRedirect?relyingParty=LM&url=app%2Fmanagement%2FLMS_ActDetails.aspx%3FActivityId%3D595029%26UserMode%3D0
A10: Introduction to Information Security | B10: View the videos with your group to complete the learning offer Please visit the Information Security Page on Merlin to learn more about Information Security at IHG: https://me2.ihgmerlin.com/web/init-ihg-information-security/home | C10: Link | D10: course | E10: IHG0047625-OJT | F10: https://mylearning.sumtotal.host/core/pillarRedirect?relyingParty=LM&url=app%2Fmanagement%2FLMS_ActDetails.aspx%3FActivityId%3D596770%26UserMode%3D0
A11: Leading and Sustaining your Service Culture | B11: View the videos with your group to complete the learning offer. Once complete, review the assessments as a group. NOTE: Assessment records are not required | C11: Link | D11: course | E11: IHG0056403-OJT | F11: https://mylearning.sumtotal.host/core/pillarRedirect?relyingParty=LM&url=app%2Fmanagement%2FLMS_ActDetails.aspx%3FActivityId%3D596772%26UserMode%3D0
A12: Luxury Fundamentals | B12: Use the link provided to access the learning offer. Review the offering in its entirety to complete. | C12: Link | D12: Course | E12: IHG0063363-OJT | F12: https://mylearning.sumtotal.host/core/pillarRedirect?relyingParty=LM&url=app%2Fmanagement%2FLMS_ActDetails.aspx%3FActivityId%3D468098%26UserMode%3D0
A13: Preventing Human Trafficking | B13: View the videos with your group to complete the learning offer. Once complete, review the assessments as a group. NOTE: Assessment records are not required | C13: Link https://ihg.sharepoint.com/sites/ResponsibleBusiness/SitePages/Human-Rights-Brand-Standards-Guidance.aspx | D13: course | E13: IHG0057043-OJT | F13: https://mylearning.sumtotal.host/core/pillarRedirect?relyingParty=LM&url=app%2Fmanagement%2FLMS_ActDetails.aspx%3FActivityId%3D468092%26UserMode%3D0
A14: IHG Problem Handling V2 | B14: View the videos with your group to complete the learning offer. Once complete, review the assessments as a group. NOTE: Assessment records are not required | C14: Link | D14: course | E14: IHG056045-OJT | F14: https://mylearning.sumtotal.host/core/pillarRedirect?relyingParty=LM&url=app%2Fmanagement%2FLMS_ActDetails.aspx%3FActivityId%3D468095%26UserMode%3D0
... A16: Welcome to IHG | B16: View the videos with your group to complete the learning offer | C16: Link | D16: course | E16: IHG058044-OJT | F16: https://mylearning.sumtotal.host/core/pillarRedirect?relyingParty=LM&url=app%2Fmanagement%2FLMS_ActDetails.aspx%3FActivityId%3D606314%26UserMode%3D0
A17: Property Orientation | B17: Complete a tour of your property with new hires. | E17: IHG8342629-OJT | F17: https://mylearning.sumtotal.host/core/pillarRedirect?relyingParty=LM&url=app%2Fmanagement%2FLMS_ActDetails.aspx%3FActivityId%3D603028%26UserMode%3D0

Sheet Vignette
A1: Course Title | B1: Instructions | C1: Hyperlink for Access | D1: Access ______ | E1: Not visible to learner: OJT Course ID: | F1: Create OJT Button
A2: First Aid | B2: Review your first aid procedures and practices. | E2: IHG1885862-OJT | F2: https://mylearning.sumtotal.host/core/pillarRedirect?relyingParty=LM&url=app%2Fmanagement%2FLMS_ActDetails.aspx%3FActivityId%3D601671%26UserMode%3D0
A3: Understanding PCI DSS | B3: View the videos with your group to complete the learning offer | C3: https://mylearning.sumtotal.host/core/pillarRedirect?relyingParty=LM&url=app%2fmanagement%2fLMS_ActDetails.aspx%3fActivityId%3d612703%26UserMode%3d0 | D3: Course | E3: IHG0047626-OJT | F3: https://mylearning.sumtotal.host/core/pillarRedirect?relyingParty=LM&url=app%2fmanagement%2fLMS_ActDetails.aspx%3fActivityId%3d595012%26UserMode%3d0
A4: Health & Safety, Security an Emergency Procedures | B4: Review your health safety and security procedures, including fire evacuation plan. | C4: Link | D4: course | E4: IHG9191264-OJT | F4: https://mylearning.sumtotal.host/core/pillarRedirect?relyingParty=LM&url=app%2Fmanagement%2FLMS_ActDetails.aspx%3FActivityId%3D601724%26UserMode%3D0
A5: Getting to Know IHG Concerto | B5: View the videos with your group to complete the learning offer. Once complete, review the assessments as a group. NOTE: Assessment records are not required | C5: https://mylearning.sumtotal.host/core/pillarRedirect?relyingParty=LM&url=app%2fmanagement%2fLMS_ActDetails.aspx%3fActivityId%3d52090%26UserMode%3d0 | D5: course | E5: IHG0049491-OJT | F5: https://mylearning.sumtotal.host/core/pillarRedirect?relyingParty=LM&url=app%2Fmanagement%2FLMS_ActDetails.aspx%3FActivityId%3D595027%26UserMode%3D0
A6: IHG Voice Program Training | B6: View the videos with your group to complete the learning offer | C6: https://mylearning.sumtotal.host/core/pillarRedirect?relyingParty=LM&url=app%2fmanagement%2fLMS_ActDetails.aspx%3fActivityId%3d2823%26UserMode%3d0 | D6: course | E6: IHG0054667-OJT | F6: https://mylearning.sumtotal.host/core/pillarRedirect?relyingParty=LM&url=app%2Fmanagement%2FLMS_ActDetails.aspx%3FActivityId%3D595030%26UserMode%3D0
A7: IHG Way of Clean 5-S Cleaning Program | B7: View the videos with your group to complete the learning offer. Once complete, review the assessments as a group. NOTE: Assessment records are not required | C7: Link | D7: course | E7: IHG7376524-OJT | F7: https://mylearning.sumtotal.host/core/pillarRedirect?relyingParty=LM&url=app%2Fmanagement%2FLMS_ActDetails.aspx%3FActivityId%3D468097%26UserMode%3D0
A8: IHG Way of Clean 5-S Cleaning Program for Non-Housekeeping Colleagues | B8: View the videos with your group to complete the learning offer. Once complete, review the assessments as a group. NOTE: Assessment records are not required | C8: Link | D8: course | E8: IHG1227263-OJT | F8: https://mylearning.sumtotal.host/core/pillarRedirect?relyingParty=LM&url=app%2Fmanagement%2FLMS_ActDetails.aspx%3FActivityId%3D595028%26UserMode%3D0
A9: IHG World Class Beverage Academy - 101 Essentials | B9: View the videos with your group to complete the learning offer. Once complete, review the assessments as a group. NOTE: Assessment records are not required | C9: Link | D9: course | E9: IHG052185-OJT | F9: https://mylearning.sumtotal.host/core/pillarRedirect?relyingParty=LM&url=app%2Fmanagement%2FLMS_ActDetails.aspx%3FActivityId%3D595029%26UserMode%3D0
A10: Introduction to Information Security | B10: View the videos with your group to complete the learning offer Please visit the Information Security Page on Merlin to learn more about Information Security at IHG: https://me2.ihgmerlin.com/web/init-ihg-information-security/home | C10: Link | D10: course | E10: IHG0047625-OJT | F10: https://mylearning.sumtotal.host/core/pillarRedirect?relyingParty=LM&url=app%2Fmanagement%2FLMS_ActDetails.aspx%3FActivityId%3D596770%26UserMode%3D0
A11: Leading and Sustaining your Service Culture | B11: View the videos with your group to complete the learning offer. Once complete, review the assessments as a group. NOTE: Assessment records are not required | C11: Link | D11: course | E11: IHG0056403-OJT | F11: https://mylearning.sumtotal.host/core/pillarRedirect?relyingParty=LM&url=app%2Fmanagement%2FLMS_ActDetails.aspx%3FActivityId%3D596772%26UserMode%3D0
A12: Luxury Fundamentals | B12: Use the link provided to access the learning offer. Review the offering in its entirety to complete. | C12: Link | D12: Course | E12: IHG0063363-OJT | F12: https://mylearning.sumtotal.host/core/pillarRedirect?relyingParty=LM&url=app%2Fmanagement%2FLMS_ActDetails.aspx%3FActivityId%3D468098%26UserMode%3D0
A13: Preventing Human Trafficking | B13: View the videos with your group to complete the learning offer. Once complete, review the assessments as a group. NOTE: Assessment records are not required | C13: Link https://ihg.sharepoint.com/sites/ResponsibleBusiness/SitePages/Human-Rights-Brand-Standards-Guidance.aspx | D13: course | E13: IHG0057043-OJT | F13: https://mylearning.sumtotal.host/core/pillarRedirect?relyingParty=LM&url=app%2Fmanagement%2FLMS_ActDetails.aspx%3FActivityId%3D468092%26UserMode%3D0
A14: IHG Problem Handling V2 | B14: View the videos with your group to complete the learning offer. Once complete, review the assessments as a group. NOTE: Assessment records are not required | C14: Link | D14: course | E14: IHG056045-OJT | F14: https://mylearning.sumtotal.host/core/pillarRedirect?relyingParty=LM&url=app%2Fmanagement%2FLMS_ActDetails.aspx%3FActivityId%3D468095%26UserMode%3D0
... A16: Welcome to IHG | B16: View the videos with your group to complete the learning offer | C16: Link | D16: course | E16: IHG058044-OJT | F16: https://mylearning.sumtotal.host/core/pillarRedirect?relyingParty=LM&url=app%2Fmanagement%2FLMS_ActDetails.aspx%3FActivityId%3D606314%26UserMode%3D0
A17: Property Orientation | B17: Complete a tour of your property with new hires. | E17: IHG8342629-OJT | F17: https://mylearning.sumtotal.host/core/pillarRedirect?relyingParty=LM&url=app%2Fmanagement%2FLMS_ActDetails.aspx%3FActivityId%3D603028%26UserMode%3D0
A18: Vignette Collection Brand Orientation | B18: Deliver your brand service training | E18: IHG1995111-OJT | F18: https://mylearning.sumtotal.host/core/pillarRedirect?relyingParty=LM&url=app%2Fmanagement%2FLMS_ActDetails.aspx%3FActivityId%3D606368%26UserMode%3D0
A19: Vignette Collection Brand Experience Training | B19: Deliver your brand service training | E19: IHG9705880-OJT | F19: https://mylearning.sumtotal.host/core/pillarRedirect?relyingParty=LM&url=app%2Fmanagement%2FLMS_ActDetails.aspx%3FActivityId%3D606368%26UserMode%3D0

Sheet Hotel Indigo
A1: Course Title | B1: Instructions | C1: Hyperlink for Access | D1: Access ______ | E1: Not visible to learner: OJT Course ID: | F1: Create OJT Button
A2: First Aid | B2: Review your first aid procedures and practices. | E2: IHG1885862-OJT | F2: https://mylearning.sumtotal.host/core/pillarRedirect?relyingParty=LM&url=app%2Fmanagement%2FLMS_ActDetails.aspx%3FActivityId%3D601671%26UserMode%3D0
A3: Understanding PCI DSS | B3: View the videos with your group to complete the learning offer | C3: https://mylearning.sumtotal.host/core/pillarRedirect?relyingParty=LM&url=app%2fmanagement%2fLMS_ActDetails.aspx%3fActivityId%3d612703%26UserMode%3d0 | D3: Course | E3: IHG0047626-OJT | F3: https://mylearning.sumtotal.host/core/pillarRedirect?relyingParty=LM&url=app%2fmanagement%2fLMS_ActDetails.aspx%3fActivityId%3d595012%26UserMode%3d0
A4: Health & Safety, Security an Emergency Procedures | B4: Review your health safety and security procedures, including fire evacuation plan. | C4: Link | D4: course | E4: IHG9191264-OJT | F4: https://mylearning.sumtotal.host/core/pillarRedirect?relyingParty=LM&url=app%2Fmanagement%2FLMS_ActDetails.aspx%3FActivityId%3D601724%26UserMode%3D0
A5: Getting to Know IHG Concerto | B5: View the videos with your group to complete the learning offer. Once complete, review the assessments as a group. NOTE: Assessment records are not required | C5: https://mylearning.sumtotal.host/core/pillarRedirect?relyingParty=LM&url=app%2fmanagement%2fLMS_ActDetails.aspx%3fActivityId%3d52090%26UserMode%3d0 | D5: course | E5: IHG0049491-OJT | F5: https://mylearning.sumtotal.host/core/pillarRedirect?relyingParty=LM&url=app%2Fmanagement%2FLMS_ActDetails.aspx%3FActivityId%3D595027%26UserMode%3D0
A6: IHG Voice Program Training | B6: View the videos with your group to complete the learning offer | C6: https://mylearning.sumtotal.host/core/pillarRedirect?relyingParty=LM&url=app%2fmanagement%2fLMS_ActDetails.aspx%3fActivityId%3d2823%26UserMode%3d0 | D6: course | E6: IHG0054667-OJT | F6: https://mylearning.sumtotal.host/core/pillarRedirect?relyingParty=LM&url=app%2Fmanagement%2FLMS_ActDetails.aspx%3FActivityId%3D595030%26UserMode%3D0
A7: IHG Way of Clean 5-S Cleaning Program | B7: View the videos with your group to complete the learning offer. Once complete, review the assessments as a group. NOTE: Assessment records are not required | C7: Link | D7: course | E7: IHG7376524-OJT | F7: https://mylearning.sumtotal.host/core/pillarRedirect?relyingParty=LM&url=app%2Fmanagement%2FLMS_ActDetails.aspx%3FActivityId%3D468097%26UserMode%3D0
A8: IHG Way of Clean 5-S Cleaning Program for Non-Housekeeping Colleagues | B8: View the videos with your group to complete the learning offer. Once complete, review the assessments as a group. NOTE: Assessment records are not required | C8: Link | D8: course | E8: IHG1227263-OJT | F8: https://mylearning.sumtotal.host/core/pillarRedirect?relyingParty=LM&url=app%2Fmanagement%2FLMS_ActDetails.aspx%3FActivityId%3D595028%26UserMode%3D0
A9: IHG World Class Beverage Academy - 101 Essentials | B9: View the videos with your group to complete the learning offer. Once complete, review the assessments as a group. NOTE: Assessment records are not required | C9: Link | D9: course | E9: IHG052185-OJT | F9: https://mylearning.sumtotal.host/core/pillarRedirect?relyingParty=LM&url=app%2Fmanagement%2FLMS_ActDetails.aspx%3FActivityId%3D595029%26UserMode%3D0
A10: Introduction to Information Security | B10: View the videos with your group to complete the learning offer Please visit the Information Security Page on Merlin to learn more about Information Security at IHG: https://me2.ihgmerlin.com/web/init-ihg-information-security/home | C10: Link | D10: course | E10: IHG0047625-OJT | F10: https://mylearning.sumtotal.host/core/pillarRedirect?relyingParty=LM&url=app%2Fmanagement%2FLMS_ActDetails.aspx%3FActivityId%3D596770%26UserMode%3D0
A11: Leading and Sustaining your Service Culture | B11: View the videos with your group to complete the learning offer. Once complete, review the assessments as a group. NOTE: Assessment records are not required | C11: Link | D11: course | E11: IHG0056403-OJT | F11: https://mylearning.sumtotal.host/core/pillarRedirect?relyingParty=LM&url=app%2Fmanagement%2FLMS_ActDetails.aspx%3FActivityId%3D596772%26UserMode%3D0
A12: Preventing Human Trafficking | B12: View the videos with your group to complete the learning offer. Once complete, review the assessments as a group. NOTE: Assessment records are not required | C12: Link https://ihg.sharepoint.com/sites/ResponsibleBusiness/SitePages/Human-Rights-Brand-Standards-Guidance.aspx | D12: course | E12: IHG0057043-OJT | F12: https://mylearning.sumtotal.host/core/pillarRedirect?relyingParty=LM&url=app%2Fmanagement%2FLMS_ActDetails.aspx%3FActivityId%3D468092%26UserMode%3D0
A13: IHG Problem Handling V2 | B13: View the videos with your group to complete the learning offer. Once complete, review the assessments as a group. NOTE: Assessment records are not required | C13: Link | D13: course | E13: IHG056045-OJT | F13: https://mylearning.sumtotal.host/core/pillarRedirect?relyingParty=LM&url=app%2Fmanagement%2FLMS_ActDetails.aspx%3FActivityId%3D468095%26UserMode%3D0
A14: True Hospitality Service Skills | B14: View the videos with your group to complete the learning offer. Once complete, review the assessments as a group. NOTE: Assessment records are not required | C14: Link | D14: course | E14: IHG051263-OJT | F14: https://mylearning.sumtotal.host/core/pillarRedirect?relyingParty=LM&url=app%2Fmanagement%2FLMS_ActDetails.aspx%3FActivityId%3D468089%26UserMode%3D0
A15: Welcome to IHG | B15: View the videos with your group to complete the learning offer | C15: Link | D15: course | E15: IHG058044-OJT | F15: https://mylearning.sumtotal.host/core/pillarRedirect?relyingParty=LM&url=app%2Fmanagement%2FLMS_ActDetails.aspx%3FActivityId%3D606314%26UserMode%3D0
A16: Property Orientation | B16: Complete a tour of your property with new hires. | E16: IHG8342629-OJT | F16: https://mylearning.sumtotal.host/core/pillarRedirect?relyingParty=LM&url=app%2Fmanagement%2FLMS_ActDetails.aspx%3FActivityId%3D603028%26UserMode%3D0
A17: Hotel Indigo Inspire New Stories Brand Experience Training | B17: View the videos with your group to complete the learning offer. Once complete, review the assessments as a group. NOTE: Assessment records are not required | C17: https://mylearning.sumtotal.host/core/pillarRedirect?relyingParty=LM&url=app%2fmanagement%2fLMS_ActDetails.aspx%3fActivityId%3d14870%26UserMode%3d0 | D17: course | E17: IHG0064463-OJT | F17: https://mylearning.sumtotal.host/Core/pillarRedirect?relyingParty=LM&url=core%2Factivitydetails%2FViewActivityDetails%3FActivityId%3D595019%26UserMode%3D0
A18: Hotel Indigo Inspire New Stories Brand Orientation | B18: View the videos with your group to complete the learning offer. Once complete, review the assessments as a group. NOTE: Assessment records are not required | C18: https://mylearning.sumtotal.host/core/pillarRedirect?relyingParty=LM&url=app%2fmanagement%2fLMS_ActDetails.aspx%3fActivityId%3d14835%26UserMode%3d0 | D18: course | E18: IHG0064483-OJT | F18: https://mylearning.sumtotal.host/core/pillarRedirect?relyingParty=LM&url=app%2Fmanagement%2FLMS_ActDetails.aspx%3FActivityId%3D595025%26UserMode%3D0

Sheet voco
A1: Course Title | B1: Instructions | C1: Hyperlink for Access | D1: Access ______ | E1: Not visible to learner: OJT Course ID: | F1: Create OJT Button
A2: First Aid | B2: Review your first aid procedures and practices. | E2: IHG1885862-OJT | F2: https://mylearning.sumtotal.host/core/pillarRedirect?relyingParty=LM&url=app%2Fmanagement%2FLMS_ActDetails.aspx%3FActivityId%3D601671%26UserMode%3D0
A3: Understanding PCI DSS | B3: View the videos with your group to complete the learning offer | C3: https://mylearning.sumtotal.host/core/pillarRedirect?relyingParty=LM&url=app%2fmanagement%2fLMS_ActDetails.aspx%3fActivityId%3d612703%26UserMode%3d0 | D3: Course | E3: IHG0047626-OJT | F3: https://mylearning.sumtotal.host/core/pillarRedirect?relyingParty=LM&url=app%2fmanagement%2fLMS_ActDetails.aspx%3fActivityId%3d595012%26UserMode%3d0
A4: Health & Safety, Security an Emergency Procedures | B4: Review your health safety and security procedures, including fire evacuation plan. | C4: Link | D4: course | E4: IHG9191264-OJT | F4: https://mylearning.sumtotal.host/core/pillarRedirect?relyingParty=LM&url=app%2Fmanagement%2FLMS_ActDetails.aspx%3FActivityId%3D601724%26UserMode%3D0
A5: Getting to Know IHG Concerto | B5: View the videos with your group to complete the learning offer. Once complete, review the assessments as a group. NOTE: Assessment records are not required | C5: https://mylearning.sumtotal.host/core/pillarRedirect?relyingParty=LM&url=app%2fmanagement%2fLMS_ActDetails.aspx%3fActivityId%3d52090%26UserMode%3d0 | D5: course | E5: IHG0049491-OJT | F5: https://mylearning.sumtotal.host/core/pillarRedirect?relyingParty=LM&url=app%2Fmanagement%2FLMS_ActDetails.aspx%3FActivityId%3D595027%26UserMode%3D0
A6: IHG Voice Program Training | B6: View the videos with your group to complete the learning offer | C6: https://mylearning.sumtotal.host/core/pillarRedirect?relyingParty=LM&url=app%2fmanagement%2fLMS_ActDetails.aspx%3fActivityId%3d2823%26UserMode%3d0 | D6: course | E6: IHG0054667-OJT | F6: https://mylearning.sumtotal.host/core/pillarRedirect?relyingParty=LM&url=app%2Fmanagement%2FLMS_ActDetails.aspx%3FActivityId%3D595030%26UserMode%3D0
A7: IHG Way of Clean 5-S Cleaning Program | B7: View the videos with your group to complete the learning offer. Once complete, review the assessments as a group. NOTE: Assessment records are not required | C7: Link | D7: course | E7: IHG7376524-OJT | F7: https://mylearning.sumtotal.host/core/pillarRedirect?relyingParty=LM&url=app%2Fmanagement%2FLMS_ActDetails.aspx%3FActivityId%3D468097%26UserMode%3D0
A8: IHG Way of Clean 5-S Cleaning Program for Non-Housekeeping Colleagues | B8: View the videos with your group to complete the learning offer. Once complete, review the assessments as a group. NOTE: Assessment records are not required | C8: Link | D8: course | E8: IHG1227263-OJT | F8: https://mylearning.sumtotal.host/core/pillarRedirect?relyingParty=LM&url=app%2Fmanagement%2FLMS_ActDetails.aspx%3FActivityId%3D595028%26UserMode%3D0
A9: IHG World Class Beverage Academy - 101 Essentials | B9: View the videos with your group to complete the learning offer. Once complete, review the assessments as a group. NOTE: Assessment records are not required | C9: Link | D9: course | E9: IHG052185-OJT | F9: https://mylearning.sumtotal.host/core/pillarRedirect?relyingParty=LM&url=app%2Fmanagement%2FLMS_ActDetails.aspx%3FActivityId%3D595029%26UserMode%3D0
A10: Introduction to Information Security | B10: View the videos with your group to complete the learning offer Please visit the Information Security Page on Merlin to learn more about Information Security at IHG: https://me2.ihgmerlin.com/web/init-ihg-information-security/home | C10: Link | D10: course | E10: IHG0047625-OJT | F10: https://mylearning.sumtotal.host/core/pillarRedirect?relyingParty=LM&url=app%2Fmanagement%2FLMS_ActDetails.aspx%3FActivityId%3D596770%26UserMode%3D0
A11: Leading and Sustaining your Service Culture | B11: View the videos with your group to complete the learning offer. Once complete, review the assessments as a group. NOTE: Assessment records are not required | C11: Link | D11: course | E11: IHG0056403-OJT | F11: https://mylearning.sumtotal.host/core/pillarRedirect?relyingParty=LM&url=app%2Fmanagement%2FLMS_ActDetails.aspx%3FActivityId%3D596772%26UserMode%3D0
A12: Preventing Human Trafficking | B12: View the videos with your group to complete the learning offer. Once complete, review the assessments as a group. NOTE: Assessment records are not required | C12: Link https://ihg.sharepoint.com/sites/ResponsibleBusiness/SitePages/Human-Rights-Brand-Standards-Guidance.aspx | D12: course | E12: IHG0057043-OJT | F12: https://mylearning.sumtotal.host/core/pillarRedirect?relyingParty=LM&url=app%2Fmanagement%2FLMS_ActDetails.aspx%3FActivityId%3D468092%26UserMode%3D0
A13: IHG Problem Handling V2 | B13: View the videos with your group to complete the learning offer. Once complete, review the assessments as a group. NOTE: Assessment records are not required | C13: Link | D13: course | E13: IHG056045-OJT | F13: https://mylearning.sumtotal.host/core/pillarRedirect?relyingParty=LM&url=app%2Fmanagement%2FLMS_ActDetails.aspx%3FActivityId%3D468095%26UserMode%3D0
A14: True Hospitality Service Skills | B14: View the videos with your group to complete the learning offer. Once complete, review the assessments as a group. NOTE: Assessment records are not required | C14: Link | D14: course | E14: IHG051263-OJT | F14: https://mylearning.sumtotal.host/core/pillarRedirect?relyingParty=LM&url=app%2Fmanagement%2FLMS_ActDetails.aspx%3FActivityId%3D468089%26UserMode%3D0
A15: Welcome to IHG | B15: View the videos with your group to complete the learning offer | C15: Link | D15: course | E15: IHG058044-OJT | F15: https://mylearning.sumtotal.host/core/pillarRedirect?relyingParty=LM&url=app%2Fmanagement%2FLMS_ActDetails.aspx%3FActivityId%3D606314%26UserMode%3D0
A16: Property Orientation | B16: Complete a tour of your property with new hires. | E16: IHG8342629-OJT | F16: https://mylearning.sumtotal.host/core/pillarRedirect?relyingParty=LM&url=app%2Fmanagement%2FLMS_ActDetails.aspx%3FActivityId%3D603028%26UserMode%3D0
A17: voco Hotels Brand Experience Training | B17: View the videos with your group to complete the learning offer. Once complete, review the assessments as a group. NOTE: Assessment records are not required | C17: https://mylearning.sumtotal.host/core/pillarRedirect?relyingParty=LM&url=app%2fmanagement%2fLMS_ActDetails.aspx%3fActivityId%3d16585%26UserMode%3d0 | D17: course | E17: IHG0066043-OJT | F17: https://mylearning.sumtotal.host/core/pillarRedirect?relyingParty=LM&url=app%2Fmanagement%2FLMS_ActDetails.aspx%3FActivityId%3D596785%26UserMode%3D0
A18: voco hotels Brand Orientation Training | B18: View the videos with your group to complete the learning offer. Once complete, review the assessments as a group. NOTE: Assessment records are not required | C18: https://mylearning.sumtotal.host/core/pillarRedirect?relyingParty=LM&url=app%2fmanagement%2fLMS_ActDetails.aspx%3fActivityId%3d3735%26UserMode%3d0 | D18: course | E18: IHG0065384-OJT | F18: https://mylearning.sumtotal.host/core/pillarRedirect?relyingParty=LM&url=app%2Fmanagement%2FLMS_ActDetails.aspx%3FActivityId%3D596786%26UserMode%3D0

Sheet Crowne Plaza
A1: Course Title | B1: Instructions | C1: Hyperlink for Access | D1: Access ______ | E1: Not visible to learner: OJT Course ID: | F1: Create OJT Button
A2: First Aid | B2: Review your first aid procedures and practices. | E2: IHG1885862-OJT | F2: https://mylearning.sumtotal.host/core/pillarRedirect?relyingParty=LM&url=app%2Fmanagement%2FLMS_ActDetails.aspx%3FActivityId%3D601671%26UserMode%3D0
A3: Understanding PCI DSS | B3: View the videos with your group to complete the learning offer | C3: https://mylearning.sumtotal.host/core/pillarRedirect?relyingParty=LM&url=app%2fmanagement%2fLMS_ActDetails.aspx%3fActivityId%3d612703%26UserMode%3d0 | D3: Course | E3: IHG0047626-OJT | F3: https://mylearning.sumtotal.host/core/pillarRedirect?relyingParty=LM&url=app%2fmanagement%2fLMS_ActDetails.aspx%3fActivityId%3d595012%26UserMode%3d0
A4: Health & Safety, Security an Emergency Procedures | B4: Review your health safety and security procedures, including fire evacuation plan. | C4: Link | D4: course | E4: IHG9191264-OJT | F4: https://mylearning.sumtotal.host/core/pillarRedirect?relyingParty=LM&url=app%2Fmanagement%2FLMS_ActDetails.aspx%3FActivityId%3D601724%26UserMode%3D0
A5: Getting to Know IHG Concerto | B5: View the videos with your group to complete the learning offer. Once complete, review the assessments as a group. NOTE: Assessment records are not required | C5: https://mylearning.sumtotal.host/core/pillarRedirect?relyingParty=LM&url=app%2fmanagement%2fLMS_ActDetails.aspx%3fActivityId%3d52090%26UserMode%3d0 | D5: course | E5: IHG0049491-OJT | F5: https://mylearning.sumtotal.host/core/pillarRedirect?relyingParty=LM&url=app%2Fmanagement%2FLMS_ActDetails.aspx%3FActivityId%3D595027%26UserMode%3D0
A6: IHG Voice Program Training | B6: View the videos with your group to complete the learning offer | C6: https://mylearning.sumtotal.host/core/pillarRedirect?relyingParty=LM&url=app%2fmanagement%2fLMS_ActDetails.aspx%3fActivityId%3d2823%26UserMode%3d0 | D6: course | E6: IHG0054667-OJT | F6: https://mylearning.sumtotal.host/core/pillarRedirect?relyingParty=LM&url=app%2Fmanagement%2FLMS_ActDetails.aspx%3FActivityId%3D595030%26UserMode%3D0
A7: IHG Way of Clean 5-S Cleaning Program | B7: View the videos with your group to complete the learning offer. Once complete, review the assessments as a group. NOTE: Assessment records are not required | C7: Link | D7: course | E7: IHG7376524-OJT | F7: https://mylearning.sumtotal.host/core/pillarRedirect?relyingParty=LM&url=app%2Fmanagement%2FLMS_ActDetails.aspx%3FActivityId%3D468097%26UserMode%3D0
A8: IHG Way of Clean 5-S Cleaning Program for Non-Housekeeping Colleagues | B8: View the videos with your group to complete the learning offer. Once complete, review the assessments as a group. NOTE: Assessment records are not required | C8: Link | D8: course | E8: IHG1227263-OJT | F8: https://mylearning.sumtotal.host/core/pillarRedirect?relyingParty=LM&url=app%2Fmanagement%2FLMS_ActDetails.aspx%3FActivityId%3D595028%26UserMode%3D0
A9: IHG World Class Beverage Academy - 101 Essentials | B9: View the videos with your group to complete the learning offer. Once complete, review the assessments as a group. NOTE: Assessment records are not required | C9: Link | D9: course | E9: IHG052185-OJT | F9: https://mylearning.sumtotal.host/core/pillarRedirect?relyingParty=LM&url=app%2Fmanagement%2FLMS_ActDetails.aspx%3FActivityId%3D595029%26UserMode%3D0
A10: Introduction to Information Security | B10: View the videos with your group to complete the learning offer Please visit the Information Security Page on Merlin to learn more about Information Security at IHG: https://me2.ihgmerlin.com/web/init-ihg-information-security/home | C10: Link | D10: course | E10: IHG0047625-OJT | F10: https://mylearning.sumtotal.host/core/pillarRedirect?relyingParty=LM&url=app%2Fmanagement%2FLMS_ActDetails.aspx%3FActivityId%3D596770%26UserMode%3D0
A11: Leading and Sustaining your Service Culture | B11: View the videos with your group to complete the learning offer. Once complete, review the assessments as a group. NOTE: Assessment records are not required | C11: Link | D11: course | E11: IHG0056403-OJT | F11: https://mylearning.sumtotal.host/core/pillarRedirect?relyingParty=LM&url=app%2Fmanagement%2FLMS_ActDetails.aspx%3FActivityId%3D596772%26UserMode%3D0
A12: Preventing Human Trafficking | B12: View the videos with your group to complete the learning offer. Once complete, review the assessments as a group. NOTE: Assessment records are not required | C12: Link https://ihg.sharepoint.com/sites/ResponsibleBusiness/SitePages/Human-Rights-Brand-Standards-Guidance.aspx | D12: course | E12: IHG0057043-OJT | F12: https://mylearning.sumtotal.host/core/pillarRedirect?relyingParty=LM&url=app%2Fmanagement%2FLMS_ActDetails.aspx%3FActivityId%3D468092%26UserMode%3D0
A13: IHG Problem Handling V2 | B13: View the videos with your group to complete the learning offer. Once complete, review the assessments as a group. NOTE: Assessment records are not required | C13: Link | D13: course | E13: IHG056045-OJT | F13: https://mylearning.sumtotal.host/core/pillarRedirect?relyingParty=LM&url=app%2Fmanagement%2FLMS_ActDetails.aspx%3FActivityId%3D468095%26UserMode%3D0
A14: True Hospitality Service Skills | B14: View the videos with your group to complete the learning offer. Once complete, review the assessments as a group. NOTE: Assessment records are not required | C14: Link | D14: course | E14: IHG051263-OJT | F14: https://mylearning.sumtotal.host/core/pillarRedirect?relyingParty=LM&url=app%2Fmanagement%2FLMS_ActDetails.aspx%3FActivityId%3D468089%26UserMode%3D0
A15: Welcome to IHG | B15: View the videos with your group to complete the learning offer | C15: Link | D15: course | E15: IHG058044-OJT | F15: https://mylearning.sumtotal.host/core/pillarRedirect?relyingParty=LM&url=app%2Fmanagement%2FLMS_ActDetails.aspx%3FActivityId%3D606314%26UserMode%3D0
A16: Property Orientation | B16: Complete a tour of your property with new hires. | E16: IHG8342629-OJT | F16: https://mylearning.sumtotal.host/core/pillarRedirect?relyingParty=LM&url=app%2Fmanagement%2FLMS_ActDetails.aspx%3FActivityId%3D603028%26UserMode%3D0
A17: Crowne Plaza Brand Orientation | B17: View the videos with your group to complete the learning offer. Once complete, review the assessments as a group. NOTE: Assessment records are not required | C17: https://mylearning.sumtotal.host/core/pillarRedirect?relyingParty=LM&url=app%2fmanagement%2fLMS_ActDetails.aspx%3fActivityId%3d10699%26UserMode%3d0 | D17: course | E17: IHG051234-OJT | F17: https://mylearning.sumtotal.host/core/pillarRedirect?relyingParty=LM&url=app%2Fmanagement%2FLMS_ActDetails.aspx%3FActivityId%3D593215%26UserMode%3D0
A18: Crowne Plaza Brand Experience Training | B18: View the videos with your group to complete the learning offer. Once complete, review the assessments as a group. NOTE: Assessment records are not required | C18: https://mylearning.sumtotal.host/core/pillarRedirect?relyingParty=LM&url=app%2fmanagement%2fLMS_ActDetails.aspx%3fActivityId%3d10769%26UserMode%3d0 | D18: course | E18: IHG058303-OJT | F18: https://mylearning.sumtotal.host/core/pillarRedirect?relyingParty=LM&url=app%2Fmanagement%2FLMS_ActDetails.aspx%3FActivityId%3D593214%26UserMode%3D0
D19: =_xlfn.XLOOKUP(A19,'All Courses'!A:A,'All Courses'!D:D,"Not found") -> 0
D20: =_xlfn.XLOOKUP(A20,'All Courses'!A:A,'All Courses'!D:D,"Not found") -> 0
D21: =_xlfn.XLOOKUP(A21,'All Courses'!A:A,'All Courses'!D:D,"Not found") -> 0
D22: =_xlfn.XLOOKUP(A22,'All Courses'!A:A,'All Courses'!D:D,"Not found") -> 0
D23: =_xlfn.XLOOKUP(A23,'All Courses'!A:A,'All Courses'!D:D,"Not found") -> 0
D24: =_xlfn.XLOOKUP(A24,'All Courses'!A:A,'All Courses'!D:D,"Not found") -> 0
D25: =_xlfn.XLOOKUP(A25,'All Courses'!A:A,'All Courses'!D:D,"Not found") -> 0
D26: =_xlfn.XLOOKUP(A26,'All Courses'!A:A,'All Courses'!D:D,"Not found") -> 0
D27: =_xlfn.XLOOKUP(A27,'All Courses'!A:A,'All Courses'!D:D,"Not found") -> 0
D28: =_xlfn.XLOOKUP(A28,'All Courses'!A:A,'All Courses'!D:D,"Not found") -> 0
D29: =_xlfn.XLOOKUP(A29,'All Courses'!A:A,'All Courses'!D:D,"Not found") -> 0

Sheet Holiday Inn
A1: Course Title | B1: Instructions | C1: Hyperlink for Access | D1: Access ______ | E1: Not visible to learner: OJT Course ID: | F1: Create OJT Button
A2: First Aid | B2: Review your first aid procedures and practices. | E2: IHG1885862-OJT | F2: https://mylearning.sumtotal.host/core/pillarRedirect?relyingParty=LM&url=app%2Fmanagement%2FLMS_ActDetails.aspx%3FActivityId%3D601671%26UserMode%3D0
A3: Understanding PCI DSS | B3: View the videos with your group to complete the learning offer | C3: https://mylearning.sumtotal.host/core/pillarRedirect?relyingParty=LM&url=app%2fmanagement%2fLMS_ActDetails.aspx%3fActivityId%3d612703%26UserMode%3d0 | D3: Course | E3: IHG0047626-OJT | F3: https://mylearning.sumtotal.host/core/pillarRedirect?relyingParty=LM&url=app%2fmanagement%2fLMS_ActDetails.aspx%3fActivityId%3d595012%26UserMode%3d0
A4: Health & Safety, Security an Emergency Procedures | B4: Review your health safety and security procedures, including fire evacuation plan. | C4: Link | D4: course | E4: IHG9191264-OJT | F4: https://mylearning.sumtotal.host/core/pillarRedirect?relyingParty=LM&url=app%2Fmanagement%2FLMS_ActDetails.aspx%3FActivityId%3D601724%26UserMode%3D0
A5: Getting to Know IHG Concerto | B5: View the videos with your group to complete the learning offer. Once complete, review the assessments as a group. NOTE: Assessment records are not required | C5: https://mylearning.sumtotal.host/core/pillarRedirect?relyingParty=LM&url=app%2fmanagement%2fLMS_ActDetails.aspx%3fActivityId%3d52090%26UserMode%3d0 | D5: course | E5: IHG0049491-OJT | F5: https://mylearning.sumtotal.host/core/pillarRedirect?relyingParty=LM&url=app%2Fmanagement%2FLMS_ActDetails.aspx%3FActivityId%3D595027%26UserMode%3D0
A6: IHG Voice Program Training | B6: View the videos with your group to complete the learning offer | C6: https://mylearning.sumtotal.host/core/pillarRedirect?relyingParty=LM&url=app%2fmanagement%2fLMS_ActDetails.aspx%3fActivityId%3d2823%26UserMode%3d0 | D6: course | E6: IHG0054667-OJT | F6: https://mylearning.sumtotal.host/core/pillarRedirect?relyingParty=LM&url=app%2Fmanagement%2FLMS_ActDetails.aspx%3FActivityId%3D595030%26UserMode%3D0
A7: IHG Way of Clean 5-S Cleaning Program | B7: View the videos with your group to complete the learning offer. Once complete, review the assessments as a group. NOTE: Assessment records are not required | C7: Link | D7: course | E7: IHG7376524-OJT | F7: https://mylearning.sumtotal.host/core/pillarRedirect?relyingParty=LM&url=app%2Fmanagement%2FLMS_ActDetails.aspx%3FActivityId%3D468097%26UserMode%3D0
A8: IHG Way of Clean 5-S Cleaning Program for Non-Housekeeping Colleagues | B8: View the videos with your group to complete the learning offer. Once complete, review the assessments as a group. NOTE: Assessment records are not required | C8: Link | D8: course | E8: IHG1227263-OJT | F8: https://mylearning.sumtotal.host/core/pillarRedirect?relyingParty=LM&url=app%2Fmanagement%2FLMS_ActDetails.aspx%3FActivityId%3D595028%26UserMode%3D0
A9: IHG World Class Beverage Academy - 101 Essentials | B9: View the videos with your group to complete the learning offer. Once complete, review the assessments as a group. NOTE: Assessment records are not required | C9: Link | D9: course | E9: IHG052185-OJT | F9: https://mylearning.sumtotal.host/core/pillarRedirect?relyingParty=LM&url=app%2Fmanagement%2FLMS_ActDetails.aspx%3FActivityId%3D595029%26UserMode%3D0
A10: Introduction to Information Security | B10: View the videos with your group to complete the learning offer Please visit the Information Security Page on Merlin to learn more about Information Security at IHG: https://me2.ihgmerlin.com/web/init-ihg-information-security/home | C10: Link | D10: course | E10: IHG0047625-OJT | F10: https://mylearning.sumtotal.host/core/pillarRedirect?relyingParty=LM&url=app%2Fmanagement%2FLMS_ActDetails.aspx%3FActivityId%3D596770%26UserMode%3D0
A11: Leading and Sustaining your Service Culture | B11: View the videos with your group to complete the learning offer. Once complete, review the assessments as a group. NOTE: Assessment records are not required | C11: Link | D11: course | E11: IHG0056403-OJT | F11: https://mylearning.sumtotal.host/core/pillarRedirect?relyingParty=LM&url=app%2Fmanagement%2FLMS_ActDetails.aspx%3FActivityId%3D596772%26UserMode%3D0
A12: Preventing Human Trafficking | B12: View the videos with your group to complete the learning offer. Once complete, review the assessments as a group. NOTE: Assessment records are not required | C12: Link https://ihg.sharepoint.com/sites/ResponsibleBusiness/SitePages/Human-Rights-Brand-Standards-Guidance.aspx | D12: course | E12: IHG0057043-OJT | F12: https://mylearning.sumtotal.host/core/pillarRedirect?relyingParty=LM&url=app%2Fmanagement%2FLMS_ActDetails.aspx%3FActivityId%3D468092%26UserMode%3D0
A13: IHG Problem Handling V2 | B13: View the videos with your group to complete the learning offer. Once complete, review the assessments as a group. NOTE: Assessment records are not required | C13: Link | D13: course | E13: IHG056045-OJT | F13: https://mylearning.sumtotal.host/core/pillarRedirect?relyingParty=LM&url=app%2Fmanagement%2FLMS_ActDetails.aspx%3FActivityId%3D468095%26UserMode%3D0
A14: True Hospitality Service Skills | B14: View the videos with your group to complete the learning offer. Once complete, review the assessments as a group. NOTE: Assessment records are not required | C14: Link | D14: course | E14: IHG051263-OJT | F14: https://mylearning.sumtotal.host/core/pillarRedirect?relyingParty=LM&url=app%2Fmanagement%2FLMS_ActDetails.aspx%3FActivityId%3D468089%26UserMode%3D0
A15: Welcome to IHG | B15: View the videos with your group to complete the learning offer | C15: Link | D15: course | E15: IHG058044-OJT | F15: https://mylearning.sumtotal.host/core/pillarRedirect?relyingParty=LM&url=app%2Fmanagement%2FLMS_ActDetails.aspx%3FActivityId%3D606314%26UserMode%3D0
A16: Property Orientation | B16: Complete a tour of your property with new hires. | E16: IHG8342629-OJT | F16: https://mylearning.sumtotal.host/core/pillarRedirect?relyingParty=LM&url=app%2Fmanagement%2FLMS_ActDetails.aspx%3FActivityId%3D603028%26UserMode%3D0
A17: Holiday Inn Brand Service Training | B17: View the videos with your group to complete the learning offer | C17: https://mylearning.sumtotal.host/core/pillarRedirect?relyingParty=LM&url=app%2fmanagement%2fLMS_ActDetails.aspx%3fActivityId%3d104579%26UserMode%3d0 | D17: course | E17: IHG3075650-OJT | F17: https://mylearning.sumtotal.host/core/pillarRedirect?relyingParty=LM&url=app%2Fmanagement%2FLMS_ActDetails.aspx%3FActivityId%3D472806%26UserMode%3D0

Sheet Holiday Inn Express
A1: Course Title | B1: Instructions | C1: Hyperlink for Access | D1: Access ______ | E1: Not visible to learner: OJT Course ID: | F1: Create OJT Button
A2: First Aid | B2: Review your first aid procedures and practices. | E2: IHG1885862-OJT | F2: https://mylearning.sumtotal.host/core/pillarRedirect?relyingParty=LM&url=app%2Fmanagement%2FLMS_ActDetails.aspx%3FActivityId%3D601671%26UserMode%3D0
A3: Understanding PCI DSS | B3: View the videos with your group to complete the learning offer | C3: https://mylearning.sumtotal.host/core/pillarRedirect?relyingParty=LM&url=app%2fmanagement%2fLMS_ActDetails.aspx%3fActivityId%3d612703%26UserMode%3d0 | D3: Course | E3: IHG0047626-OJT | F3: https://mylearning.sumtotal.host/core/pillarRedirect?relyingParty=LM&url=app%2fmanagement%2fLMS_ActDetails.aspx%3fActivityId%3d595012%26UserMode%3d0
A4: Health & Safety, Security an Emergency Procedures | B4: Review your health safety and security procedures, including fire evacuation plan. | C4: Link | D4: course | E4: IHG9191264-OJT | F4: https://mylearning.sumtotal.host/core/pillarRedirect?relyingParty=LM&url=app%2Fmanagement%2FLMS_ActDetails.aspx%3FActivityId%3D601724%26UserMode%3D0
A5: Getting to Know IHG Concerto | B5: View the videos with your group to complete the learning offer. Once complete, review the assessments as a group. NOTE: Assessment records are not required | C5: https://mylearning.sumtotal.host/core/pillarRedirect?relyingParty=LM&url=app%2fmanagement%2fLMS_ActDetails.aspx%3fActivityId%3d52090%26UserMode%3d0 | D5: course | E5: IHG0049491-OJT | F5: https://mylearning.sumtotal.host/core/pillarRedirect?relyingParty=LM&url=app%2Fmanagement%2FLMS_ActDetails.aspx%3FActivityId%3D595027%26UserMode%3D0
A6: IHG Voice Program Training | B6: View the videos with your group to complete the learning offer | C6: https://mylearning.sumtotal.host/core/pillarRedirect?relyingParty=LM&url=app%2fmanagement%2fLMS_ActDetails.aspx%3fActivityId%3d2823%26UserMode%3d0 | D6: course | E6: IHG0054667-OJT | F6: https://mylearning.sumtotal.host/core/pillarRedirect?relyingParty=LM&url=app%2Fmanagement%2FLMS_ActDetails.aspx%3FActivityId%3D595030%26UserMode%3D0
A7: IHG Way of Clean 5-S Cleaning Program | B7: View the videos with your group to complete the learning offer. Once complete, review the assessments as a group. NOTE: Assessment records are not required | C7: Link | D7: course | E7: IHG7376524-OJT | F7: https://mylearning.sumtotal.host/core/pillarRedirect?relyingParty=LM&url=app%2Fmanagement%2FLMS_ActDetails.aspx%3FActivityId%3D468097%26UserMode%3D0
A8: IHG Way of Clean 5-S Cleaning Program for Non-Housekeeping Colleagues | B8: View the videos with your group to complete the learning offer. Once complete, review the assessments as a group. NOTE: Assessment records are not required | C8: Link | D8: course | E8: IHG1227263-OJT | F8: https://mylearning.sumtotal.host/core/pillarRedirect?relyingParty=LM&url=app%2Fmanagement%2FLMS_ActDetails.aspx%3FActivityId%3D595028%26UserMode%3D0
